Workbook
Name 산출자: #REF!

Sheet 정보입력
B6: 정보입력
B7: 건물명 | C7: 오산원당초
B8: 점검 투입 기간 | C8: 2026 | D8: 3 | E8: 2 | F8: ~ | G8: 2026 | H8: 3 | I8: 10 | J8: 계획검토 + 시스템검토 + 현장 성능점검 + 보고서 작성
B9: 건물개요 | C9: 연 면 적 ( ㎡ ) | F9: 35000 | J9: 오피스텔,빌딩,공장등 공동주택제외한 건물
C10: 세대수 (세대) | J10: 공동주택(아파트)만 해당
B11: 경과년수산정 | C11: 준공일 | E11: 작업일 | G11: 경과년수
C12: 36647 | E12: 45293 | G12: =DAYS360(C12,E12)/360 -> 23.669444

Sheet 소목차표지
J14: CHAPTER I. 기계설비 성능점검 계획서

Sheet 소목차
G4: CHAPTER I. 목 차
G8: 성능점검 수행 목적
G10: 성능점검 수행 범위
G12: 성능점검 투입인원 산정 및 담당업무
G14: 투입기간
G16: 분야별 인력 투입 계획
G18: 투입인력 산정표
G20: 투입인력 산정기준
G22: 성능점검대상 기계설비의 수량
G24: 성능점검대상 기계설비의 현황
G26: 기계설비 성능점검 계획
G28: 성능점검 장비현황
... G32: 성능점검 중 품질관리 방안

Sheet 1~3. 수행목적...-24.08.26
D3: 1 | H3: 수행목적
C5: ="기계설비법 제17조 2항에 따라 "&정보입력!$C$7&" 건축물의 기계설비 전반의 체계적인 성능점검을 시행하여 그 결과를 바탕으로 성능개선 계획을 수립하고 전문적인 기계설비 유지관리를 통하여 기계설비의 수명을 연장하고 안전 및 성능을 확보하는 데 있다." -> 기계설비법 제17조 2항에 따라 오산원당초 건축물의 기계설비 전반의 체계적인 성능점검을 시행하여 그 결과를 바탕으로 성능개선 계획을 수립하고 전문적인 기계설비 유지관리를 통하여 기계설비의 수명을 연장하고 안전 및 성능을 확보하는 데 있다.
D10: 2 | H10: ="수행범위 : "&정보입력!$C$7&" 기계설비" -> 수행범위 : 오산원당초 기계설비
B12: 가. 점검대상 및 내용 확인
B13: 나. 설계도서 및 운전자료, 보수이력등 기초자료 수집
B14: 다. 현장확인 및 문제점 협의(인터뷰 등)
B15: 라. 성능점검 계획 수립
B16: 마. 성능점검
B17: 바. 성능점검 결과보고서 작성 및 성능개선 계획 수립
D20: 3 | H20: 성능점검 투입인원 산정 및 담당업무
B22: 구 분 | L22: 투입인원 (인) | Q22: 업무 내용
B23: 특급 책임기계설비유지관리자 | L23: =ROUNDUP('6.투입인력산정표-24.01.24'!$L$36,0) -> 14 | Q23: - 성능점검 및 개선방안 제안
Q24: - 기계설비 성능점검 계획수립 및 시스템 검토
Q25: - 성능점검결과보고서 작성 및 확인
B26: 고급 책임기계설비유지관리자 | L26: =ROUNDUP('6.투입인력산정표-24.01.24'!$M$36,0) -> 18 | Q26: - 기계설비 성능점검 수행
Q27: - 현장조사 및 자료수집
Q28: - 점검결과 기록
B29: 중급 책임기계설비유지관리자 | L29: =ROUNDUP('6.투입인력산정표-24.01.24'!$N$36,0) -> 16 | Q29: - 기계설비 성능점검 수행
Q30: - 현장조사 및 자료수집
Q31: - 점검결과 기록
B33: ※ 기술등급별 업무내용은 조정될 수 있음

Sheet 4~5. 분야별인력투입계획-24.01.24
D4: 4 | H4: 투입기간
D6: =정보입력!C8&"년 "&정보입력!D8&"월 "&정보입력!E8&"일 부터 "&정보입력!G8&"년 "&정보입력!H8&"월 "&정보입력!I8&"일 까지" -> 2026년 3월 2일 부터 2026년 3월 10일 까지
D9: 5 | H9: 분야별 인력 투입 계획
AR11: ※ 본문 중 빨간색 표시 부분 수정 후 폰트 칼라 검정색으로 설정요!
B12: 구분 | E12: 월 일 투입인원 | K12: 착수일(D)로부터 | AO12: 합계
K13: -15 | M13: -14 | O13: -13 | Q13: -12 | S13: -11 | U13: -10 | W13: -9 | Y13: -8 | AA13: -7 | AC13: -6 | AE13: -5 | AG13: -4 | AI13: -3 | AK13: -2 | AM13: -1 | AR13: 지우면 안됨
B14: 계획 검토 | E14: 특급유지 관리자 | I14: 1 | AO14: 7 | AR14: =IF(COUNTIF(K13:AN13,(AO14/I14)*-1)=0,"날짜 또는 투입인원 수정 요망!!!","<= OK!") -> <= OK!
B17: 시스템 검토 | E17: 특급유지 관리자 | I17: 1 | AO17: 7 | AR17: =IF(COUNTIF(K13:AN13,(AO17/I17)*-1)=0,"날짜 또는 투입인원 수정 요망!!!","<= OK!") -> <= OK!
B20: 구분 | E20: 월 일 투입인원 | K20: 착수일(D)로부터 | AO20: 합계
K21: D | M21: 1 | O21: 2 | Q21: 3 | S21: 4 | U21: 5 | W21: 6 | Y21: 7 | AA21: 8 | AC21: 9 | AE21: 10 | AG21: 11 | AI21: 12 | AK21: 13 | AM21: 14 | AR21: 지우면 안됨
B22: 현장성능 점검 | E22: 특급+고급 관리자 | I22: 3 | AO22: 3 | AR22: =IF(COUNTIF(K21:AN21,AO22/I22)=0,"인원수 확인 요망!!!","<= OK!") -> <= OK!
B25: 구분 | E25: 월 일 투입인원 | K25: 착수일(D)로부터 | AO25: 합계
K26: D | M26: 1 | O26: 2 | Q26: 3 | S26: 4 | U26: 5 | W26: 6 | Y26: 7 | AA26: 8 | AC26: 9 | AE26: 10 | AG26: 11 | AI26: 12 | AK26: 13 | AM26: 14 | AR26: 지우면 안됨
B27: 보고서 작성 | E27: 특급유지 관리자 | I27: 2 | AO27: 10 | AR27: =IF(COUNTIF(K26:AN26,(AO22/I22+AO27/I27)-1)=0,"날짜 또는 투입인원 확인/수정 요망!!!","<= OK!") -> <= OK!
B30: 투입인원 (인) | AO30: =SUM(AO14:AP19,AO22,AO27) -> 27 | AR30: =IF(AO30=SUM('1~3. 수행목적...-24.08.26'!L22:P30),"투입인원 합계 OK!","투입인원 합계 확인요망!!! [3] 성능점검 투입인원 산정 및 담당업무의 합계 인원("&SUM('1~3. 수행목적...-24.08.26'!L22:P30)&"명)과 불일치") -> 투입인원 합계 확인요망!!! [3] 성능점검 투입인원 산정 및 담당업무의 합계 인원(48명)과 불일치

Sheet 6.투입인력산정표-24.01.24
B3: 6 | E3: 성능점검 투입인력 산정표
A5: 점 검 대 상 | E5: 기준인원(인) | H5: 기계설비 점검수량 | J5: 조정계수 | L5: 성능점검인원
E7: 특급 | F7: 고급 | G7: 중급 | H7: 단위 | I7: 수량 | J7: 연면적/세대수 | K7: 경과년수 | L7: 특급 | M7: 고급 | N7: 중급
A8: 성능검토 및 계획수립 | E8: 3.58 | F8: 0 | G8: 0 | H8: 식 | I8: 1 | J8: =$T$25 -> 1.4 | K8: - | L8: =E8*I8*J8 -> 5.012 | M8: =F8*I8*J8 -> 0 | N8: =G8*I8*J8 -> 0 | P8: [표2] 연면적, 세대수, 경과년수에 따른 조정계수
A9: 시스템검토 | E9: 3.58 | F9: 0 | G9: 0 | H9: 식 | I9: 1 | J9: =$T$25 -> 1.4 | K9: - | L9: =E9*I9*J9 -> 5.012 | M9: =F9*I9*J9 -> 0 | N9: =G9*I9*J9 -> 0 | P9: 세대수(공동주택)에 따른조정 | R9: 연면적(건물)에 따른 조정 | T9: 기계설비경과 연수에 따른조정
A10: 열원 및 냉난방 설비 | C10: 냉동기 | E10: 0.13 | F10: 0.28 | G10: 0.16 | H10: 대 | I10: ='8.성능점검대상기계설비의수량-24.01.24'!$Y$7 -> 0 | J10: - | K10: =$R$23 -> 1.18 | L10: =E10*I10*K10 -> 0 | M10: =F10*I10*K10 -> 0 | N10: =G10*I10*K10 -> 0 | P10: 세대수(세대) | Q10: 조정계수 | R10: 연면적(㎡)이상 | S10: 조정계수 | T10: 경과년수(년) | U10: 조정계수
C11: 냉각탑 | E11: 0.1 | F11: 0.25 | G11: 0.17 | H11: 대 | I11: ='8.성능점검대상기계설비의수량-24.01.24'!$Y$8 -> 0 | J11: - | K11: =$R$23 -> 1.18 | L11: =E11*I11*K11 -> 0 | M11: =F11*I11*K11 -> 0 | N11: =G11*I11*K11 -> 0 | P11: 0 | Q11: 0 | R11: 0 | S11: 0 | T11: 0 | U11: 1
C12: 축열조 | E12: 0.1 | F12: 0.27 | G12: 0.17 | H12: 대 | I12: ='8.성능점검대상기계설비의수량-24.01.24'!$Y$9 -> 0 | J12: - | K12: =$R$23 -> 1.18 | L12: =E12*I12*K12 -> 0 | M12: =F12*I12*K12 -> 0 | N12: =G12*I12*K12 -> 0 | P12: 300 | Q12: 0.2 | R12: 10000 | S12: 1 | T12: 5.01 | U12: 1.05
C13: 보일러 | E13: 0.1 | F13: 0.28 | G13: 0.19 | H13: 대 | I13: ='8.성능점검대상기계설비의수량-24.01.24'!$Y$10 -> 0 | J13: - | K13: =$R$23 -> 1.18 | L13: =E13*I13*K13 -> 0 | M13: =F13*I13*K13 -> 0 | N13: =G13*I13*K13 -> 0 | P13: 501 | Q13: 0.2 | R13: 15000.01 | S13: 1.1 | T13: 10.01 | U13: 1.09
C14: 열교환기 | E14: 0.04 | F14: 0.16 | G14: 0.11 | H14: 대 | I14: ='8.성능점검대상기계설비의수량-24.01.24'!$Y$11 -> 5 | J14: - | K14: =$R$23 -> 1.18 | L14: =E14*I14*K14 -> 0.236 | M14: =F14*I14*K14 -> 0.944 | N14: =G14*I14*K14 -> 0.649 | P14: 1001 | Q14: 0.4 | R14: 30000.01 | S14: 1.4 | T14: 15.01 | U14: 1.14
C15: 팽창탱크 | E15: 0.02 | F15: 0.16 | G15: 0.07 | H15: 대 | I15: ='8.성능점검대상기계설비의수량-24.01.24'!$Y$12 -> 11 | J15: - | K15: =$R$23 -> 1.18 | L15: =E15*I15*K15 -> 0.2596 | M15: =F15*I15*K15 -> 2.0768 | N15: =G15*I15*K15 -> 0.9086 | P15: 2001 | Q15: 0.6 | R15: 60000.01 | S15: 1.8 | T15: 20.01 | U15: 1.18
C16: 펌프 | E16: 0.1 | F16: 0.21 | G16: 0.13 | H16: 대 | I16: ='8.성능점검대상기계설비의수량-24.01.24'!$Y$13 -> 6 | J16: - | K16: =$R$23 -> 1.18 | L16: =E16*I16*K16 -> 0.708 | M16: =F16*I16*K16 -> 1.4868 | N16: =G16*I16*K16 -> 0.9204 | P16: 2501 | Q16: 0.8 | R16: 100000.01 | S16: 2 | T16: 25.01 | U16: 1.2
C17: 신재생에너지 | E17: 0.09 | F17: 0.23 | G17: 0.09 | H17: 대 | I17: =SUM('8.성능점검대상기계설비의수량-24.01.24'!Y14:Y16) -> 0 | J17: - | K17: =$R$23 -> 1.18 | L17: =E17*I17*K17 -> 0 | M17: =F17*I17*K17 -> 0 | N17: =G17*I17*K17 -> 0 | P17: 3001 | Q17: 1 | R17: 200000.01 | S17: 2.5
C18: 패키지에어컨 | E18: 0.04 | F18: 0.11 | G18: 0.17 | H18: 대 | I18: ='8.성능점검대상기계설비의수량-24.01.24'!$Y$17 -> 5 | J18: - | K18: =$R$23 -> 1.18 | L18: =E18*I18*K18 -> 0.236 | M18: =F18*I18*K18 -> 0.649 | N18: =G18*I18*K18 -> 1.003 | P18: ※ 300세대 ~ 500세대는 중앙집중식(지역난방 포함) 난방방식 일 경우
C19: 항온항습기 | E19: 0.08 | F19: 0.16 | G19: 0.18 | H19: 대 | I19: ='8.성능점검대상기계설비의수량-24.01.24'!$Y$18 -> 0 | J19: - | K19: =$R$23 -> 1.18 | L19: =E19*I19*K19 -> 0 | M19: =F19*I19*K19 -> 0 | N19: =G19*I19*K19 -> 0
A20: 공기조화설비 | C20: 공기조화기 | E20: 0.04 | F20: 0.18 | G20: 0.11 | H20: 대 | I20: ='8.성능점검대상기계설비의수량-24.01.24'!$Y$19 -> 0 | J20: - | K20: =$R$23 -> 1.18 | L20: =E20*I20*K20 -> 0 | M20: =F20*I20*K20 -> 0 | N20: =G20*I20*K20 -> 0 | P20: 산출된 조정계수
C21: 팬코일유닛 | E21: 0.04 | F21: 0.11 | G21: 0.13 | H21: 대 | I21: ='8.성능점검대상기계설비의수량-24.01.24'!$Y$20 -> 0 | J21: - | K21: =$R$23 -> 1.18 | L21: =E21*I21*K21 -> 0 | M21: =F21*I21*K21 -> 0 | N21: =G21*I21*K21 -> 0 | P21: 세대수 조정계수 | R21: =VLOOKUP(정보입력!F10,'6.투입인력산정표-24.01.24'!P11:Q17,2) -> 0
A22: 환기설비 | C22: 환기설비 | E22: 0.04 | F22: 0.11 | G22: 0.13 | H22: 대 | I22: ='8.성능점검대상기계설비의수량-24.01.24'!$Y$21 -> 11 | J22: - | K22: =$R$23 -> 1.18 | L22: =E22*I22*K22 -> 0.5192 | M22: =F22*I22*K22 -> 1.4278 | N22: =G22*I22*K22 -> 1.6874 | P22: 연면적 조정계수 | R22: =VLOOKUP(정보입력!F9,'6.투입인력산정표-24.01.24'!R11:S17,2) -> 1.4
C23: 필터 | E23: 0.04 | F23: 0.1 | G23: 0.1 | H23: 대 | I23: ='8.성능점검대상기계설비의수량-24.01.24'!Y22 -> 0 | J23: - | K23: =$R$23 -> 1.18 | L23: =E23*I23*K23 -> 0 | M23: =F23*I23*K23 -> 0 | N23: =G23*I23*K23 -> 0 | P23: 경과년수 조정계수 | R23: =VLOOKUP(정보입력!G12,'6.투입인력산정표-24.01.24'!T11:U17,2) -> 1.18
A24: 위생기구설비 | E24: 0.04 | F24: 0.35 | G24: 0.2 | H24: 식 | I24: ='8.성능점검대상기계설비의수량-24.01.24'!$Y$23 -> 1 | J24: =$T$25 -> 1.4 | K24: - | L24: =E24*I24*J24 -> 0.056 | M24: =F24*I24*J24 -> 0.49 | N24: =G24*I24*J24 -> 0.28
A25: 급수·급탕설비 | C25: 급수·급탕설비 | E25: 0.04 | F25: 0.23 | G25: 0.1 | H25: 식 | I25: ='8.성능점검대상기계설비의수량-24.01.24'!$Y$24 -> 1 | J25: =$T$25 -> 1.4 | K25: - | L25: =E25*I25*J25 -> 0.056 | M25: =F25*I25*J25 -> 0.322 | N25: =G25*I25*J25 -> 0.14 | P25: 조정계수 | Q25: 세대수(공동주택) / 연면적(건축물), 법정기준 | T25: 1.4 | U25: 반드시 해당하는 조정계수 선택
C26: 고·저수조 | E26: 0.04 | F26: 0.21 | G26: 0.13 | H26: 식 | I26: ='8.성능점검대상기계설비의수량-24.01.24'!$Y$25 -> 1 | J26: =$T$25 -> 1.4 | K26: - | L26: =E26*I26*J26 -> 0.056 | M26: =F26*I26*J26 -> 0.294 | N26: =G26*I26*J26 -> 0.182
A27: 오·배수 통기 및 우수배수설비 | E27: 0.04 | F27: 0.29 | G27: 0.17 | H27: 식 | I27: =IF(OR('8.성능점검대상기계설비의수량-24.01.24'!Y26=1,'8.성능점검대상기계설비의수량-24.01.24'!Y27=1),1,0) -> 1 | J27: =$T$25 -> 1.4 | K27: - | L27: =E27*I27*J27 -> 0.056 | M27: =F27*I27*J27 -> 0.406 | N27: =G27*I27*J27 -> 0.238
A28: 오수정화 및 물 재이용설비 | C28: 오수정화설비 | E28: 0.04 | F28: 0.29 | G28: 0.17 | H28: 식 | I28: ='8.성능점검대상기계설비의수량-24.01.24'!$Y$28 -> 1 | J28: =$T$25 -> 1.4 | K28: - | L28: =E28*I28*J28 -> 0.056 | M28: =F28*I28*J28 -> 0.406 | N28: =G28*I28*J28 -> 0.238
C29: 물 재이용설비 | E29: 0.04 | F29: 0.29 | G29: 0.17 | H29: 식 | I29: ='8.성능점검대상기계설비의수량-24.01.24'!$Y$29 -> 1 | J29: =$T$25 -> 1.4 | K29: - | L29: =E29*I29*J29 -> 0.056 | M29: =F29*I29*J29 -> 0.406 | N29: =G29*I29*J29 -> 0.238
A30: 배관설비 | E30: 0.04 | F30: 1.13 | G30: 1.25 | H30: 식 | I30: ='8.성능점검대상기계설비의수량-24.01.24'!$Y$30 -> 1 | J30: =$T$25 -> 1.4 | K30: - | L30: =E30*I30*J30 -> 0.056 | M30: =F30*I30*J30 -> 1.582 | N30: =G30*I30*J30 -> 1.75
A31: 덕트설비 | E31: 0.04 | F31: 0.52 | G31: 0.4 | H31: 식 | I31: ='8.성능점검대상기계설비의수량-24.01.24'!$Y$31 -> 1 | J31: =$T$25 -> 1.4 | K31: - | L31: =E31*I31*J31 -> 0.056 | M31: =F31*I31*J31 -> 0.728 | N31: =G31*I31*J31 -> 0.56
A32: 보온설비 | E32: 0.04 | F32: 0.96 | G32: 1 | H32: 식 | I32: ='8.성능점검대상기계설비의수량-24.01.24'!$Y$32 -> 1 | J32: =$T$25 -> 1.4 | K32: - | L32: =E32*I32*J32 -> 0.056 | M32: =F32*I32*J32 -> 1.344 | N32: =G32*I32*J32 -> 1.4
A33: 자동제어설비 | E33: 0.1 | F33: 0.75 | G33: 0.5 | H33: 식 | I33: ='8.성능점검대상기계설비의수량-24.01.24'!$Y$33 -> 1 | J33: =$T$25 -> 1.4 | K33: - | L33: =E33*I33*J33 -> 0.14 | M33: =F33*I33*J33 -> 1.05 | N33: =G33*I33*J33 -> 0.7
A34: 방음·방진·내진 설비 | E34: 0.04 | F34: 0.47 | G34: 0.42 | H34: 식 | I34: ='8.성능점검대상기계설비의수량-24.01.24'!$Y$34 -> 1 | J34: =$T$25 -> 1.4 | K34: - | L34: =E34*I34*J34 -> 0.056 | M34: =F34*I34*J34 -> 0.658 | N34: =G34*I34*J34 -> 0.588
A35: 보고서작성 | E35: 0.42 | F35: 2.46 | G35: 2.71 | H35: 식 | I35: 1 | J35: =$T$25 -> 1.4 | K35: - | L35: =E35*I35*J35 -> 0.588 | M35: =F35*I35*J35 -> 3.444 | N35: =G35*I35*J35 -> 3.794
A36: 합 계 | I36: ='8.성능점검대상기계설비의수량-24.01.24'!Y35 -> 0 | L36: =SUM(L8:L35) -> 13.2708 | M36: =SUM(M8:M35) -> 17.7144 | N36: =SUM(N8:N35) -> 15.2764

Sheet 7.투입인력산정기준-24.01.24
C2: 7 | F2: 투입 인력 산정 기준
B4: □ 성능점검 투입인력은 「기계설비 유지관리기준」 [별표 4] 표 1 성능점검 투입인력 산정 기준에 따라 산정된 기준 인원에 조정계수를 곱하여 산출함
B6: [별표 4] 표 1 성능점검 투입인력 산정 기준
B8: 구분 | F8: 점검대상 | K8: 기준인원(인) | Q8: 분류 | S8: 조정계수 적용여부
K9: 고급 | M9: 중급 | O9: 고급 | S9: 연면적 또는 세대수 | X9: 경과년수
B10: 성능검토 및 계획수립 | K10: 3.58 | M10: - | O10: - | Q10: 식 | S10: ○ | AE10: 23.11.29 개정 고시 반영
B11: 시스템 검토 | K11: 3.58 | M11: - | O11: - | Q11: 식 | S11: ○
B12: 열원 및 냉난방 설비 | F12: 냉동기 | K12: 0.13 | M12: 0.28 | O12: 0.16 | Q12: 대 | X12: ○
F13: 냉각탑 | K13: 0.1 | M13: 0.25 | O13: 0.17 | Q13: 대 | X13: ○
F14: 축열조 | K14: 0.1 | M14: 0.27 | O14: 0.17 | Q14: 대 | X14: ○
F15: 보일러 | K15: 0.1 | M15: 0.28 | O15: 0.19 | Q15: 대 | X15: ○
F16: 열교환기 | K16: 0.04 | M16: 0.16 | O16: 0.11 | Q16: 대 | X16: ○
F17: 팽창탱크 | K17: 0.02 | M17: 0.16 | O17: 0.07 | Q17: 대 | X17: ○
F18: 펌프 | K18: 0.1 | M18: 0.21 | O18: 0.13 | Q18: 대 | X18: ○
F19: 신재생에너지 | K19: 0.09 | M19: 0.23 | O19: 0.09 | Q19: 대 | X19: ○
F20: 패키지에어컨 | K20: 0.04 | M20: 0.11 | O20: 0.17 | Q20: 대 | X20: ○
F21: 항온항습기 | K21: 0.08 | M21: 0.16 | O21: 0.18 | Q21: 대 | X21: ○
F22: 공기조화기 | K22: 0.04 | M22: 0.18 | O22: 0.11 | Q22: 대 | X22: ○
F23: 팬코일유닛 | K23: 0.04 | M23: 0.11 | O23: 0.13 | Q23: 대 | X23: ○
F24: 환기설비 | K24: 0.04 | M24: 0.11 | O24: 0.13 | Q24: 대 | X24: ○
F25: 필터 | K25: 0.04 | M25: 0.1 | O25: 0.1 | Q25: 대 | X25: ○
B26: 위생기구설비 | K26: 0.04 | M26: 0.35 | O26: 0.2 | Q26: 식 | S26: ○
B27: 급수·급탕설비 | F27: 급수·급탕설비 | K27: 0.04 | M27: 0.23 | O27: 0.1 | Q27: 식 | S27: ○
F28: 고·저수조 | K28: 0.04 | M28: 0.21 | O28: 0.13 | Q28: 식 | S28: ○
B29: 오·배수 통기 및 우수배수설비 | K29: 0.04 | M29: 0.29 | O29: 0.17 | Q29: 식 | S29: ○
B30: 오수정화 및 물재이용설비 | F30: 오수정화설비 | K30: 0.04 | M30: 0.29 | O30: 0.17 | Q30: 식 | S30: ○
F31: 물 재이용설비 | K31: 0.04 | M31: 0.29 | O31: 0.17 | Q31: 식 | S31: ○
B32: 배관설비 | K32: 0.04 | M32: 1.13 | O32: 1.25 | Q32: 식 | S32: ○
B33: 덕트설비 | K33: 0.04 | M33: 0.52 | O33: 0.4 | Q33: 식 | S33: ○
B34: 보온설비 | K34: 0.04 | M34: 0.96 | O34: 1 | Q34: 식 | S34: ○
B35: 자동제어설비 | K35: 0.1 | M35: 0.75 | O35: 0.5 | Q35: 식 | S35: ○
B36: 방음·방진·내진 설비 | K36: 0.04 | M36: 0.47 | O36: 0.42 | Q36: 식 | S36: ○
B37: 보고서 작성 | K37: 0.42 | M37: 2.46 | O37: 2.71 | Q37: 식 | S37: ○
B39: □ 조정계수는 「기계설비 유지관리기준」 [별표 4] 표 2 연면적, 세대수, 경과년수에 따른 조정계수에 따라 산출함. 연면적(또는 세대수)은 건축물 대장을 통해 확인가능하며 기계설비 경과년수는 기계설비 관리대장 또는 기계설비 명판을 통해 확인함
B44: [별표 4] 표 2 연면적, 세대수, 경과년수에 따른 조정 계수 | AE44: 23.11.29 개정 고시 반영
B48: 연먼적에 따른 조정 | K48: 세대수(공동주택)에 따른 조정 | T48: 기계설비 경과년수에 따른 조정
B50: 연면적(㎡) | I50: 조정 계수 | K50: 세대수 | R50: 조정 계수 | T50: 경과년수 | AA50: 조정 계수
B52: 10,000 이상 15,000 이하 | I52: 1 | K52: 300 세대 이상 500 세대 이하 (중앙집중식 난방방식) | R52: 0.2 | T52: 5년 이내 | AA52: 1
B57: 15,000 초과 30,000 이하 | I57: 1.1 | K57: 500 세대 초과 1,000 세대 이하 | R57: 0.2 | T57: 5년 초과 10년 이내 | AA57: 1.05
B62: 30,000 초과 60,000 이하 | I62: 1.4 | K62: 1,000 세대 초과 2,000 세대 이하 | R62: 0.4 | T62: 10년 초과 15년 이내 | AA62: 1.09
...

Sheet 8.성능점검대상기계설비의수량-24.01.24
B3: 8 | F3: 성능점검 대상 기계설비의 수량 (제7조 제2항 관련)
A5: 기계설비 | F5: 세부항목 | P5: 대상 여부 | R5: 전체 수량 | S5: 점검수량 산출기준 | Y5: 점검 수량
A7: 열원 및 냉난방설비 | F7: 냉동기(헤더 포함) | P7: =IF(R7=0,"×","○") -> × | R7: =IF(COUNTIF('9.성능점검대상기계설비현황-24.01.24'!M:M,"냉동기")=0,0,COUNTIF('9.성능점검대상기계설비현황-24.01.24'!M:M,"냉동기")) -> 0 | S7: 전체수량의 50% 이상 | Y7: =ROUNDUP(R7*0.5,0) -> 0
F8: 냉각탑(냉동기 관련) | P8: =IF(R8=0,"×","○") -> × | R8: =IF(COUNTIF('9.성능점검대상기계설비현황-24.01.24'!M:M,"냉각탑")=0,0,COUNTIF('9.성능점검대상기계설비현황-24.01.24'!M:M,"냉각탑")) -> 0 | S8: 전체수량의 50% 이상 | Y8: =ROUNDUP(R8*0.5,0) -> 0
F9: 축열조 | P9: =IF(R9=0,"×","○") -> × | R9: =IF(COUNTIF('9.성능점검대상기계설비현황-24.01.24'!M:M,"축열조")=0,0,COUNTIF('9.성능점검대상기계설비현황-24.01.24'!M:M,"축열조")) -> 0 | S9: 전체수량 | Y9: =R9 -> 0
F10: 보일러 (헤더 포함, 난방용량 42 kW 이하 제외) | P10: =IF(R10=0,"×","○") -> × | R10: =IF(COUNTIF('9.성능점검대상기계설비현황-24.01.24'!M:M,"보일러")=0,0,COUNTIF('9.성능점검대상기계설비현황-24.01.24'!M:M,"보일러")) -> 0 | S10: 전체수량의 50% 이상 | Y10: =ROUNDUP(R10*0.5,0) -> 0 | AA10: 23.11.29 개정 고시 반영
F11: 열교환기 | P11: =IF(R11=0,"×","○") -> ○ | R11: =IF(COUNTIF('9.성능점검대상기계설비현황-24.01.24'!M:M,"열교환기")=0,0,COUNTIF('9.성능점검대상기계설비현황-24.01.24'!M:M,"열교환기")) -> 9 | S11: 전체수량의 50% 이상 | Y11: =ROUNDUP(R11*0.5,0) -> 5
F12: 팽창탱크 (냉·난방, 급탕 팽창탱크 포함) | P12: =IF(R12=0,"×","○") -> ○ | R12: =IF(COUNTIF('9.성능점검대상기계설비현황-24.01.24'!M:M,"팽창탱크")=0,0,COUNTIF('9.성능점검대상기계설비현황-24.01.24'!M:M,"팽창탱크")) -> 11 | S12: 전체수량 | Y12: =R12 -> 11
F13: 펌프(냉·난방펌프) (예비펌프, 모터동력 0.75 kW 이하 제외) | P13: =IF(R13=0,"×","○") -> ○ | R13: =IF(COUNTIF('9.성능점검대상기계설비현황-24.01.24'!M:M,"펌프")=0,0,COUNTIF('9.성능점검대상기계설비현황-24.01.24'!M:M,"펌프")) -> 28 | S13: 전체수량의 20% 이상 | Y13: =ROUNDUP(R13*0.2,0) -> 6 | AA13: 23.11.29 개정 고시 반영
F14: 신재생에너지(지열) | P14: =IF(R14=0,"×","○") -> × | R14: =IF(COUNTIF('9.성능점검대상기계설비현황-24.01.24'!M:M,"신재생에너지(지열)")=0,0,COUNTIF('9.성능점검대상기계설비현황-24.01.24'!M:M,"신재생에너지(지열)")) -> 0 | S14: 전체수량 | Y14: =IF(R14="","",R14) -> 0
F15: 신재생에너지(태양열) | P15: =IF(R15=0,"×","○") -> × | R15: =IF(COUNTIF('9.성능점검대상기계설비현황-24.01.24'!M:M,"신재생에너지(태양열)")=0,0,COUNTIF('9.성능점검대상기계설비현황-24.01.24'!M:M,"신재생에너지(태양열)")) -> 0 | S15: 전체수량 | Y15: =IF(R15="","",R15) -> 0
F16: 신재생에너지(연료전지) | P16: =IF(R16=0,"×","○") -> × | R16: =IF(COUNTIF('9.성능점검대상기계설비현황-24.01.24'!M:M,"신재생에너지(연료전지)")=0,0,COUNTIF('9.성능점검대상기계설비현황-24.01.24'!M:M,"신재생에너지(연료전지)")) -> 0 | S16: 전체수량 | Y16: =IF(R16="","",R16) -> 0
F17: 패키지에어컨 (냉·난방용량 7.3 kW 이하 제외(실외기 기준), 내부필터 포함) | P17: =IF(R17=0,"×","○") -> ○ | R17: =IF(COUNTIF('9.성능점검대상기계설비현황-24.01.24'!M:M,"패키지에어컨")=0,0,COUNTIF('9.성능점검대상기계설비현황-24.01.24'!M:M,"패키지에어컨")) -> 23 | S17: 전체수량의 20% 이상 | Y17: =IF(R17="","",ROUNDUP(R17*0.2,0)) -> 5 | AA17: 23.11.29 개정 고시 반영
F18: 항온항습기(내부필터 포함) | P18: =IF(R18=0,"×","○") -> × | R18: =IF(COUNTIF('9.성능점검대상기계설비현황-24.01.24'!M:M,"항온항습기")=0,0,COUNTIF('9.성능점검대상기계설비현황-24.01.24'!M:M,"항온항습기")) -> 0 | S18: 전체수량의 20% 이상 | Y18: =IF(R18="","",ROUNDUP(R18*0.2,0)) -> 0 | AA18: 23.11.29 개정 고시 반영
A19: 공기조화설비 | F19: 공기조화기(송풍기포함, 내부필터 포함) | P19: =IF(R19=0,"×","○") -> × | R19: =IF(COUNTIF('9.성능점검대상기계설비현황-24.01.24'!M:M,"공기조화기")=0,0,COUNTIF('9.성능점검대상기계설비현황-24.01.24'!M:M,"공기조화기")) -> 0 | S19: 전체수량의 20% 이상 | Y19: =IF(R19="","",ROUNDUP(R19*0.2,0)) -> 0 | AA19: 23.11.29 개정 고시 반영
F20: 팬코일 유닛(유니트 기준, 내부필터 포함) | P20: =IF(R20=0,"×","○") -> × | R20: =IF(COUNTIF('9.성능점검대상기계설비현황-24.01.24'!M:M,"팬코일유닛")=0,0,COUNTIF('9.성능점검대상기계설비현황-24.01.24'!M:M,"팬코일유닛")) -> 0 | S20: 전체수량의 20% 이상 | Y20: =IF(R20="","",ROUNDUP(R20*0.2,0)) -> 0 | AA20: 23.11.29 개정 고시 반영
A21: 환기설비 | F21: 환기설비 (모터동력 0.75 kW 이하 및 벽부형 제외) | P21: =IF(R21=0,"×","○") -> ○ | R21: =IF(COUNTIF('9.성능점검대상기계설비현황-24.01.24'!M:M,"환기설비")=0,0,COUNTIF('9.성능점검대상기계설비현황-24.01.24'!M:M,"환기설비")) -> 53 | S21: 전체수량의 20% 이상 | Y21: =IF(R21="","",ROUNDUP(R21*0.2,0)) -> 11 | AA21: 23.11.29 개정 고시 반영
F22: 필 터 (필터유닛,냄새제거 필터유닛, 특수목적필터 등 포함) | P22: =IF(R22=0,"×","○") -> × | R22: =IF(COUNTIF('9.성능점검대상기계설비현황-24.01.24'!M:M,"필터")=0,0,COUNTIF('9.성능점검대상기계설비현황-24.01.24'!M:M,"필터")) -> 0 | S22: 전체수량 | Y22: =IF(R22="","",R22) -> 0 | AA22: 23.11.29 개정 고시 반영
A23: 위생기구설비 | F23: 위생기구설비 | P23: =IF(Y23=0,"×","○") -> ○ | R23: 식 | Y23: =IF(COUNTIF('9.성능점검대상기계설비현황-24.01.24'!M:M,"위생기구설비")=0,0,COUNTIF('9.성능점검대상기계설비현황-24.01.24'!M:M,"위생기구설비")) -> 1
A24: 급수·급탕설비 | F24: 급수펌프, 급탕탱크 등 (모터동력 0.75 kW 이하 제외) | P24: =IF(Y24=0,"×","○") -> ○ | Y24: =IF(COUNTIF('9.성능점검대상기계설비현황-24.01.24'!M:M,"급수펌프, 급탕탱크 등")=0,0,COUNTIF('9.성능점검대상기계설비현황-24.01.24'!M:M,"급수펌프, 급탕탱크 등")) -> 1 | AA24: 23.11.29 개정 고시 반영
F25: 고·저수조 | P25: =IF(Y25=0,"×","○") -> ○ | Y25: =IF(COUNTIF('9.성능점검대상기계설비현황-24.01.24'!M:M,"고·저수조")=0,0,COUNTIF('9.성능점검대상기계설비현황-24.01.24'!M:M,"고·저수조")) -> 1
A26: 오·배수 통기 및 우수배수설비 | F26: 오·배수용 펌프(모터동력 0.75 kW 이하 제외) | P26: =IF(Y26=0,"×","○") -> ○ | Y26: =IF(COUNTIF('9.성능점검대상기계설비현황-24.01.24'!M:M,"오·배수 통기 및 우수배수설비")=0,0,COUNTIF('9.성능점검대상기계설비현황-24.01.24'!M:M,"오·배수 통기 및 우수배수설비")) -> 1 | AA26: 23.11.29 개정 고시 반영
F27: 오·배수 통기 및 우수배수설비 | P27: =IF(Y27=0,"×","○") -> ○ | Y27: =IF(COUNTIF('9.성능점검대상기계설비현황-24.01.24'!M:M,"오·배수 통기 및 우수배수설비")=0,0,COUNTIF('9.성능점검대상기계설비현황-24.01.24'!M:M,"오·배수 통기 및 우수배수설비")) -> 1
A28: 오수정화 및 물 재이용설비 | F28: 오수정화설비 | P28: =IF(Y28=0,"×","○") -> ○ | Y28: =IF(COUNTIF('9.성능점검대상기계설비현황-24.01.24'!M:M,"오수정화설비")=0,0,COUNTIF('9.성능점검대상기계설비현황-24.01.24'!M:M,"오수정화설비")) -> 1
F29: 물 재이용설비 | P29: =IF(Y29=0,"×","○") -> ○ | Y29: =IF(COUNTIF('9.성능점검대상기계설비현황-24.01.24'!M:M,"물 재이용설비")=0,0,COUNTIF('9.성능점검대상기계설비현황-24.01.24'!M:M,"물 재이용설비")) -> 1
A30: 배관설비 | F30: 배관설비 | P30: =IF(Y30=0,"×","○") -> ○ | Y30: =IF(COUNTIF('9.성능점검대상기계설비현황-24.01.24'!M:M,"배관설비")=0,0,COUNTIF('9.성능점검대상기계설비현황-24.01.24'!M:M,"배관설비")) -> 1
A31: 덕트설비 | F31: 덕트설비 | P31: =IF(Y31=0,"×","○") -> ○ | Y31: =IF(COUNTIF('9.성능점검대상기계설비현황-24.01.24'!M:M,"덕트설비")=0,0,COUNTIF('9.성능점검대상기계설비현황-24.01.24'!M:M,"덕트설비")) -> 1
A32: 보온설비 | F32: 보온설비(동파방지 발열선 시스템 포함) | P32: =IF(Y32=0,"×","○") -> ○ | Y32: =IF(COUNTIF('9.성능점검대상기계설비현황-24.01.24'!M:M,"보온설비")=0,0,COUNTIF('9.성능점검대상기계설비현황-24.01.24'!M:M,"보온설비")) -> 1 | AA32: 23.11.29 개정 고시 반영
A33: 자동제어설비 | F33: 자동제어설비(BEMS, 원격검침시스템, 중앙감시반, 기계실, 공조실 포함) | P33: =IF(Y33=0,"×","○") -> ○ | Y33: =IF(COUNTIF('9.성능점검대상기계설비현황-24.01.24'!M:M,"자동제어설비")=0,0,COUNTIF('9.성능점검대상기계설비현황-24.01.24'!M:M,"자동제어설비")) -> 1 | AA33: 23.11.29 개정 고시 반영
A34: 방음·방진·내진설비 | F34: 방음·방진·내진설비 | P34: =IF(Y34=0,"×","○") -> ○ | Y34: =IF(COUNTIF('9.성능점검대상기계설비현황-24.01.24'!M:M,"방음·방진·내진 설비")=0,0,COUNTIF('9.성능점검대상기계설비현황-24.01.24'!M:M,"방음·방진·내진 설비")) -> 1
A36: □ 열원 및 냉난방 설비
A37: - 냉동기 : 전체 수량의 50% 이상, 냉동기의 냉수배관과 연결된 헤더 포함
A38: - 냉각탑 : 전체 수량의 50% 이상, 점검대상 냉동기에 관련된 냉각탑에 한함
A39: - 축열조 : 축열조 및 관련 시스템 설비의 전체 수량
A40: - 보일러 : 전체 수량의 50% 이상, 보일러 주변 시스템, 응축수 탱크, 연도, 송풍기, 헤더 포함, 난방용량 42 kW 이하 제외
A41: - 열교환기 : 전체 수량의 50% 이상
A42: - 팽창탱크 : 전체 수량, 부속기기 포함
A43: - 펌프(냉·난방) : 전체수량의 20% 이상, 냉·난방 순환펌프, 냉각수 펌프 등이며 예비펌프는 제외 (동력 0.75kW이하 제외)
A45: - 신재생에너지(지열, 태양열, 연료전지 등) 전체 수량을 점검
A46: - 패키지에어컨 : 전체 수량의 20% 이상,장비 수량은 실외기 기준이며 자체 필터도 점검에 포함 (냉난방용량 7.3kW 이하 제외 (실외기 기준))
...

Sheet 9.성능점검대상기계설비현황-24.01.24
C4: 9 | E4: 성능점검 대상 기계설비 현황
L5: ="건물명 : "&정보입력!C7 -> 건물명 : 오산원당초
B6: 기계설비종류 | C6: 설비번호 | D6: 항 목 | G6: 수량 | H6: 용도 | I6: 사 양 | J6: 설치장소 | K6: 예비 | L6: 제조사 | M6: 수량 확인용
B7: 열원 및 냉·난방 설비 | C7: HX-1 | D7: 열교환기 | F7: 판형 | G7: 1 | H7: 오피스텔 3~13F 난방용 | I7: 1293000 | J7: B7F 기계실 | L7: 장한기술 | M7: 열교환기
C8: HX-2 | D8: 열교환기 | F8: 판형 | G8: 1 | H8: 오피스텔 14~24F 난방용 | I8: 1293000 | J8: B7F 기계실 | L8: 장한기술 | M8: 열교환기
C9: HX-3 | D9: 열교환기 | F9: 판형 | G9: 1 | H9: 오피스텔 25~35F 난방용 | I9: 769000 | J9: B7F 기계실 | L9: 장한기술 | M9: 열교환기
C10: HX-5 | D10: 열교환기 | F10: 판형 | G10: 1 | H10: 오피스텔 3~13F 급탕 재열용 | I10: 278000 | J10: B7F 기계실 | L10: 장한기술 | M10: 열교환기
C11: HX-6 | D11: 열교환기 | F11: 판형 | G11: 1 | H11: 오피스텔 3~13F 급탕 예열용 | I11: 278000 | J11: B7F 기계실 | L11: 장한기술 | M11: 열교환기
C12: HX-7 | D12: 열교환기 | F12: 판형 | G12: 1 | H12: 오피스텔 14~24F 급탕 재열용 | I12: 278000 | J12: B7F 기계실 | L12: 장한기술 | M12: 열교환기
C13: HX-8 | D13: 열교환기 | F13: 판형 | G13: 1 | H13: 오피스텔 14~24F 급탕 예열용 | I13: 278000 | J13: B7F 기계실 | L13: 장한기술 | M13: 열교환기
C14: HX-9 | D14: 열교환기 | F14: 판형 | G14: 1 | H14: 오피스텔 25~35F 급탕 재열용 | I14: 209000 | J14: B7F 기계실 | L14: 장한기술 | M14: 열교환기
C15: HX-10 | D15: 열교환기 | F15: 판형 | G15: 1 | H15: 오피스텔 25~35F 급탕 예열용 | I15: 209000 | J15: B7F 기계실 | L15: 장한기술 | M15: 열교환기
C16: ET-1 | D16: 팽창탱크 | F16: 펌프제어형 | G16: 1 | H16: 저층부 난방용 | I16: 1000 | J16: 판매시설 B7F 기계실 | L16: 장한기술 | M16: 팽창탱크
C17: ET-2 | D17: 팽창탱크 | F17: 펌프제어형 | G17: 1 | H17: 중층부 난방용 | I17: 1000 | J17: B7F 기계실 | L17: 장한기술 | M17: 팽창탱크
C18: ET-3 | D18: 팽창탱크 | F18: 펌프제어형 | G18: 1 | H18: 고층부 난방용 | I18: 600 | J18: B7F 기계실 | L18: 장한기술 | M18: 팽창탱크
C19: ET-4 | D19: 팽창탱크 | F19: 펌프제어형 | G19: 1 | H19: 판매 난방용 | I19: 800 | J19: B7F 기계실 | L19: 가동중단(판매) | M19: 팽창탱크
... C27: P-1-1 | D27: 난방순환펌프 | F27: IN-LINE | G27: 1 | H27: 저층부용 | I27: 11 | J27: B7F 기계실 | L27: 그런포스 | M27: 펌프
C28: P-1-2 | D28: 난방순환펌프 | F28: IN-LINE | G28: 1 | H28: 저층부용 | I28: 11 | J28: B7F 기계실 | K28: 1 | L28: 그런포스 | M28: 펌프
C29: P-2-1 | D29: 난방순환펌프 | F29: IN-LINE | G29: 1 | H29: 중층부용 | I29: 11 | J29: B7F 기계실 | L29: 그런포스 | M29: 펌프
B30: 열원 및 냉·난방 설비 | C30: P-2-2 | D30: 난방순환펌프 | F30: IN-LINE | G30: 1 | H30: 중층부용 | I30: 11 | J30: B7F 기계실 | K30: 1 | L30: 그런포스 | M30: 펌프
C31: P-3-1 | D31: 난방순환펌프 | F31: IN-LINE | G31: 1 | H31: 고층부용 | I31: 7.5 | J31: B7F 기계실 | L31: 그런포스 | M31: 펌프
C32: P-3-2 | D32: 난방순환펌프 | F32: IN-LINE | G32: 1 | H32: 고층부용 | I32: 7.5 | J32: B7F 기계실 | K32: 1 | L32: 그런포스 | M32: 펌프
C33: P-5-1 | D33: 급수펌프 | F33: 부스터 | G33: 1 | H33: 저층부용 | I33: 7.5 | J33: B7F 기계실 | L33: 그런포스 | M33: 펌프
C34: P-5-2 | D34: 급수펌프 | F34: 부스터 | G34: 1 | H34: 저층부용 | I34: 7.5 | J34: B7F 기계실 | L34: 그런포스 | M34: 펌프
C35: P-5-3 | D35: 급수펌프 | F35: 부스터 | G35: 1 | H35: 저층부용 | I35: 7.5 | J35: B7F 기계실 | L35: 그런포스 | M35: 펌프
C36: P-6-1 | D36: 급수펌프 | F36: 부스터 | G36: 1 | H36: 중층부용 | I36: 11 | J36: B7F 기계실 | L36: 그런포스 | M36: 펌프
C37: P-6-2 | D37: 급수펌프 | F37: 부스터 | G37: 1 | H37: 중층부용 | I37: 11 | J37: B7F 기계실 | L37: 그런포스 | M37: 펌프
C38: P-6-3 | D38: 급수펌프 | F38: 부스터 | G38: 1 | H38: 중층부용 | I38: 11 | J38: B7F 기계실 | L38: 그런포스 | M38: 펌프
C39: P-7-1 | D39: 급수펌프 | F39: 부스터 | G39: 1 | H39: 고층부용 | I39: 18.5 | J39: B7F 기계실 | L39: 그런포스 | M39: 펌프
C40: P-7-2 | D40: 급수펌프 | F40: 부스터 | G40: 1 | H40: 고층부용 | I40: 18.5 | J40: B7F 기계실 | L40: 그런포스 | M40: 펌프
C41: P-8-1 | D41: 급수펌프 | F41: 부스터 | G41: 1 | H41: 판매 및 영업시설 시수용 | I41: 3 | J41: 판매시설 B7F 기계실 | L41: 그런포스 | M41: 펌프
C42: P-8-2 | D42: 급수펌프 | F42: 부스터 | G42: 1 | H42: 판매 및 영업시설 시수용 | I42: 3 | J42: 판매시설 B7F 기계실 | L42: 그런포스 | M42: 펌프
C43: P-9-1 | D43: 급수펌프 | F43: 부스터 | G43: 1 | H43: 판매 및 영업시설 중수용 | I43: 5.52 | J43: 판매시설 B7F 중수실 | L43: 그런포스 | M43: 펌프
C44: P-9-2 | D44: 급수펌프 | F44: 부스터 | G44: 1 | H44: 판매 및 영업시설 중수용 | I44: 5.52 | J44: 판매시설 B7F 중수실 | L44: 그런포스 | M44: 펌프
C45: P-10-1 | D45: 급탕순환펌프 | F45: IN-LINE | G45: 1 | H45: 저층부용 | I45: 2.2 | J45: B7F 기계실 | L45: 그런포스 | M45: 펌프
C46: P-10-2 | D46: 급탕순환펌프 | F46: IN-LINE | G46: 1 | H46: 저층부용 | I46: 2.2 | J46: B7F 기계실 | K46: 1 | L46: 그런포스 | M46: 펌프
C47: P-11-1 | D47: 급탕순환펌프 | F47: IN-LINE | G47: 1 | H47: 중층부용 | I47: 2.2 | J47: B7F 기계실 | L47: 그런포스 | M47: 펌프
C48: P-11-2 | D48: 급탕순환펌프 | F48: IN-LINE | G48: 1 | H48: 중층부용 | I48: 2.2 | J48: B7F 기계실 | K48: 1 | L48: 그런포스 | M48: 펌프
C49: P-12-1 | D49: 급탕순환펌프 | F49: IN-LINE | G49: 1 | H49: 고층부용 | I49: 0.55 | J49: B7F 기계실 | L49: 그런포스 | M49: 펌프
C50: P-12-2 | D50: 급탕순환펌프 | F50: IN-LINE | G50: 1 | H50: 고층부용 | I50: 0.55 | J50: B7F 기계실 | K50: 1 | L50: 그런포스 | M50: 펌프
...

Sheet 10.기계설비성능점검계획-24.01.24
B2: 10 | D2: 기계설비 성능점검 계획
F3: 성능점검 : ○ | AA3: ="건물명 : "&정보입력!$C$7 -> 건물명 : 오산원당초 | AC3: 대상 수량 확인 | AD3: ○ | AE3: =G4 -> 2026 | AI3: =K4 -> 2027 | AM3: =O4 -> 2028 | AQ3: =S4 -> 2029 | AU3: =W4 -> 2030
A4: 기계설비 종류 | B4: 설비번호 | C4: 항 목 | F4: 수량 | G4: 2026 | K4: 2027 | O4: 2028 | S4: 2029 | W4: 2030 | AA4: 설치장소 | AE4: =G5 -> 1 | AF4: =H5 -> 5 | AG4: =I5 -> 9 | AH4: =J5 -> 12 | AI4: =K5 -> 1 | AJ4: =L5 -> 5 | AK4: =M5 -> 9 | AL4: =N5 -> 12 | ... AX4: =Z5 -> 12
G5: 1 | H5: 5 | I5: 9 | J5: 12 | K5: 1 | L5: 5 | M5: 9 | N5: 12 | O5: 1 | P5: 5 | Q5: 9 | R5: 12 | S5: 1 | T5: 5 | U5: 9 | V5: 12 | W5: 1 | X5: 5 | Y5: 9 | Z5: 12 | AB5: 수량 확인용 | AC5: =IF(VLOOKUP(AD5,'8.성능점검대상기계설비의수량-24.01.24'!$F:$Y,20,0)=SUM(AE5:AX5)/5,"OK","NOT OK") -> OK | AD5: =AZ5 -> 냉동기(헤더 포함) | AE5: =COUNTIFS($AB:$AB,$AD5,G:G,$AD$3) -> 0 | AF5: =COUNTIFS($AB:$AB,$AD5,H:H,$AD$3) -> 0 | AG5: =COUNTIFS($AB:$AB,$AD5,I:I,$AD$3) -> 0 | AH5: =COUNTIFS($AB:$AB,$AD5,J:J,$AD$3) -> 0 | AI5: =COUNTIFS($AB:$AB,$AD5,K:K,$AD$3) -> 0 | AJ5: =COUNTIFS($AB:$AB,$AD5,L:L,$AD$3) -> 0 | AK5: =COUNTIFS($AB:$AB,$AD5,M:M,$AD$3) -> 0 | AL5: =COUNTIFS($AB:$AB,$AD5,N:N,$AD$3) -> 0 | AM5: =COUNTIFS($AB:$AB,$AD5,O:O,$AD$3) -> 0 | AN5: =COUNTIFS($AB:$AB,$AD5,P:P,$AD$3) -> 0 | AO5: =COUNTIFS($AB:$AB,$AD5,Q:Q,$AD$3) -> 0 | AP5: =COUNTIFS($AB:$AB,$AD5,R:R,$AD$3) -> 0 | AQ5: =COUNTIFS($AB:$AB,$AD5,S:S,$AD$3) -> 0 | AR5: =COUNTIFS($AB:$AB,$AD5,T:T,$AD$3) -> 0 | AS5: =COUNTIFS($AB:$AB,$AD5,U:U,$AD$3) -> 0 | AT5: =COUNTIFS($AB:$AB,$AD5,V:V,$AD$3) -> 0 | AU5: =COUNTIFS($AB:$AB,$AD5,W:W,$AD$3) -> 0 | AV5: =COUNTIFS($AB:$AB,$AD5,X:X,$AD$3) -> 0 | AW5: =COUNTIFS($AB:$AB,$AD5,Y:Y,$AD$3) -> 0 | AX5: =COUNTIFS($AB:$AB,$AD5,Z:Z,$AD$3) -> 0 | AZ5: 냉동기(헤더 포함)
A6: 열원 및 냉·난방 설비 | B6: HX-1 | C6: =VLOOKUP(B6,'9.성능점검대상기계설비현황-24.01.24'!C7:L130,2,FALSE) -> 열교환기 | E6: =VLOOKUP(B6,'9.성능점검대상기계설비현황-24.01.24'!C7:L130,4,FALSE) -> 판형 | F6: 1 | G6: ○ | O6: ○ | W6: ○ | AA6: =VLOOKUP(B6,'9.성능점검대상기계설비현황-24.01.24'!$C:$L,8,0) -> B7F 기계실 | AB6: 열교환기 | AC6: =IF(VLOOKUP(AD6,'8.성능점검대상기계설비의수량-24.01.24'!$F:$Y,20,0)=SUM(AE6:AX6)/5,"OK","NOT OK") -> OK | AD6: =AZ6 -> 냉각탑(냉동기 관련) | AE6: =COUNTIFS($AB:$AB,$AD6,G:G,$AD$3) -> 0 | AF6: =COUNTIFS($AB:$AB,$AD6,H:H,$AD$3) -> 0 | AG6: =COUNTIFS($AB:$AB,$AD6,I:I,$AD$3) -> 0 | AH6: =COUNTIFS($AB:$AB,$AD6,J:J,$AD$3) -> 0 | AI6: =COUNTIFS($AB:$AB,$AD6,K:K,$AD$3) -> 0 | AJ6: =COUNTIFS($AB:$AB,$AD6,L:L,$AD$3) -> 0 | AK6: =COUNTIFS($AB:$AB,$AD6,M:M,$AD$3) -> 0 | AL6: =COUNTIFS($AB:$AB,$AD6,N:N,$AD$3) -> 0 | AM6: =COUNTIFS($AB:$AB,$AD6,O:O,$AD$3) -> 0 | AN6: =COUNTIFS($AB:$AB,$AD6,P:P,$AD$3) -> 0 | AO6: =COUNTIFS($AB:$AB,$AD6,Q:Q,$AD$3) -> 0 | AP6: =COUNTIFS($AB:$AB,$AD6,R:R,$AD$3) -> 0 | AQ6: =COUNTIFS($AB:$AB,$AD6,S:S,$AD$3) -> 0 | AR6: =COUNTIFS($AB:$AB,$AD6,T:T,$AD$3) -> 0 | AS6: =COUNTIFS($AB:$AB,$AD6,U:U,$AD$3) -> 0 | AT6: =COUNTIFS($AB:$AB,$AD6,V:V,$AD$3) -> 0 | AU6: =COUNTIFS($AB:$AB,$AD6,W:W,$AD$3) -> 0 | AV6: =COUNTIFS($AB:$AB,$AD6,X:X,$AD$3) -> 0 | AW6: =COUNTIFS($AB:$AB,$AD6,Y:Y,$AD$3) -> 0 | AX6: =COUNTIFS($AB:$AB,$AD6,Z:Z,$AD$3) -> 0 | AZ6: 냉각탑(냉동기 관련)
B7: HX-2 | C7: =VLOOKUP(B7,'9.성능점검대상기계설비현황-24.01.24'!C8:L131,2,FALSE) -> 열교환기 | E7: =VLOOKUP(B7,'9.성능점검대상기계설비현황-24.01.24'!C8:L131,4,FALSE) -> 판형 | F7: 1 | K7: ○ | O7: ○ | W7: ○ | AA7: =VLOOKUP(B7,'9.성능점검대상기계설비현황-24.01.24'!$C:$L,8,0) -> B7F 기계실 | AB7: 열교환기 | AC7: =IF(VLOOKUP(AD7,'8.성능점검대상기계설비의수량-24.01.24'!$F:$Y,20,0)=SUM(AE7:AX7)/5,"OK","NOT OK") -> OK | AD7: =AZ7 -> 축열조 | AE7: =COUNTIFS($AB:$AB,$AD7,G:G,$AD$3) -> 0 | AF7: =COUNTIFS($AB:$AB,$AD7,H:H,$AD$3) -> 0 | AG7: =COUNTIFS($AB:$AB,$AD7,I:I,$AD$3) -> 0 | AH7: =COUNTIFS($AB:$AB,$AD7,J:J,$AD$3) -> 0 | AI7: =COUNTIFS($AB:$AB,$AD7,K:K,$AD$3) -> 0 | AJ7: =COUNTIFS($AB:$AB,$AD7,L:L,$AD$3) -> 0 | AK7: =COUNTIFS($AB:$AB,$AD7,M:M,$AD$3) -> 0 | AL7: =COUNTIFS($AB:$AB,$AD7,N:N,$AD$3) -> 0 | AM7: =COUNTIFS($AB:$AB,$AD7,O:O,$AD$3) -> 0 | AN7: =COUNTIFS($AB:$AB,$AD7,P:P,$AD$3) -> 0 | AO7: =COUNTIFS($AB:$AB,$AD7,Q:Q,$AD$3) -> 0 | AP7: =COUNTIFS($AB:$AB,$AD7,R:R,$AD$3) -> 0 | AQ7: =COUNTIFS($AB:$AB,$AD7,S:S,$AD$3) -> 0 | AR7: =COUNTIFS($AB:$AB,$AD7,T:T,$AD$3) -> 0 | AS7: =COUNTIFS($AB:$AB,$AD7,U:U,$AD$3) -> 0 | AT7: =COUNTIFS($AB:$AB,$AD7,V:V,$AD$3) -> 0 | AU7: =COUNTIFS($AB:$AB,$AD7,W:W,$AD$3) -> 0 | AV7: =COUNTIFS($AB:$AB,$AD7,X:X,$AD$3) -> 0 | AW7: =COUNTIFS($AB:$AB,$AD7,Y:Y,$AD$3) -> 0 | AX7: =COUNTIFS($AB:$AB,$AD7,Z:Z,$AD$3) -> 0 | AZ7: 축열조
B8: HX-3 | C8: =VLOOKUP(B8,'9.성능점검대상기계설비현황-24.01.24'!C9:L132,2,FALSE) -> 열교환기 | E8: =VLOOKUP(B8,'9.성능점검대상기계설비현황-24.01.24'!C9:L132,4,FALSE) -> 판형 | F8: 1 | K8: ○ | S8: ○ | W8: ○ | AA8: =VLOOKUP(B8,'9.성능점검대상기계설비현황-24.01.24'!$C:$L,8,0) -> B7F 기계실 | AB8: 열교환기 | AC8: =IF(VLOOKUP(AD8,'8.성능점검대상기계설비의수량-24.01.24'!$F:$Y,20,0)=SUM(AE8:AX8)/5,"OK","NOT OK") -> OK | AD8: =AZ8 -> 보일러 (헤더 포함, 난방용량 42 kW 이하 제외) | AE8: =COUNTIFS($AB:$AB,$AD8,G:G,$AD$3) -> 0 | AF8: =COUNTIFS($AB:$AB,$AD8,H:H,$AD$3) -> 0 | AG8: =COUNTIFS($AB:$AB,$AD8,I:I,$AD$3) -> 0 | AH8: =COUNTIFS($AB:$AB,$AD8,J:J,$AD$3) -> 0 | AI8: =COUNTIFS($AB:$AB,$AD8,K:K,$AD$3) -> 0 | AJ8: =COUNTIFS($AB:$AB,$AD8,L:L,$AD$3) -> 0 | AK8: =COUNTIFS($AB:$AB,$AD8,M:M,$AD$3) -> 0 | AL8: =COUNTIFS($AB:$AB,$AD8,N:N,$AD$3) -> 0 | AM8: =COUNTIFS($AB:$AB,$AD8,O:O,$AD$3) -> 0 | AN8: =COUNTIFS($AB:$AB,$AD8,P:P,$AD$3) -> 0 | AO8: =COUNTIFS($AB:$AB,$AD8,Q:Q,$AD$3) -> 0 | AP8: =COUNTIFS($AB:$AB,$AD8,R:R,$AD$3) -> 0 | AQ8: =COUNTIFS($AB:$AB,$AD8,S:S,$AD$3) -> 0 | AR8: =COUNTIFS($AB:$AB,$AD8,T:T,$AD$3) -> 0 | AS8: =COUNTIFS($AB:$AB,$AD8,U:U,$AD$3) -> 0 | AT8: =COUNTIFS($AB:$AB,$AD8,V:V,$AD$3) -> 0 | AU8: =COUNTIFS($AB:$AB,$AD8,W:W,$AD$3) -> 0 | AV8: =COUNTIFS($AB:$AB,$AD8,X:X,$AD$3) -> 0 | AW8: =COUNTIFS($AB:$AB,$AD8,Y:Y,$AD$3) -> 0 | AX8: =COUNTIFS($AB:$AB,$AD8,Z:Z,$AD$3) -> 0 | AZ8: 보일러 (헤더 포함, 난방용량 42 kW 이하 제외)
B9: HX-5 | C9: =VLOOKUP(B9,'9.성능점검대상기계설비현황-24.01.24'!C10:L133,2,FALSE) -> 열교환기 | E9: =VLOOKUP(B9,'9.성능점검대상기계설비현황-24.01.24'!C10:L133,4,FALSE) -> 판형 | F9: 1 | K9: ○ | S9: ○ | AA9: =VLOOKUP(B9,'9.성능점검대상기계설비현황-24.01.24'!$C:$L,8,0) -> B7F 기계실 | AB9: 열교환기 | AC9: =IF(VLOOKUP(AD9,'8.성능점검대상기계설비의수량-24.01.24'!$F:$Y,20,0)=SUM(AE9:AX9)/5,"OK","NOT OK") -> OK | AD9: =AZ9 -> 열교환기 | AE9: =COUNTIFS($AB:$AB,$AD9,G:G,$AD$3) -> 5 | AF9: =COUNTIFS($AB:$AB,$AD9,H:H,$AD$3) -> 0 | AG9: =COUNTIFS($AB:$AB,$AD9,I:I,$AD$3) -> 0 | AH9: =COUNTIFS($AB:$AB,$AD9,J:J,$AD$3) -> 0 | AI9: =COUNTIFS($AB:$AB,$AD9,K:K,$AD$3) -> 5 | AJ9: =COUNTIFS($AB:$AB,$AD9,L:L,$AD$3) -> 0 | AK9: =COUNTIFS($AB:$AB,$AD9,M:M,$AD$3) -> 0 | AL9: =COUNTIFS($AB:$AB,$AD9,N:N,$AD$3) -> 0 | AM9: =COUNTIFS($AB:$AB,$AD9,O:O,$AD$3) -> 5 | AN9: =COUNTIFS($AB:$AB,$AD9,P:P,$AD$3) -> 0 | AO9: =COUNTIFS($AB:$AB,$AD9,Q:Q,$AD$3) -> 0 | AP9: =COUNTIFS($AB:$AB,$AD9,R:R,$AD$3) -> 0 | AQ9: =COUNTIFS($AB:$AB,$AD9,S:S,$AD$3) -> 5 | AR9: =COUNTIFS($AB:$AB,$AD9,T:T,$AD$3) -> 0 | AS9: =COUNTIFS($AB:$AB,$AD9,U:U,$AD$3) -> 0 | AT9: =COUNTIFS($AB:$AB,$AD9,V:V,$AD$3) -> 0 | AU9: =COUNTIFS($AB:$AB,$AD9,W:W,$AD$3) -> 5 | AV9: =COUNTIFS($AB:$AB,$AD9,X:X,$AD$3) -> 0 | AW9: =COUNTIFS($AB:$AB,$AD9,Y:Y,$AD$3) -> 0 | AX9: =COUNTIFS($AB:$AB,$AD9,Z:Z,$AD$3) -> 0 | AZ9: 열교환기
B10: HX-6 | C10: =VLOOKUP(B10,'9.성능점검대상기계설비현황-24.01.24'!C11:L134,2,FALSE) -> 열교환기 | E10: =VLOOKUP(B10,'9.성능점검대상기계설비현황-24.01.24'!C11:L134,4,FALSE) -> 판형 | F10: 1 | K10: ○ | S10: ○ | AA10: =VLOOKUP(B10,'9.성능점검대상기계설비현황-24.01.24'!$C:$L,8,0) -> B7F 기계실 | AB10: 열교환기 | AC10: =IF(VLOOKUP(AD10,'8.성능점검대상기계설비의수량-24.01.24'!$F:$Y,20,0)=SUM(AE10:AX10)/5,"OK","NOT OK") -> OK | AD10: =AZ10 -> 팽창탱크 (냉·난방, 급탕 팽창탱크 포함) | AE10: =COUNTIFS($AB:$AB,$AD10,G:G,$AD$3) -> 11 | AF10: =COUNTIFS($AB:$AB,$AD10,H:H,$AD$3) -> 0 | AG10: =COUNTIFS($AB:$AB,$AD10,I:I,$AD$3) -> 0 | AH10: =COUNTIFS($AB:$AB,$AD10,J:J,$AD$3) -> 0 | AI10: =COUNTIFS($AB:$AB,$AD10,K:K,$AD$3) -> 11 | AJ10: =COUNTIFS($AB:$AB,$AD10,L:L,$AD$3) -> 0 | AK10: =COUNTIFS($AB:$AB,$AD10,M:M,$AD$3) -> 0 | AL10: =COUNTIFS($AB:$AB,$AD10,N:N,$AD$3) -> 0 | AM10: =COUNTIFS($AB:$AB,$AD10,O:O,$AD$3) -> 11 | AN10: =COUNTIFS($AB:$AB,$AD10,P:P,$AD$3) -> 0 | AO10: =COUNTIFS($AB:$AB,$AD10,Q:Q,$AD$3) -> 0 | AP10: =COUNTIFS($AB:$AB,$AD10,R:R,$AD$3) -> 0 | AQ10: =COUNTIFS($AB:$AB,$AD10,S:S,$AD$3) -> 11 | AR10: =COUNTIFS($AB:$AB,$AD10,T:T,$AD$3) -> 0 | AS10: =COUNTIFS($AB:$AB,$AD10,U:U,$AD$3) -> 0 | AT10: =COUNTIFS($AB:$AB,$AD10,V:V,$AD$3) -> 0 | AU10: =COUNTIFS($AB:$AB,$AD10,W:W,$AD$3) -> 11 | AV10: =COUNTIFS($AB:$AB,$AD10,X:X,$AD$3) -> 0 | AW10: =COUNTIFS($AB:$AB,$AD10,Y:Y,$AD$3) -> 0 | AX10: =COUNTIFS($AB:$AB,$AD10,Z:Z,$AD$3) -> 0 | AZ10: 팽창탱크 (냉·난방, 급탕 팽창탱크 포함)
B11: HX-7 | C11: =VLOOKUP(B11,'9.성능점검대상기계설비현황-24.01.24'!C12:L135,2,FALSE) -> 열교환기 | E11: =VLOOKUP(B11,'9.성능점검대상기계설비현황-24.01.24'!C12:L135,4,FALSE) -> 판형 | F11: 1 | G11: ○ | K11: ○ | S11: ○ | AA11: =VLOOKUP(B11,'9.성능점검대상기계설비현황-24.01.24'!$C:$L,8,0) -> B7F 기계실 | AB11: 열교환기 | AC11: =IF(VLOOKUP(AD11,'8.성능점검대상기계설비의수량-24.01.24'!$F:$Y,20,0)=SUM(AE11:AX11)/5,"OK","NOT OK") -> NOT OK | AD11: =AZ11 -> 펌프(냉·난방펌프) (예비펌프, 모터동력 0.75 kW 이하 제외) | AE11: =COUNTIFS($AB:$AB,$AD11,G:G,$AD$3) -> 5 | AF11: =COUNTIFS($AB:$AB,$AD11,H:H,$AD$3) -> 0 | AG11: =COUNTIFS($AB:$AB,$AD11,I:I,$AD$3) -> 0 | AH11: =COUNTIFS($AB:$AB,$AD11,J:J,$AD$3) -> 0 | AI11: =COUNTIFS($AB:$AB,$AD11,K:K,$AD$3) -> 5 | AJ11: =COUNTIFS($AB:$AB,$AD11,L:L,$AD$3) -> 0 | AK11: =COUNTIFS($AB:$AB,$AD11,M:M,$AD$3) -> 0 | AL11: =COUNTIFS($AB:$AB,$AD11,N:N,$AD$3) -> 0 | AM11: =COUNTIFS($AB:$AB,$AD11,O:O,$AD$3) -> 5 | AN11: =COUNTIFS($AB:$AB,$AD11,P:P,$AD$3) -> 0 | AO11: =COUNTIFS($AB:$AB,$AD11,Q:Q,$AD$3) -> 0 | AP11: =COUNTIFS($AB:$AB,$AD11,R:R,$AD$3) -> 0 | AQ11: =COUNTIFS($AB:$AB,$AD11,S:S,$AD$3) -> 5 | AR11: =COUNTIFS($AB:$AB,$AD11,T:T,$AD$3) -> 0 | AS11: =COUNTIFS($AB:$AB,$AD11,U:U,$AD$3) -> 0 | AT11: =COUNTIFS($AB:$AB,$AD11,V:V,$AD$3) -> 0 | AU11: =COUNTIFS($AB:$AB,$AD11,W:W,$AD$3) -> 5 | AV11: =COUNTIFS($AB:$AB,$AD11,X:X,$AD$3) -> 0 | AW11: =COUNTIFS($AB:$AB,$AD11,Y:Y,$AD$3) -> 0 | AX11: =COUNTIFS($AB:$AB,$AD11,Z:Z,$AD$3) -> 0 | AZ11: 펌프(냉·난방펌프) (예비펌프, 모터동력 0.75 kW 이하 제외)
B12: HX-8 | C12: =VLOOKUP(B12,'9.성능점검대상기계설비현황-24.01.24'!C13:L136,2,FALSE) -> 열교환기 | E12: =VLOOKUP(B12,'9.성능점검대상기계설비현황-24.01.24'!C13:L136,4,FALSE) -> 판형 | F12: 1 | G12: ○ | O12: ○ | S12: ○ | AA12: =VLOOKUP(B12,'9.성능점검대상기계설비현황-24.01.24'!$C:$L,8,0) -> B7F 기계실 | AB12: 열교환기 | AC12: =IF(VLOOKUP(AD12,'8.성능점검대상기계설비의수량-24.01.24'!$F:$Y,20,0)=SUM(AE12:AX12)/5,"OK","NOT OK") -> OK | AD12: =AZ12 -> 신재생에너지(지열) | AE12: =COUNTIFS($AB:$AB,$AD12,G:G,$AD$3) -> 0 | AF12: =COUNTIFS($AB:$AB,$AD12,H:H,$AD$3) -> 0 | AG12: =COUNTIFS($AB:$AB,$AD12,I:I,$AD$3) -> 0 | AH12: =COUNTIFS($AB:$AB,$AD12,J:J,$AD$3) -> 0 | AI12: =COUNTIFS($AB:$AB,$AD12,K:K,$AD$3) -> 0 | AJ12: =COUNTIFS($AB:$AB,$AD12,L:L,$AD$3) -> 0 | AK12: =COUNTIFS($AB:$AB,$AD12,M:M,$AD$3) -> 0 | AL12: =COUNTIFS($AB:$AB,$AD12,N:N,$AD$3) -> 0 | AM12: =COUNTIFS($AB:$AB,$AD12,O:O,$AD$3) -> 0 | AN12: =COUNTIFS($AB:$AB,$AD12,P:P,$AD$3) -> 0 | AO12: =COUNTIFS($AB:$AB,$AD12,Q:Q,$AD$3) -> 0 | AP12: =COUNTIFS($AB:$AB,$AD12,R:R,$AD$3) -> 0 | AQ12: =COUNTIFS($AB:$AB,$AD12,S:S,$AD$3) -> 0 | AR12: =COUNTIFS($AB:$AB,$AD12,T:T,$AD$3) -> 0 | AS12: =COUNTIFS($AB:$AB,$AD12,U:U,$AD$3) -> 0 | AT12: =COUNTIFS($AB:$AB,$AD12,V:V,$AD$3) -> 0 | AU12: =COUNTIFS($AB:$AB,$AD12,W:W,$AD$3) -> 0 | AV12: =COUNTIFS($AB:$AB,$AD12,X:X,$AD$3) -> 0 | AW12: =COUNTIFS($AB:$AB,$AD12,Y:Y,$AD$3) -> 0 | AX12: =COUNTIFS($AB:$AB,$AD12,Z:Z,$AD$3) -> 0 | AZ12: 신재생에너지(지열)
B13: HX-9 | C13: =VLOOKUP(B13,'9.성능점검대상기계설비현황-24.01.24'!C14:L137,2,FALSE) -> 열교환기 | E13: =VLOOKUP(B13,'9.성능점검대상기계설비현황-24.01.24'!C14:L137,4,FALSE) -> 판형 | F13: 1 | G13: ○ | O13: ○ | W13: ○ | AA13: =VLOOKUP(B13,'9.성능점검대상기계설비현황-24.01.24'!$C:$L,8,0) -> B7F 기계실 | AB13: 열교환기 | AC13: =IF(VLOOKUP(AD13,'8.성능점검대상기계설비의수량-24.01.24'!$F:$Y,20,0)=SUM(AE13:AX13)/5,"OK","NOT OK") -> OK | AD13: =AZ13 -> 신재생에너지(태양열) | AE13: =COUNTIFS($AB:$AB,$AD13,G:G,$AD$3) -> 0 | AF13: =COUNTIFS($AB:$AB,$AD13,H:H,$AD$3) -> 0 | AG13: =COUNTIFS($AB:$AB,$AD13,I:I,$AD$3) -> 0 | AH13: =COUNTIFS($AB:$AB,$AD13,J:J,$AD$3) -> 0 | AI13: =COUNTIFS($AB:$AB,$AD13,K:K,$AD$3) -> 0 | AJ13: =COUNTIFS($AB:$AB,$AD13,L:L,$AD$3) -> 0 | AK13: =COUNTIFS($AB:$AB,$AD13,M:M,$AD$3) -> 0 | AL13: =COUNTIFS($AB:$AB,$AD13,N:N,$AD$3) -> 0 | AM13: =COUNTIFS($AB:$AB,$AD13,O:O,$AD$3) -> 0 | AN13: =COUNTIFS($AB:$AB,$AD13,P:P,$AD$3) -> 0 | AO13: =COUNTIFS($AB:$AB,$AD13,Q:Q,$AD$3) -> 0 | AP13: =COUNTIFS($AB:$AB,$AD13,R:R,$AD$3) -> 0 | AQ13: =COUNTIFS($AB:$AB,$AD13,S:S,$AD$3) -> 0 | AR13: =COUNTIFS($AB:$AB,$AD13,T:T,$AD$3) -> 0 | AS13: =COUNTIFS($AB:$AB,$AD13,U:U,$AD$3) -> 0 | AT13: =COUNTIFS($AB:$AB,$AD13,V:V,$AD$3) -> 0 | AU13: =COUNTIFS($AB:$AB,$AD13,W:W,$AD$3) -> 0 | AV13: =COUNTIFS($AB:$AB,$AD13,X:X,$AD$3) -> 0 | AW13: =COUNTIFS($AB:$AB,$AD13,Y:Y,$AD$3) -> 0 | AX13: =COUNTIFS($AB:$AB,$AD13,Z:Z,$AD$3) -> 0 | AZ13: 신재생에너지(태양열)
B14: HX-10 | C14: =VLOOKUP(B14,'9.성능점검대상기계설비현황-24.01.24'!C15:L138,2,FALSE) -> 열교환기 | E14: =VLOOKUP(B14,'9.성능점검대상기계설비현황-24.01.24'!C15:L138,4,FALSE) -> 판형 | F14: 1 | G14: ○ | O14: ○ | W14: ○ | AA14: =VLOOKUP(B14,'9.성능점검대상기계설비현황-24.01.24'!$C:$L,8,0) -> B7F 기계실 | AB14: 열교환기 | AC14: =IF(VLOOKUP(AD14,'8.성능점검대상기계설비의수량-24.01.24'!$F:$Y,20,0)=SUM(AE14:AX14)/5,"OK","NOT OK") -> OK | AD14: =AZ14 -> 신재생에너지(연료전지) | AE14: =COUNTIFS($AB:$AB,$AD14,G:G,$AD$3) -> 0 | AF14: =COUNTIFS($AB:$AB,$AD14,H:H,$AD$3) -> 0 | AG14: =COUNTIFS($AB:$AB,$AD14,I:I,$AD$3) -> 0 | AH14: =COUNTIFS($AB:$AB,$AD14,J:J,$AD$3) -> 0 | AI14: =COUNTIFS($AB:$AB,$AD14,K:K,$AD$3) -> 0 | AJ14: =COUNTIFS($AB:$AB,$AD14,L:L,$AD$3) -> 0 | AK14: =COUNTIFS($AB:$AB,$AD14,M:M,$AD$3) -> 0 | AL14: =COUNTIFS($AB:$AB,$AD14,N:N,$AD$3) -> 0 | AM14: =COUNTIFS($AB:$AB,$AD14,O:O,$AD$3) -> 0 | AN14: =COUNTIFS($AB:$AB,$AD14,P:P,$AD$3) -> 0 | AO14: =COUNTIFS($AB:$AB,$AD14,Q:Q,$AD$3) -> 0 | AP14: =COUNTIFS($AB:$AB,$AD14,R:R,$AD$3) -> 0 | AQ14: =COUNTIFS($AB:$AB,$AD14,S:S,$AD$3) -> 0 | AR14: =COUNTIFS($AB:$AB,$AD14,T:T,$AD$3) -> 0 | AS14: =COUNTIFS($AB:$AB,$AD14,U:U,$AD$3) -> 0 | AT14: =COUNTIFS($AB:$AB,$AD14,V:V,$AD$3) -> 0 | AU14: =COUNTIFS($AB:$AB,$AD14,W:W,$AD$3) -> 0 | AV14: =COUNTIFS($AB:$AB,$AD14,X:X,$AD$3) -> 0 | AW14: =COUNTIFS($AB:$AB,$AD14,Y:Y,$AD$3) -> 0 | AX14: =COUNTIFS($AB:$AB,$AD14,Z:Z,$AD$3) -> 0 | AZ14: 신재생에너지(연료전지)
B15: ET-1 | C15: =VLOOKUP(B15,'9.성능점검대상기계설비현황-24.01.24'!C16:L139,2,FALSE) -> 팽창탱크 | E15: =VLOOKUP(B15,'9.성능점검대상기계설비현황-24.01.24'!C16:L139,4,FALSE) -> 펌프제어형 | F15: 1 | G15: ○ | K15: ○ | O15: ○ | S15: ○ | W15: ○ | AA15: =VLOOKUP(B15,'9.성능점검대상기계설비현황-24.01.24'!$C:$L,8,0) -> 판매시설 B7F 기계실 | AB15: 팽창탱크 (냉·난방, 급탕 팽창탱크 포함) | AC15: =IF(VLOOKUP(AD15,'8.성능점검대상기계설비의수량-24.01.24'!$F:$Y,20,0)=SUM(AE15:AX15)/5,"OK","NOT OK") -> OK | AD15: =AZ15 -> 패키지에어컨 (냉·난방용량 7.3 kW 이하 제외(실외기 기준), 내부필터 포함) | AE15: =COUNTIFS($AB:$AB,$AD15,G:G,$AD$3) -> 5 | AF15: =COUNTIFS($AB:$AB,$AD15,H:H,$AD$3) -> 0 | AG15: =COUNTIFS($AB:$AB,$AD15,I:I,$AD$3) -> 0 | AH15: =COUNTIFS($AB:$AB,$AD15,J:J,$AD$3) -> 0 | AI15: =COUNTIFS($AB:$AB,$AD15,K:K,$AD$3) -> 5 | AJ15: =COUNTIFS($AB:$AB,$AD15,L:L,$AD$3) -> 0 | AK15: =COUNTIFS($AB:$AB,$AD15,M:M,$AD$3) -> 0 | AL15: =COUNTIFS($AB:$AB,$AD15,N:N,$AD$3) -> 0 | AM15: =COUNTIFS($AB:$AB,$AD15,O:O,$AD$3) -> 5 | AN15: =COUNTIFS($AB:$AB,$AD15,P:P,$AD$3) -> 0 | AO15: =COUNTIFS($AB:$AB,$AD15,Q:Q,$AD$3) -> 0 | AP15: =COUNTIFS($AB:$AB,$AD15,R:R,$AD$3) -> 0 | AQ15: =COUNTIFS($AB:$AB,$AD15,S:S,$AD$3) -> 5 | AR15: =COUNTIFS($AB:$AB,$AD15,T:T,$AD$3) -> 0 | AS15: =COUNTIFS($AB:$AB,$AD15,U:U,$AD$3) -> 0 | AT15: =COUNTIFS($AB:$AB,$AD15,V:V,$AD$3) -> 0 | AU15: =COUNTIFS($AB:$AB,$AD15,W:W,$AD$3) -> 5 | AV15: =COUNTIFS($AB:$AB,$AD15,X:X,$AD$3) -> 0 | AW15: =COUNTIFS($AB:$AB,$AD15,Y:Y,$AD$3) -> 0 | AX15: =COUNTIFS($AB:$AB,$AD15,Z:Z,$AD$3) -> 0 | AZ15: 패키지에어컨 (냉·난방용량 7.3 kW 이하 제외(실외기 기준), 내부필터 포함)
B16: ET-2 | C16: =VLOOKUP(B16,'9.성능점검대상기계설비현황-24.01.24'!C17:L140,2,FALSE) -> 팽창탱크 | E16: =VLOOKUP(B16,'9.성능점검대상기계설비현황-24.01.24'!C17:L140,4,FALSE) -> 펌프제어형 | F16: 1 | G16: ○ | K16: ○ | O16: ○ | S16: ○ | W16: ○ | AA16: =VLOOKUP(B16,'9.성능점검대상기계설비현황-24.01.24'!$C:$L,8,0) -> B7F 기계실 | AB16: 팽창탱크 (냉·난방, 급탕 팽창탱크 포함) | AC16: =IF(VLOOKUP(AD16,'8.성능점검대상기계설비의수량-24.01.24'!$F:$Y,20,0)=SUM(AE16:AX16)/5,"OK","NOT OK") -> OK | AD16: =AZ16 -> 항온항습기(내부필터 포함) | AE16: =COUNTIFS($AB:$AB,$AD16,G:G,$AD$3) -> 0 | AF16: =COUNTIFS($AB:$AB,$AD16,H:H,$AD$3) -> 0 | AG16: =COUNTIFS($AB:$AB,$AD16,I:I,$AD$3) -> 0 | AH16: =COUNTIFS($AB:$AB,$AD16,J:J,$AD$3) -> 0 | AI16: =COUNTIFS($AB:$AB,$AD16,K:K,$AD$3) -> 0 | AJ16: =COUNTIFS($AB:$AB,$AD16,L:L,$AD$3) -> 0 | AK16: =COUNTIFS($AB:$AB,$AD16,M:M,$AD$3) -> 0 | AL16: =COUNTIFS($AB:$AB,$AD16,N:N,$AD$3) -> 0 | AM16: =COUNTIFS($AB:$AB,$AD16,O:O,$AD$3) -> 0 | AN16: =COUNTIFS($AB:$AB,$AD16,P:P,$AD$3) -> 0 | AO16: =COUNTIFS($AB:$AB,$AD16,Q:Q,$AD$3) -> 0 | AP16: =COUNTIFS($AB:$AB,$AD16,R:R,$AD$3) -> 0 | AQ16: =COUNTIFS($AB:$AB,$AD16,S:S,$AD$3) -> 0 | AR16: =COUNTIFS($AB:$AB,$AD16,T:T,$AD$3) -> 0 | AS16: =COUNTIFS($AB:$AB,$AD16,U:U,$AD$3) -> 0 | AT16: =COUNTIFS($AB:$AB,$AD16,V:V,$AD$3) -> 0 | AU16: =COUNTIFS($AB:$AB,$AD16,W:W,$AD$3) -> 0 | AV16: =COUNTIFS($AB:$AB,$AD16,X:X,$AD$3) -> 0 | AW16: =COUNTIFS($AB:$AB,$AD16,Y:Y,$AD$3) -> 0 | AX16: =COUNTIFS($AB:$AB,$AD16,Z:Z,$AD$3) -> 0 | AZ16: 항온항습기(내부필터 포함)
B17: ET-3 | C17: =VLOOKUP(B17,'9.성능점검대상기계설비현황-24.01.24'!C18:L141,2,FALSE) -> 팽창탱크 | E17: =VLOOKUP(B17,'9.성능점검대상기계설비현황-24.01.24'!C18:L141,4,FALSE) -> 펌프제어형 | F17: 1 | G17: ○ | K17: ○ | O17: ○ | S17: ○ | W17: ○ | AA17: =VLOOKUP(B17,'9.성능점검대상기계설비현황-24.01.24'!$C:$L,8,0) -> B7F 기계실 | AB17: 팽창탱크 (냉·난방, 급탕 팽창탱크 포함) | AC17: =IF(VLOOKUP(AD17,'8.성능점검대상기계설비의수량-24.01.24'!$F:$Y,20,0)=SUM(AE17:AX17)/5,"OK","NOT OK") -> OK | AD17: =AZ17 -> 공기조화기(송풍기포함, 내부필터 포함) | AE17: =COUNTIFS($AB:$AB,$AD17,G:G,$AD$3) -> 0 | AF17: =COUNTIFS($AB:$AB,$AD17,H:H,$AD$3) -> 0 | AG17: =COUNTIFS($AB:$AB,$AD17,I:I,$AD$3) -> 0 | AH17: =COUNTIFS($AB:$AB,$AD17,J:J,$AD$3) -> 0 | AI17: =COUNTIFS($AB:$AB,$AD17,K:K,$AD$3) -> 0 | AJ17: =COUNTIFS($AB:$AB,$AD17,L:L,$AD$3) -> 0 | AK17: =COUNTIFS($AB:$AB,$AD17,M:M,$AD$3) -> 0 | AL17: =COUNTIFS($AB:$AB,$AD17,N:N,$AD$3) -> 0 | AM17: =COUNTIFS($AB:$AB,$AD17,O:O,$AD$3) -> 0 | AN17: =COUNTIFS($AB:$AB,$AD17,P:P,$AD$3) -> 0 | AO17: =COUNTIFS($AB:$AB,$AD17,Q:Q,$AD$3) -> 0 | AP17: =COUNTIFS($AB:$AB,$AD17,R:R,$AD$3) -> 0 | AQ17: =COUNTIFS($AB:$AB,$AD17,S:S,$AD$3) -> 0 | AR17: =COUNTIFS($AB:$AB,$AD17,T:T,$AD$3) -> 0 | AS17: =COUNTIFS($AB:$AB,$AD17,U:U,$AD$3) -> 0 | AT17: =COUNTIFS($AB:$AB,$AD17,V:V,$AD$3) -> 0 | AU17: =COUNTIFS($AB:$AB,$AD17,W:W,$AD$3) -> 0 | AV17: =COUNTIFS($AB:$AB,$AD17,X:X,$AD$3) -> 0 | AW17: =COUNTIFS($AB:$AB,$AD17,Y:Y,$AD$3) -> 0 | AX17: =COUNTIFS($AB:$AB,$AD17,Z:Z,$AD$3) -> 0 | AZ17: 공기조화기(송풍기포함, 내부필터 포함)
B18: ET-4 | C18: =VLOOKUP(B18,'9.성능점검대상기계설비현황-24.01.24'!C19:L142,2,FALSE) -> 팽창탱크 | E18: =VLOOKUP(B18,'9.성능점검대상기계설비현황-24.01.24'!C19:L142,4,FALSE) -> 펌프제어형 | F18: 1 | G18: ○ | K18: ○ | O18: ○ | S18: ○ | W18: ○ | AA18: =VLOOKUP(B18,'9.성능점검대상기계설비현황-24.01.24'!$C:$L,8,0) -> B7F 기계실 | AB18: 팽창탱크 (냉·난방, 급탕 팽창탱크 포함) | AC18: =IF(VLOOKUP(AD18,'8.성능점검대상기계설비의수량-24.01.24'!$F:$Y,20,0)=SUM(AE18:AX18)/5,"OK","NOT OK") -> OK | AD18: =AZ18 -> 팬코일 유닛(유니트 기준, 내부필터 포함) | AE18: =COUNTIFS($AB:$AB,$AD18,G:G,$AD$3) -> 0 | AF18: =COUNTIFS($AB:$AB,$AD18,H:H,$AD$3) -> 0 | AG18: =COUNTIFS($AB:$AB,$AD18,I:I,$AD$3) -> 0 | AH18: =COUNTIFS($AB:$AB,$AD18,J:J,$AD$3) -> 0 | AI18: =COUNTIFS($AB:$AB,$AD18,K:K,$AD$3) -> 0 | AJ18: =COUNTIFS($AB:$AB,$AD18,L:L,$AD$3) -> 0 | AK18: =COUNTIFS($AB:$AB,$AD18,M:M,$AD$3) -> 0 | AL18: =COUNTIFS($AB:$AB,$AD18,N:N,$AD$3) -> 0 | AM18: =COUNTIFS($AB:$AB,$AD18,O:O,$AD$3) -> 0 | AN18: =COUNTIFS($AB:$AB,$AD18,P:P,$AD$3) -> 0 | AO18: =COUNTIFS($AB:$AB,$AD18,Q:Q,$AD$3) -> 0 | AP18: =COUNTIFS($AB:$AB,$AD18,R:R,$AD$3) -> 0 | AQ18: =COUNTIFS($AB:$AB,$AD18,S:S,$AD$3) -> 0 | AR18: =COUNTIFS($AB:$AB,$AD18,T:T,$AD$3) -> 0 | AS18: =COUNTIFS($AB:$AB,$AD18,U:U,$AD$3) -> 0 | AT18: =COUNTIFS($AB:$AB,$AD18,V:V,$AD$3) -> 0 | AU18: =COUNTIFS($AB:$AB,$AD18,W:W,$AD$3) -> 0 | AV18: =COUNTIFS($AB:$AB,$AD18,X:X,$AD$3) -> 0 | AW18: =COUNTIFS($AB:$AB,$AD18,Y:Y,$AD$3) -> 0 | AX18: =COUNTIFS($AB:$AB,$AD18,Z:Z,$AD$3) -> 0 | AZ18: 팬코일 유닛(유니트 기준, 내부필터 포함)
B19: ET-5 | C19: =VLOOKUP(B19,'9.성능점검대상기계설비현황-24.01.24'!C20:L143,2,FALSE) -> 팽창탱크 | E19: =VLOOKUP(B19,'9.성능점검대상기계설비현황-24.01.24'!C20:L143,4,FALSE) -> 밀폐형 | F19: 1 | G19: ○ | K19: ○ | O19: ○ | S19: ○ | W19: ○ | AA19: =VLOOKUP(B19,'9.성능점검대상기계설비현황-24.01.24'!$C:$L,8,0) -> B7F 기계실 | AB19: 팽창탱크 (냉·난방, 급탕 팽창탱크 포함) | AC19: =IF(VLOOKUP(AD19,'8.성능점검대상기계설비의수량-24.01.24'!$F:$Y,20,0)=SUM(AE19:AX19)/5,"OK","NOT OK") -> OK | AD19: =AZ19 -> 환기설비 (모터동력 0.75 kW 이하 및 벽부형 제외) | AE19: =COUNTIFS($AB:$AB,$AD19,G:G,$AD$3) -> 11 | AF19: =COUNTIFS($AB:$AB,$AD19,H:H,$AD$3) -> 0 | AG19: =COUNTIFS($AB:$AB,$AD19,I:I,$AD$3) -> 0 | AH19: =COUNTIFS($AB:$AB,$AD19,J:J,$AD$3) -> 0 | AI19: =COUNTIFS($AB:$AB,$AD19,K:K,$AD$3) -> 11 | AJ19: =COUNTIFS($AB:$AB,$AD19,L:L,$AD$3) -> 0 | AK19: =COUNTIFS($AB:$AB,$AD19,M:M,$AD$3) -> 0 | AL19: =COUNTIFS($AB:$AB,$AD19,N:N,$AD$3) -> 0 | AM19: =COUNTIFS($AB:$AB,$AD19,O:O,$AD$3) -> 11 | AN19: =COUNTIFS($AB:$AB,$AD19,P:P,$AD$3) -> 0 | AO19: =COUNTIFS($AB:$AB,$AD19,Q:Q,$AD$3) -> 0 | AP19: =COUNTIFS($AB:$AB,$AD19,R:R,$AD$3) -> 0 | AQ19: =COUNTIFS($AB:$AB,$AD19,S:S,$AD$3) -> 11 | AR19: =COUNTIFS($AB:$AB,$AD19,T:T,$AD$3) -> 0 | AS19: =COUNTIFS($AB:$AB,$AD19,U:U,$AD$3) -> 0 | AT19: =COUNTIFS($AB:$AB,$AD19,V:V,$AD$3) -> 0 | AU19: =COUNTIFS($AB:$AB,$AD19,W:W,$AD$3) -> 11 | AV19: =COUNTIFS($AB:$AB,$AD19,X:X,$AD$3) -> 0 | AW19: =COUNTIFS($AB:$AB,$AD19,Y:Y,$AD$3) -> 0 | AX19: =COUNTIFS($AB:$AB,$AD19,Z:Z,$AD$3) -> 0 | AZ19: 환기설비 (모터동력 0.75 kW 이하 및 벽부형 제외)
B20: ET-6 | C20: =VLOOKUP(B20,'9.성능점검대상기계설비현황-24.01.24'!C21:L144,2,FALSE) -> 팽창탱크 | E20: =VLOOKUP(B20,'9.성능점검대상기계설비현황-24.01.24'!C21:L144,4,FALSE) -> 밀폐형 | F20: 1 | G20: ○ | K20: ○ | O20: ○ | S20: ○ | W20: ○ | AA20: =VLOOKUP(B20,'9.성능점검대상기계설비현황-24.01.24'!$C:$L,8,0) -> B7F 기계실 | AB20: 팽창탱크 (냉·난방, 급탕 팽창탱크 포함) | AC20: =IF(VLOOKUP(AD20,'8.성능점검대상기계설비의수량-24.01.24'!$F:$Y,20,0)=SUM(AE20:AX20)/5,"OK","NOT OK") -> OK | AD20: =AZ20 -> 필 터 (필터유닛,냄새제거 필터유닛, 특수목적필터 등 포함) | AE20: =COUNTIFS($AB:$AB,$AD20,G:G,$AD$3) -> 0 | AF20: =COUNTIFS($AB:$AB,$AD20,H:H,$AD$3) -> 0 | AG20: =COUNTIFS($AB:$AB,$AD20,I:I,$AD$3) -> 0 | AH20: =COUNTIFS($AB:$AB,$AD20,J:J,$AD$3) -> 0 | AI20: =COUNTIFS($AB:$AB,$AD20,K:K,$AD$3) -> 0 | AJ20: =COUNTIFS($AB:$AB,$AD20,L:L,$AD$3) -> 0 | AK20: =COUNTIFS($AB:$AB,$AD20,M:M,$AD$3) -> 0 | AL20: =COUNTIFS($AB:$AB,$AD20,N:N,$AD$3) -> 0 | AM20: =COUNTIFS($AB:$AB,$AD20,O:O,$AD$3) -> 0 | AN20: =COUNTIFS($AB:$AB,$AD20,P:P,$AD$3) -> 0 | AO20: =COUNTIFS($AB:$AB,$AD20,Q:Q,$AD$3) -> 0 | AP20: =COUNTIFS($AB:$AB,$AD20,R:R,$AD$3) -> 0 | AQ20: =COUNTIFS($AB:$AB,$AD20,S:S,$AD$3) -> 0 | AR20: =COUNTIFS($AB:$AB,$AD20,T:T,$AD$3) -> 0 | AS20: =COUNTIFS($AB:$AB,$AD20,U:U,$AD$3) -> 0 | AT20: =COUNTIFS($AB:$AB,$AD20,V:V,$AD$3) -> 0 | AU20: =COUNTIFS($AB:$AB,$AD20,W:W,$AD$3) -> 0 | AV20: =COUNTIFS($AB:$AB,$AD20,X:X,$AD$3) -> 0 | AW20: =COUNTIFS($AB:$AB,$AD20,Y:Y,$AD$3) -> 0 | AX20: =COUNTIFS($AB:$AB,$AD20,Z:Z,$AD$3) -> 0 | AZ20: 필 터 (필터유닛,냄새제거 필터유닛, 특수목적필터 등 포함)
B21: ET-7 | C21: =VLOOKUP(B21,'9.성능점검대상기계설비현황-24.01.24'!C22:L145,2,FALSE) -> 팽창탱크 | E21: =VLOOKUP(B21,'9.성능점검대상기계설비현황-24.01.24'!C22:L145,4,FALSE) -> 밀폐형 | F21: 1 | G21: ○ | K21: ○ | O21: ○ | S21: ○ | W21: ○ | AA21: =VLOOKUP(B21,'9.성능점검대상기계설비현황-24.01.24'!$C:$L,8,0) -> B7F 기계실 | AB21: 팽창탱크 (냉·난방, 급탕 팽창탱크 포함) | AC21: =IF(VLOOKUP(AD21,'8.성능점검대상기계설비의수량-24.01.24'!$F:$Y,20,0)=SUM(AE21:AX21)/5,"OK","NOT OK") -> OK | AD21: =AZ21 -> 위생기구설비 | AE21: =COUNTIFS($AB:$AB,$AD21,G:G,$AD$3) -> 1 | AF21: =COUNTIFS($AB:$AB,$AD21,H:H,$AD$3) -> 0 | AG21: =COUNTIFS($AB:$AB,$AD21,I:I,$AD$3) -> 0 | AH21: =COUNTIFS($AB:$AB,$AD21,J:J,$AD$3) -> 0 | AI21: =COUNTIFS($AB:$AB,$AD21,K:K,$AD$3) -> 1 | AJ21: =COUNTIFS($AB:$AB,$AD21,L:L,$AD$3) -> 0 | AK21: =COUNTIFS($AB:$AB,$AD21,M:M,$AD$3) -> 0 | AL21: =COUNTIFS($AB:$AB,$AD21,N:N,$AD$3) -> 0 | AM21: =COUNTIFS($AB:$AB,$AD21,O:O,$AD$3) -> 1 | AN21: =COUNTIFS($AB:$AB,$AD21,P:P,$AD$3) -> 0 | AO21: =COUNTIFS($AB:$AB,$AD21,Q:Q,$AD$3) -> 0 | AP21: =COUNTIFS($AB:$AB,$AD21,R:R,$AD$3) -> 0 | AQ21: =COUNTIFS($AB:$AB,$AD21,S:S,$AD$3) -> 1 | AR21: =COUNTIFS($AB:$AB,$AD21,T:T,$AD$3) -> 0 | AS21: =COUNTIFS($AB:$AB,$AD21,U:U,$AD$3) -> 0 | AT21: =COUNTIFS($AB:$AB,$AD21,V:V,$AD$3) -> 0 | AU21: =COUNTIFS($AB:$AB,$AD21,W:W,$AD$3) -> 1 | AV21: =COUNTIFS($AB:$AB,$AD21,X:X,$AD$3) -> 0 | AW21: =COUNTIFS($AB:$AB,$AD21,Y:Y,$AD$3) -> 0 | AX21: =COUNTIFS($AB:$AB,$AD21,Z:Z,$AD$3) -> 0 | AZ21: 위생기구설비
B22: ET-8 | C22: =VLOOKUP(B22,'9.성능점검대상기계설비현황-24.01.24'!C23:L146,2,FALSE) -> 팽창탱크 | E22: =VLOOKUP(B22,'9.성능점검대상기계설비현황-24.01.24'!C23:L146,4,FALSE) -> 밀폐형 | F22: 1 | G22: ○ | K22: ○ | O22: ○ | S22: ○ | W22: ○ | AA22: =VLOOKUP(B22,'9.성능점검대상기계설비현황-24.01.24'!$C:$L,8,0) -> B7F 기계실 | AB22: 팽창탱크 (냉·난방, 급탕 팽창탱크 포함) | AC22: =IF(VLOOKUP(AD22,'8.성능점검대상기계설비의수량-24.01.24'!$F:$Y,20,0)=SUM(AE22:AX22)/5,"OK","NOT OK") -> OK | AD22: =AZ22 -> 급수펌프, 급탕탱크 등 (모터동력 0.75 kW 이하 제외) | AE22: =COUNTIFS($AB:$AB,$AD22,G:G,$AD$3) -> 1 | AF22: =COUNTIFS($AB:$AB,$AD22,H:H,$AD$3) -> 0 | AG22: =COUNTIFS($AB:$AB,$AD22,I:I,$AD$3) -> 0 | AH22: =COUNTIFS($AB:$AB,$AD22,J:J,$AD$3) -> 0 | AI22: =COUNTIFS($AB:$AB,$AD22,K:K,$AD$3) -> 1 | AJ22: =COUNTIFS($AB:$AB,$AD22,L:L,$AD$3) -> 0 | AK22: =COUNTIFS($AB:$AB,$AD22,M:M,$AD$3) -> 0 | AL22: =COUNTIFS($AB:$AB,$AD22,N:N,$AD$3) -> 0 | AM22: =COUNTIFS($AB:$AB,$AD22,O:O,$AD$3) -> 1 | AN22: =COUNTIFS($AB:$AB,$AD22,P:P,$AD$3) -> 0 | AO22: =COUNTIFS($AB:$AB,$AD22,Q:Q,$AD$3) -> 0 | AP22: =COUNTIFS($AB:$AB,$AD22,R:R,$AD$3) -> 0 | AQ22: =COUNTIFS($AB:$AB,$AD22,S:S,$AD$3) -> 1 | AR22: =COUNTIFS($AB:$AB,$AD22,T:T,$AD$3) -> 0 | AS22: =COUNTIFS($AB:$AB,$AD22,U:U,$AD$3) -> 0 | AT22: =COUNTIFS($AB:$AB,$AD22,V:V,$AD$3) -> 0 | AU22: =COUNTIFS($AB:$AB,$AD22,W:W,$AD$3) -> 1 | AV22: =COUNTIFS($AB:$AB,$AD22,X:X,$AD$3) -> 0 | AW22: =COUNTIFS($AB:$AB,$AD22,Y:Y,$AD$3) -> 0 | AX22: =COUNTIFS($AB:$AB,$AD22,Z:Z,$AD$3) -> 0 | AZ22: 급수펌프, 급탕탱크 등 (모터동력 0.75 kW 이하 제외)
B23: ET-9 | C23: =VLOOKUP(B23,'9.성능점검대상기계설비현황-24.01.24'!C24:L147,2,FALSE) -> 팽창탱크 | E23: =VLOOKUP(B23,'9.성능점검대상기계설비현황-24.01.24'!C24:L147,4,FALSE) -> 밀폐형 | F23: 1 | G23: ○ | K23: ○ | O23: ○ | S23: ○ | W23: ○ | AA23: =VLOOKUP(B23,'9.성능점검대상기계설비현황-24.01.24'!$C:$L,8,0) -> B7F 기계실 | AB23: 팽창탱크 (냉·난방, 급탕 팽창탱크 포함) | AC23: =IF(VLOOKUP(AD23,'8.성능점검대상기계설비의수량-24.01.24'!$F:$Y,20,0)=SUM(AE23:AX23)/5,"OK","NOT OK") -> OK | AD23: =AZ23 -> 고·저수조 | AE23: =COUNTIFS($AB:$AB,$AD23,G:G,$AD$3) -> 1 | AF23: =COUNTIFS($AB:$AB,$AD23,H:H,$AD$3) -> 0 | AG23: =COUNTIFS($AB:$AB,$AD23,I:I,$AD$3) -> 0 | AH23: =COUNTIFS($AB:$AB,$AD23,J:J,$AD$3) -> 0 | AI23: =COUNTIFS($AB:$AB,$AD23,K:K,$AD$3) -> 1 | AJ23: =COUNTIFS($AB:$AB,$AD23,L:L,$AD$3) -> 0 | AK23: =COUNTIFS($AB:$AB,$AD23,M:M,$AD$3) -> 0 | AL23: =COUNTIFS($AB:$AB,$AD23,N:N,$AD$3) -> 0 | AM23: =COUNTIFS($AB:$AB,$AD23,O:O,$AD$3) -> 1 | AN23: =COUNTIFS($AB:$AB,$AD23,P:P,$AD$3) -> 0 | AO23: =COUNTIFS($AB:$AB,$AD23,Q:Q,$AD$3) -> 0 | AP23: =COUNTIFS($AB:$AB,$AD23,R:R,$AD$3) -> 0 | AQ23: =COUNTIFS($AB:$AB,$AD23,S:S,$AD$3) -> 1 | AR23: =COUNTIFS($AB:$AB,$AD23,T:T,$AD$3) -> 0 | AS23: =COUNTIFS($AB:$AB,$AD23,U:U,$AD$3) -> 0 | AT23: =COUNTIFS($AB:$AB,$AD23,V:V,$AD$3) -> 0 | AU23: =COUNTIFS($AB:$AB,$AD23,W:W,$AD$3) -> 1 | AV23: =COUNTIFS($AB:$AB,$AD23,X:X,$AD$3) -> 0 | AW23: =COUNTIFS($AB:$AB,$AD23,Y:Y,$AD$3) -> 0 | AX23: =COUNTIFS($AB:$AB,$AD23,Z:Z,$AD$3) -> 0 | AZ23: 고·저수조
B24: ET-10 | C24: =VLOOKUP(B24,'9.성능점검대상기계설비현황-24.01.24'!C25:L148,2,FALSE) -> 팽창탱크 | E24: =VLOOKUP(B24,'9.성능점검대상기계설비현황-24.01.24'!C25:L148,4,FALSE) -> 밀폐형 | F24: 1 | G24: ○ | K24: ○ | O24: ○ | S24: ○ | W24: ○ | AA24: =VLOOKUP(B24,'9.성능점검대상기계설비현황-24.01.24'!$C:$L,8,0) -> B7F 기계실 | AB24: 팽창탱크 (냉·난방, 급탕 팽창탱크 포함) | AC24: =IF(VLOOKUP(AD24,'8.성능점검대상기계설비의수량-24.01.24'!$F:$Y,20,0)=SUM(AE24:AX24)/5,"OK","NOT OK") -> OK | AD24: =AZ25 -> 오·배수 통기 및 우수배수설비 | AE24: =COUNTIFS($AB:$AB,$AD24,G:G,$AD$3) -> 1 | AF24: =COUNTIFS($AB:$AB,$AD24,H:H,$AD$3) -> 0 | AG24: =COUNTIFS($AB:$AB,$AD24,I:I,$AD$3) -> 0 | AH24: =COUNTIFS($AB:$AB,$AD24,J:J,$AD$3) -> 0 | AI24: =COUNTIFS($AB:$AB,$AD24,K:K,$AD$3) -> 1 | AJ24: =COUNTIFS($AB:$AB,$AD24,L:L,$AD$3) -> 0 | AK24: =COUNTIFS($AB:$AB,$AD24,M:M,$AD$3) -> 0 | AL24: =COUNTIFS($AB:$AB,$AD24,N:N,$AD$3) -> 0 | AM24: =COUNTIFS($AB:$AB,$AD24,O:O,$AD$3) -> 1 | AN24: =COUNTIFS($AB:$AB,$AD24,P:P,$AD$3) -> 0 | AO24: =COUNTIFS($AB:$AB,$AD24,Q:Q,$AD$3) -> 0 | AP24: =COUNTIFS($AB:$AB,$AD24,R:R,$AD$3) -> 0 | AQ24: =COUNTIFS($AB:$AB,$AD24,S:S,$AD$3) -> 1 | AR24: =COUNTIFS($AB:$AB,$AD24,T:T,$AD$3) -> 0 | AS24: =COUNTIFS($AB:$AB,$AD24,U:U,$AD$3) -> 0 | AT24: =COUNTIFS($AB:$AB,$AD24,V:V,$AD$3) -> 0 | AU24: =COUNTIFS($AB:$AB,$AD24,W:W,$AD$3) -> 1 | AV24: =COUNTIFS($AB:$AB,$AD24,X:X,$AD$3) -> 0 | AW24: =COUNTIFS($AB:$AB,$AD24,Y:Y,$AD$3) -> 0 | AX24: =COUNTIFS($AB:$AB,$AD24,Z:Z,$AD$3) -> 0 | AZ24: 오·배수용 펌프(모터동력 0.75 kW 이하 제외)
B25: ET-11 | C25: =VLOOKUP(B25,'9.성능점검대상기계설비현황-24.01.24'!C26:L149,2,FALSE) -> 팽창탱크 | E25: =VLOOKUP(B25,'9.성능점검대상기계설비현황-24.01.24'!C26:L149,4,FALSE) -> 밀폐형 | F25: 1 | G25: ○ | K25: ○ | O25: ○ | S25: ○ | W25: ○ | AA25: =VLOOKUP(B25,'9.성능점검대상기계설비현황-24.01.24'!$C:$L,8,0) -> B7F 기계실 | AB25: 팽창탱크 (냉·난방, 급탕 팽창탱크 포함) | AC25: =IF(VLOOKUP(AD25,'8.성능점검대상기계설비의수량-24.01.24'!$F:$Y,20,0)=SUM(AE25:AX25)/5,"OK","NOT OK") -> OK | AD25: =AZ26 -> 오수정화설비 | AE25: =COUNTIFS($AB:$AB,$AD25,G:G,$AD$3) -> 1 | AF25: =COUNTIFS($AB:$AB,$AD25,H:H,$AD$3) -> 0 | AG25: =COUNTIFS($AB:$AB,$AD25,I:I,$AD$3) -> 0 | AH25: =COUNTIFS($AB:$AB,$AD25,J:J,$AD$3) -> 0 | AI25: =COUNTIFS($AB:$AB,$AD25,K:K,$AD$3) -> 1 | AJ25: =COUNTIFS($AB:$AB,$AD25,L:L,$AD$3) -> 0 | AK25: =COUNTIFS($AB:$AB,$AD25,M:M,$AD$3) -> 0 | AL25: =COUNTIFS($AB:$AB,$AD25,N:N,$AD$3) -> 0 | AM25: =COUNTIFS($AB:$AB,$AD25,O:O,$AD$3) -> 1 | AN25: =COUNTIFS($AB:$AB,$AD25,P:P,$AD$3) -> 0 | AO25: =COUNTIFS($AB:$AB,$AD25,Q:Q,$AD$3) -> 0 | AP25: =COUNTIFS($AB:$AB,$AD25,R:R,$AD$3) -> 0 | AQ25: =COUNTIFS($AB:$AB,$AD25,S:S,$AD$3) -> 1 | AR25: =COUNTIFS($AB:$AB,$AD25,T:T,$AD$3) -> 0 | AS25: =COUNTIFS($AB:$AB,$AD25,U:U,$AD$3) -> 0 | AT25: =COUNTIFS($AB:$AB,$AD25,V:V,$AD$3) -> 0 | AU25: =COUNTIFS($AB:$AB,$AD25,W:W,$AD$3) -> 1 | AV25: =COUNTIFS($AB:$AB,$AD25,X:X,$AD$3) -> 0 | AW25: =COUNTIFS($AB:$AB,$AD25,Y:Y,$AD$3) -> 0 | AX25: =COUNTIFS($AB:$AB,$AD25,Z:Z,$AD$3) -> 0 | AZ25: 오·배수 통기 및 우수배수설비
B26: P-1-1 | C26: =VLOOKUP(B26,'9.성능점검대상기계설비현황-24.01.24'!C27:L150,2,FALSE) -> 난방순환펌프 | E26: =VLOOKUP(B26,'9.성능점검대상기계설비현황-24.01.24'!C27:L150,4,FALSE) -> IN-LINE | F26: 1 | K26: ○ | W26: ○ | AA26: =VLOOKUP(B26,'9.성능점검대상기계설비현황-24.01.24'!$C:$L,8,0) -> B7F 기계실 | AB26: 펌프(냉·난방펌프) (예비펌프, 모터동력 0.75 kW 이하 제외) | AC26: =IF(VLOOKUP(AD26,'8.성능점검대상기계설비의수량-24.01.24'!$F:$Y,20,0)=SUM(AE26:AX26)/5,"OK","NOT OK") -> OK | AD26: =AZ27 -> 물 재이용설비 | AE26: =COUNTIFS($AB:$AB,$AD26,G:G,$AD$3) -> 1 | AF26: =COUNTIFS($AB:$AB,$AD26,H:H,$AD$3) -> 0 | AG26: =COUNTIFS($AB:$AB,$AD26,I:I,$AD$3) -> 0 | AH26: =COUNTIFS($AB:$AB,$AD26,J:J,$AD$3) -> 0 | AI26: =COUNTIFS($AB:$AB,$AD26,K:K,$AD$3) -> 1 | AJ26: =COUNTIFS($AB:$AB,$AD26,L:L,$AD$3) -> 0 | AK26: =COUNTIFS($AB:$AB,$AD26,M:M,$AD$3) -> 0 | AL26: =COUNTIFS($AB:$AB,$AD26,N:N,$AD$3) -> 0 | AM26: =COUNTIFS($AB:$AB,$AD26,O:O,$AD$3) -> 1 | AN26: =COUNTIFS($AB:$AB,$AD26,P:P,$AD$3) -> 0 | AO26: =COUNTIFS($AB:$AB,$AD26,Q:Q,$AD$3) -> 0 | AP26: =COUNTIFS($AB:$AB,$AD26,R:R,$AD$3) -> 0 | AQ26: =COUNTIFS($AB:$AB,$AD26,S:S,$AD$3) -> 1 | AR26: =COUNTIFS($AB:$AB,$AD26,T:T,$AD$3) -> 0 | AS26: =COUNTIFS($AB:$AB,$AD26,U:U,$AD$3) -> 0 | AT26: =COUNTIFS($AB:$AB,$AD26,V:V,$AD$3) -> 0 | AU26: =COUNTIFS($AB:$AB,$AD26,W:W,$AD$3) -> 1 | AV26: =COUNTIFS($AB:$AB,$AD26,X:X,$AD$3) -> 0 | AW26: =COUNTIFS($AB:$AB,$AD26,Y:Y,$AD$3) -> 0 | AX26: =COUNTIFS($AB:$AB,$AD26,Z:Z,$AD$3) -> 0 | AZ26: 오수정화설비
B27: P-2-1 | C27: =VLOOKUP(B27,'9.성능점검대상기계설비현황-24.01.24'!C28:L151,2,FALSE) -> 난방순환펌프 | E27: =VLOOKUP(B27,'9.성능점검대상기계설비현황-24.01.24'!C28:L151,4,FALSE) -> IN-LINE | F27: 1 | K27: ○ | W27: ○ | AA27: =VLOOKUP(B27,'9.성능점검대상기계설비현황-24.01.24'!$C:$L,8,0) -> B7F 기계실 | AB27: 펌프(냉·난방펌프) (예비펌프, 모터동력 0.75 kW 이하 제외) | AC27: =IF(VLOOKUP(AD27,'8.성능점검대상기계설비의수량-24.01.24'!$F:$Y,20,0)=SUM(AE27:AX27)/5,"OK","NOT OK") -> OK | AD27: =AZ28 -> 배관설비 | AE27: =COUNTIFS($AB:$AB,$AD27,G:G,$AD$3) -> 1 | AF27: =COUNTIFS($AB:$AB,$AD27,H:H,$AD$3) -> 0 | AG27: =COUNTIFS($AB:$AB,$AD27,I:I,$AD$3) -> 0 | AH27: =COUNTIFS($AB:$AB,$AD27,J:J,$AD$3) -> 0 | AI27: =COUNTIFS($AB:$AB,$AD27,K:K,$AD$3) -> 1 | AJ27: =COUNTIFS($AB:$AB,$AD27,L:L,$AD$3) -> 0 | AK27: =COUNTIFS($AB:$AB,$AD27,M:M,$AD$3) -> 0 | AL27: =COUNTIFS($AB:$AB,$AD27,N:N,$AD$3) -> 0 | AM27: =COUNTIFS($AB:$AB,$AD27,O:O,$AD$3) -> 1 | AN27: =COUNTIFS($AB:$AB,$AD27,P:P,$AD$3) -> 0 | AO27: =COUNTIFS($AB:$AB,$AD27,Q:Q,$AD$3) -> 0 | AP27: =COUNTIFS($AB:$AB,$AD27,R:R,$AD$3) -> 0 | AQ27: =COUNTIFS($AB:$AB,$AD27,S:S,$AD$3) -> 1 | AR27: =COUNTIFS($AB:$AB,$AD27,T:T,$AD$3) -> 0 | AS27: =COUNTIFS($AB:$AB,$AD27,U:U,$AD$3) -> 0 | AT27: =COUNTIFS($AB:$AB,$AD27,V:V,$AD$3) -> 0 | AU27: =COUNTIFS($AB:$AB,$AD27,W:W,$AD$3) -> 1 | AV27: =COUNTIFS($AB:$AB,$AD27,X:X,$AD$3) -> 0 | AW27: =COUNTIFS($AB:$AB,$AD27,Y:Y,$AD$3) -> 0 | AX27: =COUNTIFS($AB:$AB,$AD27,Z:Z,$AD$3) -> 0 | AZ27: 물 재이용설비
A28: 열원 및 냉·난방 설비 | B28: P-3-1 | C28: =VLOOKUP(B28,'9.성능점검대상기계설비현황-24.01.24'!C29:L152,2,FALSE) -> 난방순환펌프 | E28: =VLOOKUP(B28,'9.성능점검대상기계설비현황-24.01.24'!C29:L152,4,FALSE) -> IN-LINE | F28: 1 | K28: ○ | W28: ○ | AA28: =VLOOKUP(B28,'9.성능점검대상기계설비현황-24.01.24'!$C:$L,8,0) -> B7F 기계실 | AB28: 펌프(냉·난방펌프) (예비펌프, 모터동력 0.75 kW 이하 제외) | AC28: =IF(VLOOKUP(AD28,'8.성능점검대상기계설비의수량-24.01.24'!$F:$Y,20,0)=SUM(AE28:AX28)/5,"OK","NOT OK") -> OK | AD28: =AZ29 -> 덕트설비 | AE28: =COUNTIFS($AB:$AB,$AD28,G:G,$AD$3) -> 1 | AF28: =COUNTIFS($AB:$AB,$AD28,H:H,$AD$3) -> 0 | AG28: =COUNTIFS($AB:$AB,$AD28,I:I,$AD$3) -> 0 | AH28: =COUNTIFS($AB:$AB,$AD28,J:J,$AD$3) -> 0 | AI28: =COUNTIFS($AB:$AB,$AD28,K:K,$AD$3) -> 1 | AJ28: =COUNTIFS($AB:$AB,$AD28,L:L,$AD$3) -> 0 | AK28: =COUNTIFS($AB:$AB,$AD28,M:M,$AD$3) -> 0 | AL28: =COUNTIFS($AB:$AB,$AD28,N:N,$AD$3) -> 0 | AM28: =COUNTIFS($AB:$AB,$AD28,O:O,$AD$3) -> 1 | AN28: =COUNTIFS($AB:$AB,$AD28,P:P,$AD$3) -> 0 | AO28: =COUNTIFS($AB:$AB,$AD28,Q:Q,$AD$3) -> 0 | AP28: =COUNTIFS($AB:$AB,$AD28,R:R,$AD$3) -> 0 | AQ28: =COUNTIFS($AB:$AB,$AD28,S:S,$AD$3) -> 1 | AR28: =COUNTIFS($AB:$AB,$AD28,T:T,$AD$3) -> 0 | AS28: =COUNTIFS($AB:$AB,$AD28,U:U,$AD$3) -> 0 | AT28: =COUNTIFS($AB:$AB,$AD28,V:V,$AD$3) -> 0 | AU28: =COUNTIFS($AB:$AB,$AD28,W:W,$AD$3) -> 1 | AV28: =COUNTIFS($AB:$AB,$AD28,X:X,$AD$3) -> 0 | AW28: =COUNTIFS($AB:$AB,$AD28,Y:Y,$AD$3) -> 0 | AX28: =COUNTIFS($AB:$AB,$AD28,Z:Z,$AD$3) -> 0 | AZ28: 배관설비
