Workbook
Name 산출자: #REF!
Name 산출자: #REF!

Sheet 정보입력-Rev.2
B2: 정보입력
B3: 현장명칭 | C3: ○○○○○○ 아파트
B4: 현장주소 | C4: 인천 서구 율도로 81번길 4
B5: 점검기간 (현장 작업기간) | C5: 2026 | D5: 년 | E5: 9 | F5: 월 | G5: 2 | H5: 일 | I5: ~ | J5: 2026 | K5: 년 | L5: 9 | M5: 월 | N5: 2 | O5: 일
B6: 점검일수 | C6: =DATE(J5,L5,N5)-DATE(C5,E5,G5)+1 -> 1
B7: 연면적(m2) | C7: 14200 | P7: <= 오피스텔,빌딩,공장등 공동주택제외한 건물인 경우 입력
B8: 세대수(세대) | P8: <= 공동주택(아파트)만 입력
B9: 점 검 자 | C9: 홍길동
B10: 제출일자 | C10: 46295
B11: 성능점검기준일 | C11: 45034 | P11: <= 오른쪽 기준일 적용 시 참고해서 적용
B12: ※ 아래 유지관리자 테이블은 결과보고서의 유지관리자 입력의 번거러움, 오타 등을 방지하기 위한 것으로 유지관리자 추가/수정 또는 삭제 시 아래 명단에서 삭제/수정/추가하시면 되겠습니다.
B16: 유지관리자 (삭제 금지) | P16: ※ 26.06.11 기준 현황이며, 변동사항 발생 시 때마다 필히 반영할 것
B17: 성명 | C17: 등급 | H17: 수첩발급번호 | O17: 법인 | Q17: 특이사항
B18: 곽동현 | C18: 기계설비유지관리특급 | H18: 202111-V00007 | O18: 기계설비-본사
B19: 김성한 | C19: 기계설비유지관리특급 | H19: 202103-C00275 | O19: 기계설비-본사 | Q19: 비상주
B20: 권양국 | C20: 기계설비유지관리특급 | H20: 202208-U00769 | O20: 기계설비-본사 | Q20: 비상주
B21: 양준우 | C21: 기계설비유지관리특급 | H21: 202402-E01032 | O21: 기계설비-본사
B22: 박천택 | C22: 기계설비유지관리중급 | H22: 202212-Z00556 | O22: 기계설비-본사 | Q22: 비상주
B23: 이한민 | C23: 기계설비유지관리초급 | H23: 202303-T02766 | O23: 기계설비-본사
B24: 이민우 | C24: 기계설비유지관리초급 | H24: 202303-F02979 | O24: 기계설비-본사
B27: 황선구 | C27: 기계설비유지관리특급 | H27: 202104-N01755 | O27: 기계설비-인천
B28: 최상수 | C28: 기계설비유지관리특급 | H28: 202305-J00353 | O28: 기계설비-인천 | Q28: 비상주
B29: 이승건 | C29: 기계설비유지관리고급 | H29: 202207-A00382 | O29: 기계설비-인천
B30: 신상훈 | C30: 기계설비유지관리중급 | H30: 202301-X00759 | O30: 기계설비-인천
B32: 정상석 | C32: 기계설비유지관리특급 | H32: 202212-J00191 | O32: 기계설비-광주
B33: 양병일 | C33: 기계설비유지관리특급 | H33: 202211-D00091 | O33: 기계설비-광주 | Q33: 비상주
B34: 장동근 | C34: 기계설비유지관리고급 | H34: 202104-M04872 | O34: 기계설비-광주 | Q34: 비상주
B35: 김중현 | C35: 기계설비유지관리고급 | H35: 202207-O00938 | O35: 기계설비-광주

Sheet II. 표지
J14: CHAPTER II. 기계설비 성능점검 결과 보고서

Sheet II. 결과보고서
A2: ■ 기계설비 유지관리기준[별지 제4호 서식]
D4: II. | H4: 기계설비 성능점검 결과 보고서
A5: (앞쪽)
A6: 점검현장 개 요 | D6: 명칭(상호) | G6: ='정보입력-Rev.2'!$C$3 -> ○○○○○○ 아파트 | N6: 선임자격 | R6: 특급 | T6: [ ] | V6: 고급 | X6: [ ]
R7: 중급 | T7: [ ] | V7: 초급 | X7: [√ ]
D8: 주 소 | G8: ='정보입력-Rev.2'!$C$4 -> 인천 서구 율도로 81번길 4
D9: 용 도 | G9: 공동주택 | N9: 연면적 [세대수] | R9: =IF('정보입력-Rev.2'!$C7="","",'정보입력-Rev.2'!C7) -> 14200 | X9: m2
R10: =IF('정보입력-Rev.2'!C8="","",'정보입력-Rev.2'!C8) | X10: (세대)
D11: 건물구조 | G11: 지상 35 층, 지하 7 층 | N11: 성능점검 기준일 | R11: ='정보입력-Rev.2'!$C$11 -> 45034
A14: 관리주체 | D14: 성 명 (대표자) | G14: ○○○○○○ 아파트입주자 대표회의(홍길동) | N14: 전화번호 | R14: 032-328-8182
D16: 주 소 | G16: 경기도 부천시 상동로 117번길 37, 진성프라자 3층
A18: 점검대상 기계설비 종류 | G18: 냉동기, 냉각탑, 축열조, 보일러, 열교환기, 팽창탱크, 펌프, 신재생에너지(지열), 패키지에어컨, 항온항습기, 공기조화기, 팬코일유닛, 환기, 필터, 위생기구, 급수·급탕, 고·저수조, 오·배수 통기 및 우수 배수, 오수정화, 물재이용, 배관, 덕트, 보온, 자동제어, 방음·방진·내진
A21: 점검기간 | G21: ='정보입력-Rev.2'!C5&"년 "&'정보입력-Rev.2'!E5&" 월 "&'정보입력-Rev.2'!G5&" 일 ~ "&'정보입력-Rev.2'!J5&" 년 "&'정보입력-Rev.2'!L5&" 월 "&'정보입력-Rev.2'!N5&" 일( 총 점검일수 : "&'정보입력-Rev.2'!C6&" 일 ) " -> 2026년 9 월 2 일 ~ 2026 년 9 월 2 일( 총 점검일수 : 1 일 )
A23: 점검방법 | G23: [ ] | I23: 자체점검 | P23: [V] | R23: 성능점검업체 대행 | AA23: 23.11.29 개정 고시 반영
A24: 점검 참여 | G24: 상호( 명칭 ) | N24: 대표자 | S24: 성능점검업(사업자)등록번호 | AA24: 23.11.29 개정 고시 반영 | AI24: 법인 선택 아래 누르시오 | AJ24: 사업자등록번호
A25: 성능점검업체 | G25: 한국기계설비관리㈜ | N25: 이 승 원 | S25: =AJ25 -> 825-88-00620 | AI25: 본사 | AJ25: =VLOOKUP(AI25,AI27:AJ30,2,0) -> 825-88-00620
A27: 점검 참여 기계설비유지관리자 | AI27: 본사 | AJ27: 825-88-00620
A28: 성명 | G28: 등급 | N28: 수첩발급번호 | S28: 점검기간 | AI28: 인천 | AJ28: 514-86-02914
A29: 곽동현 | G29: =IF(ISBLANK(A29),"",VLOOKUP(A29,'정보입력-Rev.2'!$B$18:$N$51,2,0)) -> 기계설비유지관리특급 | N29: =IF(ISBLANK(A29),"",VLOOKUP(A29,'정보입력-Rev.2'!B:N,7,0)) -> 202111-V00007 | S29: =IF(A29="","",'정보입력-Rev.2'!$C$5&"."&'정보입력-Rev.2'!$E$5&"."&'정보입력-Rev.2'!$G$5&" ~ "&'정보입력-Rev.2'!$J$5&"."&'정보입력-Rev.2'!$L$5&"."&'정보입력-Rev.2'!$N$5) -> 2026.9.2 ~ 2026.9.2 | AI29: 광주 | AJ29: 398-81-03107
A30: 김성한 | G30: =IF(ISBLANK(A30),"",VLOOKUP(A30,'정보입력-Rev.2'!$B$18:$N$51,2,0)) -> 기계설비유지관리특급 | N30: =IF(ISBLANK(A30),"",VLOOKUP(A30,'정보입력-Rev.2'!B:N,7,0)) -> 202103-C00275 | S30: =IF(A30="","",'정보입력-Rev.2'!$C$5&"."&'정보입력-Rev.2'!$E$5&"."&'정보입력-Rev.2'!$G$5&" ~ "&'정보입력-Rev.2'!$J$5&"."&'정보입력-Rev.2'!$L$5&"."&'정보입력-Rev.2'!$N$5) -> 2026.9.2 ~ 2026.9.2
G31: =IF(ISBLANK(A31),"",VLOOKUP(A31,'정보입력-Rev.2'!$B$18:$N$51,2,0)) | N31: =IF(ISBLANK(A31),"",VLOOKUP(A31,'정보입력-Rev.2'!B:N,7,0)) | S31: =IF(A31="","",'정보입력-Rev.2'!$C$5&"."&'정보입력-Rev.2'!$E$5&"."&'정보입력-Rev.2'!$G$5&" ~ "&'정보입력-Rev.2'!$J$5&"."&'정보입력-Rev.2'!$L$5&"."&'정보입력-Rev.2'!$N$5)
G32: =IF(ISBLANK(A32),"",VLOOKUP(A32,'정보입력-Rev.2'!$B$18:$N$51,2,0)) | N32: =IF(ISBLANK(A32),"",VLOOKUP(A32,'정보입력-Rev.2'!B:N,7,0)) | S32: =IF(A32="","",'정보입력-Rev.2'!$C$5&"."&'정보입력-Rev.2'!$E$5&"."&'정보입력-Rev.2'!$G$5&" ~ "&'정보입력-Rev.2'!$J$5&"."&'정보입력-Rev.2'!$L$5&"."&'정보입력-Rev.2'!$N$5)
A33: 「기계설비법」제17조제3항에 따라 기계설비 성능점검 결과보고서를 제출합니다.
A34: ='정보입력-Rev.2'!$C$10 -> 46295
A35: 관리주체 (서명 또는 인)
A36: 특별자치시장 · 특별자치도지사 · 시장 · 군수 · 구청장 귀하
A37: 첨부서류 | D37: 1. 기계설비 성능점검 대상 점검표(별지 제3호서식)
D38: 2. [별표 3]에 따른 기계설비 시스템 검토, 성능개선 계획 수립 및 에너지사용량 검토 결과

Sheet 점검결과내역서
A1: (뒷쪽)
A2: 점검결과 내역서 | AB2: 점검결과 내역서 표준안 ※ 준공 후 5년 미만 2. 준공 후 설비 가동 기간이 0년 정도로 가동기간이 짧으며 최신의 기계 설비로, 노후 진행이 없고 기계설비 전체가 안정적이며, 외관 등의 상태가 양호하여 기계 설비 성능이 적합함. ※ 준공 후 5~15년 2. 준공 후 설비가동 기간이 00년 정도로 기계설비 내구년한에 가까워지고 있으며, 노후가 서서히 진행되고 있으나 체계적인 유지관리로 기계설비 성능은 적합함. 3. 본 건물의 용도는 주거시설, .......... 로써 현재 기계설비 성능점검 항목으로는 이 상이 없으나 전반적으로 노후가 많이 진행되고 있어 추후 기계설비성능 개선계획 을 수립하여 에너지 효율화 및 성능 개선이 필요합니다. ※ 준공 후 15년 이상 2. 준공 후 설비 가동 기간이 00년으로 기계설비 내구 년한에 도래하였으나 예방적 유지관리 및 사후유지관리를 통해 설비수명을 연장하고 있어 기계설비 성능은 적 합하나 기계설비가 전반적으로 노후가 많이 진행되었습니다. 3. 본 건물의 용도는 주거시설, .......... 로써 현재 기계설비 성능점검 항목으로는 이 상이 없으나 전반적으로 노후가 많이 진행되고 있어 추후 기계설비성능 개선계획 을 수립하여 에너지 효율화 및 성능 개선이 필요합니다. ※ 유지관리점검표를 기록 보관하고 있지 않을 경우 4. 기계설비 유지관리 기준 양식에 의한 유지관리 및 점검표를 기록 보관하지 않 으므로 즉시 유지관리 점검표 작성 및 보관을 해야 함.
A3: 현장 명칭 | F3: ='정보입력-Rev.2'!$C$3 -> ○○○○○○ 아파트 | M3: 주소 | P3: ='정보입력-Rev.2'!$C$4 -> 인천 서구 율도로 81번길 4
A4: 점검결과 (특기사항) | F4: 1. 당 건물은 2007년 08월 28일 준공 후 15년 경과하였습니다. 2. 준공 후 설비 가동 기간이 15년으로 기계설비 내구 년한에 도래하였으나 예방적 유지관리 및 사후유지관리를 통해 설비수명을 연장하고 있어 기계설비 성능은 적 합하나 기계설비가 전반적으로 노후가 많이 진행되었습니다. 3. 본 건물의 용도는 주거시설, 상업시설, 업무시설, 교육시설 ,공장 등으로 기계설 비 성능점검 항목으로는 이상이 없으므로 추후 기계설비 유지관리 계획을 수립 하여 성능, 안전 및 에너지 효율화에 힘써야 할 것입니다. 4. 기계설비 유지관리 기준 양식에 의한 유지관리 및 점검표를 기록 보관하지 않으므 로 즉시 유지관리 점검표 작성 및 보관을 해야 함.
A6: 점검자(대표자) | F6: 상호(명칭) | I6: 한국기계설비관리㈜ | O6: 성명 | R6: 이승원 | U6: (서명 또는 인)
A8: 구분 | I8: 점검결과 | M8: 조치필요사항
A9: 열원 및 냉난방설비 | I9: × | M9: 열교환기 압력계 고장 및 규격 외 볼트사용으로 케이싱 조립 불가, 펌프 전류 차단 장치 문제 有
A10: 공기조화설비 | I10: /
A11: 환기설비 | I11: ○
A12: 위생기구설비 | I12: × | M12: 양변기 막힘 및 소변기 센서 불량
A13: 급수·급탕설비 | I13: ○
A14: 오·배수통기 및 우수배수설비 | I14: × | M14: 102동 수중펌프 #5 고장
A15: 오수정화 및 물재이용설비 | I15: ○
A16: 배관설비 | I16: ○
A17: 덕트설비 | I17: ○
A18: 보온설비 | I18: × | M18: 동파방지 열선 수동으로 ON/OFF 시켜서 사용 중
A19: 자동제어설비 | I19: ○
A20: 방음·방진·내진설비 | I20: ○
A21: 작 성 방 법
A22: 1. 점검결과에는 [ 적합 ○, 조치필요 ×, 해당없음 / ]을 표기한다.
A23: 2. 조치필요사항에는 점검대상 기계설비의 성능점검 결과에 따른 조치필요사항을 작성한다.
A24: 3. 고장 등으로 장기간 사용되지 않는 기계설비도 포함하되, 점검결과에는 [미사용]을 표기한다.

Sheet III. 표지
J14: CHAPTER III. 기계설비 성능점검 대상 점검표

Sheet III. 기계설비성능점검표
A3: ■ 기계설비 유지관리기준 [별지 제3호서식]
C7: III. | F7: 기계설비 성능점검 대상 점검표
A9: 상호(명칭) | C9: ='정보입력-Rev.2'!C$3 -> ○○○○○○ 아파트 | H9: 현장주소 | J9: ='정보입력-Rev.2'!C$4 -> 인천 서구 율도로 81번길 4
A11: 구분 | B11: 대상설비 | E11: 대상 | G11: 점검결과 | I11: 구 분 | K11: 대상설비 | L11: 대상 | M11: 점검결과
A12: 열원 및 냉·난방설비 | B12: 냉동기 | E12: [ ] | I12: 환기설비 | K12: 환기설비 | L12: [√ ] | M12: ○
B13: 냉각탑 | E13: [ ] | K13: 필터 | L13: [ ] | Q13: 곽동현 | S13: 황선구 | U13: 강길모 | W13: 정상석
B14: 축열조 | E14: [ ] | I14: 위생기구설비 | K14: 위생기구설비 | L14: [√ ] | M14: ×
B15: 보일러 | E15: [ ] | I15: 급수‧급탕설비 | K15: 급수‧급탕설비 | L15: [√ ] | M15: ○
B16: 열교환기 | E16: [√ ] | G16: × | K16: 고‧저수조 | L16: [√ ] | M16: ○
B17: 팽창탱크 | E17: [ ] | G17: ○ | I17: 오‧배수통기 및 우수배수설비 | K17: 오‧배수 통기 및 우수배수설비 | L17: [√ ] | M17: ×
B18: 펌프(냉 ‧ 난방) | E18: [√ ] | G18: × | I18: 오수정화 및 물 재이용설비 | K18: 오수정화설비 | L18: [ ]
B19: 신재생 | C19: 지열 | E19: [ ] | K19: 물 재이용설비 | L19: [√ ] | M19: ○
C20: 태양열 | E20: [ ] | I20: 배관설비 | K20: 배관설비 | L20: [√ ] | M20: ○
C21: 연료전지 | E21: [ ] | I21: 덕트설비 | K21: 덕트설비 | L21: [√ ] | M21: ○
B22: 패키지 에어컨 | E22: [ ] | G22: ○ | I22: 보온설비 | K22: 보온설비 | L22: [√ ] | M22: ×
B23: 항온항습기 | E23: [ ] | I23: 자동제어설비 | K23: 자동제어설비 | L23: [√ ]
A24: 공기조화설비 | B24: 공기조화기 | E24: [ ] | I24: 방음‧방진‧내진설비 | K24: 방음‧방진‧내진설비 | L24: [√ ]
B25: 팬코일 유닛 | E25: [ ]
A27: ="점검기간 : "&'정보입력-Rev.2'!C5&" 년 "&'정보입력-Rev.2'!E5&" 월 "&'정보입력-Rev.2'!G5&" 일 부터 "&'정보입력-Rev.2'!J5&" 년 "&'정보입력-Rev.2'!L5&" 월 "&'정보입력-Rev.2'!N5&" 일 까지" -> 점검기간 : 2026 년 9 월 2 일 부터 2026 년 9 월 2 일 까지
A29: 점검자 : 특급기계설비유지관리자 곽 동 현 (서명) | N29: 점검자는 성능점검자 중 특급 기계설비유지관리자가 최종확인하고 점검자에 서명함. 매뉴얼 36 페이지 참고
A32: 작 성 방 법
A33: 1. 해당 건축물등의 특성과 현장 여건에 적합하도록 점검대상 기계설비 및 성능점검표를 추가·변경할 수 있다.
A34: 2. [ ]에는 점검대상 기계설비에 해당하는 경우 √ 표시를 한다.
A35: 3. 점검결과에는 [ 적합 ○, 조치필요 ×, 해당없음 / ]을 표기한다.
A36: 4. 고장 등으로 장기간 사용되지 않는 기계설비도 포함하되, 점검결과에는 [미사용]을 표기한다.

Sheet 냉동기
A2: 냉동기 성능점검표 | R2: 설비번호
R3: 용 도
A4: 점검자 | C4: ='정보입력-Rev.2'!$C$9 -> 홍길동 | I4: 점검일자 | L4: ='정보입력-Rev.2'!$C$5&"."&'정보입력-Rev.2'!$E$5&"."&'정보입력-Rev.2'!$G$5&" ~ "&'정보입력-Rev.2'!$J$5&"."&'정보입력-Rev.2'!$L$5&"."&'정보입력-Rev.2'!$N$5 -> 2026.9.2 ~ 2026.9.2 | R4: 설치위치(No.)
A6: 구 분 | C6: 점검내용 | V6: 점검결과
A7: 점검 항목 | C7: ① 유지관리 점검표 확인 | V7: ○
C8: ② 기내압력 점검 | V8: ○
C9: ③ 노후 및 부식 상태 | V9: ○
C10: ④ 허용압력[압축기(재생기), 응축기, 증발기] 상태 | V10: ○
C11: ⑤ 펌프(용액, 냉매, 진공) 상태 | V11: ○
C12: ⑥ 연소장치 상태 | V12: ○
C13: ⑦ 경보 상태 | V13: ○
C14: ⑧ 안전장치(인터록) 상태 | V14: ○
C15: ⑨ 과부하 차단 상태 | V15: ○
C16: ⑩ 안전밸브 상태 | V16: ○
C17: ⑪ 저ㆍ고수위 경보 상태 | V17: ○
C18: ⑫ 배기가스온도 | V18: ○
C19: ⑬ 냉동기에 연결된 헤더 상태 | V19: ○
... C21: ⑮ COP 상태 | V21: ○
A22: 조치 사항 | C22: < 미흡사항 >
C25: < 조치필요사항 >
A28: 현장 사진
A38: 비 고
A41: 작 성 방 법
A42: 1. 유지관리지침서 및 기계설비 유지관리 및 성능점검 대상 현황표와의 적합여부를 참고하여 점검결과를 작성한다.
A43: 2. 점검결과에는 [적합 ○, 조치필요 ×, 해당없음 /]을 표기한다.
A44: 3. 현황사진에는 영 별표 7 제3호의 장비를 사용한 측정사진 및 측정데이터를 포함하여 첨부한다.
A45: 4. 전체 수량의 50% 이상 범위 내에서 점검을 실시한다.
A46: 5. 압축식 냉동기, 흡수식 냉동기, 냉온수기, 공랭식 냉동기 등을 포함하여 작성한다.
A49: ① 유지관리 점검표 확인
Z50: [부적합사항 및 조치필요사항 예시]
A51: 구 분 | C51: 점검내용
A52: 점검 기준 | C52: - 해당 기계설비의 유지관리 점검표가 있는가 | Z52: 구비서류미비(준공도서,운용메뉴얼등) | AD52: 미비서류 보완
C53: - 기계설비 유지관리기준 별지 제2호서식에 따라 적정하게 작성되었는가
C54: - 반기별 1회 이상 작성되었는가
A56: 현황 사진 | I56: 적합 | Q56: 미흡사항
A57: 사진 | I57: 사진 | Q57: 사진
I65: 사유 : | K65: 기계설비유지관리 기준에 따라 반기별 1회 적정하게 작성되어 적합함 | Q65: 사유 : | Z65: · 기계설비 유지관리기준 별지 제2호서식에 따라 유지관리 점검표를 반기별 1회이상 작성, 보유하고 있으므로 적합함
A69: ② 기내압력 점검(흡수식 냉동기)
A71: 구 분 | C71: 점검내용
A72: 점검 방법 | C72: - 취급설명서의 진공압력값과 냉동기 판넬 또는 마노미터의 압력값 비교 확인 | Z72: 1.흡수식
...

Sheet 냉각탑
A2: 냉각탑 성능점검표 | R2: 설비번호
R3: 용 도
A4: 점검자 | C4: ='정보입력-Rev.2'!$C$9 -> 홍길동 | I4: 점검일자 | L4: ='정보입력-Rev.2'!$C$5&"."&'정보입력-Rev.2'!$E$5&"."&'정보입력-Rev.2'!$G$5&" ~ "&'정보입력-Rev.2'!$J$5&"."&'정보입력-Rev.2'!$L$5&"."&'정보입력-Rev.2'!$N$5 -> 2026.9.2 ~ 2026.9.2 | R4: 설치위치(No.)
A6: 구 분 | C6: 점검내용 | V6: 점검결과
A7: 점검 항목 | C7: ① 유지관리 점검표 확인 | V7: ○
C8: ② 냉각탑 수조 및 볼탭 상태 | V8: ○
C9: ③ 노후 및 부식 상태 | V9: ○
C10: ④ 살수장치 상태 | V10: ○
C11: ⑤ 송풍기 날개 상태 | V11: ○
C12: ⑥ 레지오넬라균(수질검사, 공중위생관리법 관련) | V12: ○
C13: ⑦ 냉각수 유량 상태 | V13: ○
C14: ⑧ 송풍기 회전 상태 | V14: ○
C15: ⑨ 충진물 상태 | V15: ○
C16: ⑩ 부하전류 상태 | V16: ○
A17: 조치 사항 | C17: < 미흡사항 >
C20: < 조치필요사항 >
A23: 현장 사진
A34: 비 고
A37: 작 성 방 법
A38: 1. 유지관리지침서 및 기계설비 유지관리 및 성능점검 대상 현황표와의 적합여부를 참고하여 점검결과를 작성한다.
A39: 2. 점검결과에는 [적합 ○, 조치필요 ×, 해당없음 /]을 표기한다.
A40: 3. 현황사진에는 영 별표 7 제3호의 장비를 사용한 측정사진 및 측정데이터를 포함하여 첨부한다.
A41: 4. 전체 수량의 50% 이상 범위 내에서 점검을 실시한다.
A42: 5. 향류형 냉각탑, 직교류형 냉각탑 등을 포함하여 작성한다.
A45: ① 유지관리 점검표 확인
A47: 구 분 | C47: 점검내용 | Z47: · 구비서류 미비(준공도서, 운용 매뉴얼 등) | AE47: · 미비 서류 보완
A48: 점검 기준 | C48: - 해당 기계설비의 유지관리 점검표가 있는가
C49: - 기계설비 유지관리기준 별지 제2호서식에 따라 작성되었는가
C50: - 반기별 1회 이상 작성되었는가
A52: 현황 사진 | I52: 적합 | Q52: 미흡사항
A53: 유지관리 점검표 사진 | I53: 사진 | Q53: 사진
I61: 사유 : | K61: 기계설비유지관리 기준에 따라 반기별 1회 적정하게 작성되어 적합함 | Q61: 사유 : | Z61: · 기계설비 유지관리기준 별지 제2호서식에 따라 유지관리 점검표를 반기별 1회이상 작성, 보유하고 있으므로 적합함
A65: ② 냉각탑 수조 및 볼탭 상태
A67: 구 분 | C67: 점검내용
A68: 점검 방법 | C68: - 냉각탑 점검구를 개방하여 수조 내부 육안점검
A69: 점검 기준 | C69: 냉각탑 수조 | G69: - 누수 부위는 없는가 | Z69: · 누수, 부식 또는 경화 부위 발생 | AE69: · 수조 보수
G70: - 누수 또는 경화된 부위는 없는가
G71: - 수조 내부는 청결한가(또는 주기적으로 청소하고 있는가) | Z71: · 수조 내 청소 상태 불량 | AE71: · 수조 내부 청소
C72: 냉각탑 볼탭 | G72: - 볼탭 밸브는 정상적으로 개폐되는가
G73: - 보급수 연결 부위에 누수는 없는가
...

Sheet 축열조
A2: 축열조 성능점검표 | R2: 설비번호
R3: 용 도
A4: 점검자 | C4: ='정보입력-Rev.2'!$C$9 -> 홍길동 | I4: 점검일자 | L4: ='정보입력-Rev.2'!$C$5&"."&'정보입력-Rev.2'!$E$5&"."&'정보입력-Rev.2'!$G$5&" ~ "&'정보입력-Rev.2'!$J$5&"."&'정보입력-Rev.2'!$L$5&"."&'정보입력-Rev.2'!$N$5 -> 2026.9.2 ~ 2026.9.2 | R4: 설치위치(No.)
A6: 구 분 | C6: 점검내용 | V6: 점검결과
A7: 점검 항목 | C7: ① 유지관리 점검표 확인 | V7: ○
C8: ② 축열조 벽면의 균열 상태 | V8: ○
C9: ③ 축열·방열 상태의 데이터 점검 | V9: ○
C10: ④ 분배기 판 노즐 상태 | V10: ○
C11: ⑤ 브라인 농도 상태 | V11: ○
C12: ⑥ 서포트 고정 상태 | V12: ○
C13: ⑦ 에너지 사용 분석 | V13: ○
A14: 조치 사항 | C14: < 미흡사항 >
C17: < 조치필요사항 >
A20: 현장 사진
A33: 비 고
A36: 작 성 방 법
A37: 1. 유지관리지침서 및 기계설비 유지관리 및 성능점검 대상 현황표와의 적합여부를 참고하여 점검결과를 작성한다.
A38: 2. 점검결과에는 [적합 ○, 조치필요 ×, 해당없음 /]을 표기한다.
A39: 3. 현황사진에는 영 별표 7 제3호의 장비를 사용한 측정사진 및 측정데이터를 포함하여 첨부한다.
A40: 4. 빙축열시스템, 수축열시스템 등을 포함하여 작성한다.
A43: ① 유지관리 점검표 확인
A45: 구 분 | C45: 점검내용
A46: 점검 기준 | C46: - 해당 기계설비의 유지관리 점검표가 있는가 | Z46: · 구비서류 미비(준공도서, 운용 매뉴얼 등) | AD46: · 미비 서류 보완
C47: - 기계설비 유지관리기준 별지 제2호서식에 따라 작성되었는가
C48: - 반기별 1회 이상 작성되었는가
A50: 현황 사진 | I50: 적합 | Q50: 미흡사항
A51: 유지관리 점검표 사진 | I51: 사진 | Q51: 사진
Z57: · 기계설비 유지관리기준 별지 제2호서식에 따라 유지관리 점검표를 반기별 1회이상 작성, 보유하고 있으므로 적합함
I59: 사유 : | K59: 기계설비유지관리 기준에 따라 반기별 1회 적정하게 작성되어 적합함 | Q59: 사유 :
A63: ② 축열조 벽면의 균열 상태
A65: 구 분 | C65: 점검내용
A66: 점검 방법 | C66: - 축열조의 균열 유무를 육안으로 확인
A67: 점검 기준 | C67: - 축열조의 벽면에 균열이 있는가
Z68: · 균열이 있는 경우 | AD68: · 제조사 보수
A69: 현황 사진 | I69: 적합 | Q69: 미흡사항
A70: 사진 | I70: 사진 | Q70: 사진
I78: 사유 : | K78: 균열이 없으므로 적합함 | Q78: 사유 :
A89: ③ 축열·방열 상태 및 데이터 점검
A91: 구 분 | C91: 점검내용
A92: 점검 방법 | C92: - 축열상태는 축열운전 시 브라인 순환유량과 축열조 입출구 브라인 온도를 확인하여 설계값과 | Z92: · 축열, 방열 브라인 유량과 브라인 입출구 온도가 설계 값의 ±10%를 초과하는 경우 | AD92: · 원인 파악, 상태에 따라 제조사 보수
...

Sheet 보일러
A2: 보일러 성능점검표 | R2: 설비번호
R3: 용 도
A4: 점검자 | C4: ='정보입력-Rev.2'!$C$9 -> 홍길동 | I4: 점검일자 | L4: ='정보입력-Rev.2'!$C$5&"."&'정보입력-Rev.2'!$E$5&"."&'정보입력-Rev.2'!$G$5&" ~ "&'정보입력-Rev.2'!$J$5&"."&'정보입력-Rev.2'!$L$5&"."&'정보입력-Rev.2'!$N$5 -> 2026.9.2 ~ 2026.9.2 | R4: 설치위치(No.)
A6: 구 분 | C6: 점검내용 | V6: 점검결과
A7: 점검 항목 | C7: ① 유지관리 점검표 확인 | V7: ○
C8: ② 노후 및 부식 상태 | V8: ○
C9: ③ 버너 연소 상태 | V9: ○
C10: ④ 수위제어 및 급수 공급 상태 | V10: ○
C11: ⑤ 화염 검출기 상태 | V11: ○
C12: ⑥ 운전 압력 상태 | V12: ○
C13: ⑦ 안전밸브 및 압력스위치 상태 | V13: ○
C14: ⑧ 배기가스 성분 측정 | V14: ○
C15: ⑨ 에너지 사용량 분석 | V15: ○
C16: ⑩ 보일러에 연결된 헤더 상태 | V16: ○
C17: ⑪ 감압밸브 작동 상태(소음, 진동) | V17: ○
A18: 조치 사항 | C18: < 미흡사항 >
C21: < 조치필요사항 >
A24: 현장 사진
A35: 비 고
A38: 작 성 방 법
A39: 1. 유지관리지침서 및 기계설비 유지관리 및 성능점검 대상 현황표와의 적합여부를 참고하여 점검결과를 작성한다.
A40: 2. 점검결과에는 [적합 ○, 조치필요 ×, 해당없음 /]을 표기한다.
A41: 3. 현황사진에는 영 별표 7 제3호의 장비를 사용한 측정사진 및 측정데이터를 포함하여 첨부한다.
A42: 4. 전체 수량의 50% 이상 범위 내에서 점검을 실시한다.
A45: ① 유지관리 점검표 확인
A47: 구 분 | C47: 점검내용
A48: 점검 기준 | C48: - 해당 기계설비의 유지관리 점검표가 있는가 | Z48: · 구비서류 미비(준공도서, 운용 매뉴얼 등) | AE48: · 미비 서류 보완
C49: - 기계설비 유지관리기준 별지 제2호서식에 따라 작성되었는가
C50: - 반기별 1회 이상 작성되었는가
A52: 현황 사진 | I52: 적합 | Q52: 미흡사항
A53: 유지관리 점검표 사진 | I53: 사진 | Q53: 사진
Z59: · 기계설비 유지관리기준 별지 제2호서식에 따라 유지관리 점검표를 반기별 1회이상 작성, 보유하고 있으므로 적합함
I61: 사유 : | K61: 기계설비유지관리 기준에 따라 반기별 1회 적정하게 작성되어 적합함 | Q61: 사유 :
A65: ② 노후 및 부식 상태
A67: 구 분 | C67: 점검내용
A68: 점검 방법 | C68: - 장비의 외관 노후 및 부식 상태를 육안으로 점검
C69: - 보일러 계속사용검사를 실시한 경우에는 대체 가능
A70: 점검 기준 | C70: - 케이싱 변형 및 파손은 없는가 | Z70: · 검사대상기기의 경우 보일 러 계속사용검사증이 없는 경우 | AE70: · 상태에 따라 부분 보수, 전체 보수, 교체
C71: - 보온 마감 상태는 양호한가
C72: - 보일러 계속사용검사증을 보유하고 있는가
...

Sheet 열교환기
A2: 열교환기 성능점검표 | R2: 설비번호
R3: 용 도
A4: 점검자 | C4: ='정보입력-Rev.2'!$C$9 -> 홍길동 | I4: 점검일자 | L4: ='정보입력-Rev.2'!$C$5&"."&'정보입력-Rev.2'!$E$5&"."&'정보입력-Rev.2'!$G$5&" ~ "&'정보입력-Rev.2'!$J$5&"."&'정보입력-Rev.2'!$L$5&"."&'정보입력-Rev.2'!$N$5 -> 2026.9.2 ~ 2026.9.2 | R4: 설치위치(No.)
A6: 구 분 | C6: 점검내용 | V6: 점검결과
A7: 점검 항목 | C7: ① 유지관리 점검표 확인 | V7: ○
C8: ② 노후 및 부식 상태 | V8: ○
C9: ③ 열교환기 튜브상태(개방검사 이력확인 등) | V9: ○
C10: ④ 응축수 배출 온도 상태(증기 열교환기에 한함) | V10: ○
C11: ⑤ 안전밸브 상태(증기 열교환기에 한함) | V11: ○
C12: ⑥ 증기트랩 상태(증기 열교환기에 한함) | V12: ○
A13: 조치 사항 | C13: < 미흡사항 >
C16: < 조치필요사항 >
A19: 현장 사진
A34: 비 고
A37: 작 성 방 법
A38: 1. 유지관리지침서 및 기계설비 유지관리 및 성능점검 대상 현황표와의 적합여부를 참고하여 점검결과를 작성한다.
A39: 2. 점검결과에는 [적합 ○, 조치필요 ×, 해당없음 /]을 표기한다.
A40: 3. 현황사진에는 영 별표 7 제3호의 장비를 사용한 측정사진 및 측정데이터를 포함하여 첨부한다.
A41: 4. 전체 수량의 50% 이상 범위 내에서 점검을 실시한다.
A44: ① 유지관리 점검표 확인
A46: 구 분 | C46: 점검내용 | Y46: · 구비서류 미비(준공도서, 운용 매뉴얼 등) | AC46: · 미비 서류 보완
A47: 점검 기준 | C47: - 해당 기계설비의 유지관리 점검표가 있는가
C48: - 기계설비 유지관리기준 별지 제2호서식에 따라 작성되었는가
C49: - 반기별 1회 이상 작성되었는가
A51: 현황 사진 | I51: 적합 | Q51: 미흡사항
A52: 유지관리 점검표 사진 | I52: 사진 | Q52: 사진
Z58: · 기계설비 유지관리기준 별지 제2호서식에 따라 유지관리 점검표를 반기별 1회이상 작성, 보유하고 있으므로 적합함
I60: 사유 : | K60: 기계설비유지관리 기준에 따라 반기별 1회 적정하게 작성되어 적합함 | Q60: 사유 :
A64: ② 노후 및 부식 상태
A66: 구 분 | C66: 점검내용
A67: 점검 방법 | C67: - 장비의 외관 상태를 육안으로 점검
A68: 점검 기준 | C68: - 장비 본체의 케이싱 변형 및 파손은 없는가
C69: - 장비 본체의 보온 마감 상태는 양호한가
C70: - 부속 밸브류의 접속 부위 및 외관 상태는 양호한가
C71: - 온도계, 압력계의 연결 부위 상태는 양호한가
A73: 현황 사진 | I73: 적합 | Q73: 미흡사항
A74: 사진 | I74: 사진 | Q74: 사진
I82: 사유 : | K82: 보온마감 양호하고 케이싱 파손이 없으며, 접속 및 연결부위 양호하므로 적합함 | Q82: 사유 :
A91: ③ 열교환기 튜브상태(개방검사 이력확인 등)
A93: 구 분 | D93: 점검내용 | Y93: · 정격 운전 기준 이전 성능 점검 열교환 효율 대비 금년 성능점검 열교환 효율이 90% 미만인 경우 | AC93: · 열교환기 세관
...

Sheet 팽창탱크
A2: 팽창탱크 성능점검표 | R2: 설비번호
R3: 용 도
A4: 점검자 | C4: ='정보입력-Rev.2'!$C$9 -> 홍길동 | I4: 점검일자 | L4: ='정보입력-Rev.2'!$C$5&"."&'정보입력-Rev.2'!$E$5&"."&'정보입력-Rev.2'!$G$5&" ~ "&'정보입력-Rev.2'!$J$5&"."&'정보입력-Rev.2'!$L$5&"."&'정보입력-Rev.2'!$N$5 -> 2026.9.2 ~ 2026.9.2 | R4: 설치위치(No.)
A6: 구 분 | C6: 점검내용 | V6: 점검결과
A7: 점검 항목 | C7: ① 유지관리 점검표 확인 | V7: ○
C8: ② 균열 및 부식 상태 | V8: ○
C9: ③ 블래더 작동 상태 | V9: ○
C10: ④ 팽창탱크 배관 및 안전밸브 상태 | V10: ○
A11: 조치 사항 | C11: < 미흡사항 >
C14: < 조치필요사항 >
A17: 현장 사진
A34: 비 고
A37: 작 성 방 법
A38: 1. 유지관리지침서 및 기계설비 유지관리 및 성능점검 대상 현황표와의 적합여부를 참고하여 점검결과를 작성한다.
A39: 2. 점검결과에는 [적합 ○, 조치필요 ×, 해당없음 /]을 표기한다.
A40: 3. 현황사진에는 영 별표 7 제3호의 장비를 사용한 측정사진 및 측정데이터를 포함하여 첨부한다.
A41: 4. 밀폐식 팽창탱크, 팽창기수분리기, 급탕용 팽창탱크 등을 포함하여 작성한다.
A44: ① 유지관리 점검표 확인
A46: 구 분 | C46: 점검내용
A47: 점검 기준 | C47: - 해당 기계설비의 유지관리 점검표가 있는가 | Y47: · 구비서류 미비(준공도서, 운용 매뉴얼 등) | AC47: · 미비 서류 보완
C48: - 기계설비 유지관리기준 별지 제2호서식에 따라 작성되었는가
C49: - 반기별 1회 이상 작성되었는가
A51: 현황 사진 | I51: 적합 | Q51: 미흡사항
A52: 유지관리 점검표 사진 | I52: 사진 | Q52: 사진
Y58: · 기계설비 유지관리기준 별지 제2호서식에 따라 유지관리 점검표를 반기별 1회이상 작성, 보유하고 있으므로 적합함
I60: 사유 : | K60: 기계설비유지관리 기준에 따라 반기별 1회 적정하게 작성되어 적합함 | Q60: 사유 :
A64: ② 균열 및 부식상태
A66: 구 분 | C66: 점검내용
A67: 점검 방법 | C67: - 팽창탱크의 누수 및 부식상태를 육안으로 확인
A68: 점검 기준 | C68: - 부식이 발생하지 않고 누수가 없는가
Y69: · 탱크 표면 균열 발생 | AC69: · 탱크 균열부위 보수 또는 교체
A70: 현황 사진 | I70: 적합 | Q70: 미흡사항
A71: 사진 | I71: 사진 | Q71: 사진 | Y71: · 탱크 외부 및 배관 연결부 위 부식 발생 | AC71: · 녹 제거 후 도장 또는 배관 교체
I79: 사유 : | K79: 부식이 발생하지 않고 누수가 없으므로 적합함 | Q79: 사유 :
A90: ③ 블래더 작동 상태
A92: 구 분 | C92: 점검내용
A93: 점검 방법 | C93: - 운전 전, 후 팽창탱크 연결 배관 압력 확인
A94: 점검 기준 | C94: - 팽창탱크 연결부 압력과 설정압력(설계압력) 이내로 유지되는지 확인
Y95: · 설정압력(설계압력)대로 유 지하지 못함 | AC95: · 블래더 교체 또는 탱크 봉 입 압력 조정
A96: 현황 사진 | I96: 적합 | Q96: 미흡사항
...

Sheet 펌프
A2: 펌프(냉·난방) 성능점검표 | R2: 설비번호
R3: 용 도
A4: 점검자 | C4: ='정보입력-Rev.2'!$C$9 -> 홍길동 | I4: 점검일자 | L4: ='정보입력-Rev.2'!$C$5&"."&'정보입력-Rev.2'!$E$5&"."&'정보입력-Rev.2'!$G$5&" ~ "&'정보입력-Rev.2'!$J$5&"."&'정보입력-Rev.2'!$L$5&"."&'정보입력-Rev.2'!$N$5 -> 2026.9.2 ~ 2026.9.2 | R4: 설치위치(No.)
A6: 구 분 | C6: 점검내용 | V6: 점검결과
A7: 점검 항목 | C7: ① 유지관리 점검표 확인 | V7: ○
C8: ② 샤프트 및 패킹 마모 상태 | V8: ○
C9: ③ 이상 소음 및 진동 상태 | V9: ○
C10: ④ 베어링 및 모터 등 과열 상태 | V10: ○
C11: ⑤ 베이스 앵커볼트 노후 및 풀림 상태 | V11: ○
C12: ⑥ 이상 전류 차단 장치 동작 상태 | V12: ○
C13: ⑦ 유량, 양정 및 동력 적정 상태 | V13: ○
A14: 조치 사항 | C14: < 미흡사항 >
C17: < 조치필요사항 >
A20: 현장 사진
A34: 비 고
A37: 작 성 방 법
A38: 1. 유지관리지침서 및 기계설비 유지관리 및 성능점검 대상 현황표와의 적합여부를 참고하여 점검결과를 작성한다.
A39: 2. 점검결과에는 [적합 ○, 조치필요 ×, 해당없음 /]을 표기한다.
A40: 3. 현황사진에는 영 별표 7 제3호의 장비를 사용한 측정사진 및 측정데이터를 포함하여 첨부한다.
A41: 4. 전체 수량의 20% 이상 범위 내에서 점검을 실시한다.
A42: 5. 순환펌프, 급수펌프, 배수펌프, 오수펌프, 수중펌프 등을 포함하여 작성한다.
A45: ① 유지관리 점검표 확인
A47: 구 분 | C47: 점검내용 | Y47: · 구비서류 미비(준공도서, 운용 매뉴얼 등) | AC47: · 미비 서류 보완
A48: 점검 기준 | C48: - 해당 기계설비의 유지관리 점검표가 있는가
C49: - 기계설비 유지관리기준 별지 제2호서식에 따라 작성되었는가
C50: - 반기별 1회 이상 작성되었는가
A52: 현황 사진 | I52: 적합 | Q52: 미흡사항
A53: 유지관리 점검표 사진 | I53: 사진 | Q53: 사진
Y59: · 기계설비 유지관리기준 별지 제2호서식에 따라 유지관리 점검표를 반기별 1회이상 작성, 보유하고 있으므로 적합함
I60: 사유 : | K60: 기계설비유지관리 기준에 따라 반기별 1회 적정하게 작성되어 적합함 | Q60: 사유 :
A64: ② 샤프트 및 패킹 마모 상태
A66: 구 분 | C66: 점검내용
A67: 점검 방법 | C67: - 펌프 샤프트 부위의 누수와 그랜드패킹 또는 메카니컬씰의 마모 상태 확인
A68: 점검 기준 | C68: 그랜드패킹 | G68: - 패킹 누르개에서 물방울이 조금 떨어질 것 | Y68: 그랜드패킹 | Z68: 누수량이 많을 경우 | AC68: 패킹 누르개의 조임량을 늘림
C69: 메카니컬씰 | G69: - 누수되지 않을 것 | AC69: 그랜드패킹 교체
Y70: 메카니컬씰 | AC70: 메카니컬씰 교체
A71: 현황 사진 | I71: 적합 | Q71: 미흡사항
A72: 사진 | I72: 사진 | Q72: 사진
I80: 사유 : | K80: 누수되지 않아 적합함 | Q80: 사유 :
A92: ③ 이상 소음 및 진동 상태
...

Sheet 신재생에너지(지열)
A2: 신재생에너지(지열) 시스템 성능점검표 | R2: 설비번호
R3: 용 도
A4: 점검자 | C4: ='정보입력-Rev.2'!$C$9 -> 홍길동 | I4: 점검일자 | L4: ='정보입력-Rev.2'!$C$5&"."&'정보입력-Rev.2'!$E$5&"."&'정보입력-Rev.2'!$G$5&" ~ "&'정보입력-Rev.2'!$J$5&"."&'정보입력-Rev.2'!$L$5&"."&'정보입력-Rev.2'!$N$5 -> 2026.9.2 ~ 2026.9.2 | R4: 설치위치(No.)
A6: 구 분 | C6: 점검내용 | V6: 점검결과
A7: 점검 항목 | C7: ① 유지관리 점검표 확인 | V7: ○
C8: ② 노후, 부식 상태 | V8: ○
C9: ③ 지열시스템 및 히트펌프 정상 작동 상태 | V9: ○
A10: 조치 사항 | C10: < 미흡사항 >
C13: < 조치필요사항 >
A16: 현장 사진
A30: 비 고
A33: 작 성 방 법
A34: 1. 유지관리지침서 및 기계설비 유지관리 및 성능점검 대상 현황표와의 적합여부를 참고하여 점검결과를 작성한다.
A35: 2. 점검결과에는 [적합 ○, 조치필요 ×, 해당없음 /]을 표기한다.
A36: 3. 현황사진에는 영 별표 7 제3호의 장비를 사용한 측정사진 및 측정데이터를 포함하여 첨부한다.
A39: ① 유지관리 점검표 확인
A41: 구 분 | C41: 점검내용
A42: 점검 기준 | C42: - 해당 기계설비의 유지관리 점검표가 있는가 | Z42: · 구비서류 미비(준공도서, 운용 매뉴얼 등) | AE42: · 미비 서류 보완
C43: - 기계설비 유지관리기준 별지 제2호서식에 따라 작성되었는가
C44: - 반기별 1회 이상 작성되었는가
A46: 현황 사진 | I46: 적합 | Q46: 미흡사항
A47: 유지관리 점검표 사진 | I47: 사진 | Q47: 사진
Z53: · 기계설비 유지관리기준 별지 제2호서식에 따라 유지관리 점검표를 반기별 1회이상 작성, 보유하고 있으므로 적합함
I55: 사유 : | K55: 기계설비유지관리 기준에 따라 반기별 1회 적정하게 작성되어 적합함 | Q55: 사유 :
A59: ② 노후, 부식 상태
A61: 구 분 | C61: 점검내용
A62: 점검 방법 | C62: - 장비 사용 연수, 외관 및 설치 상태에 대한 육안점검
A63: 점검 기준 | C63: - 장비의 사용 연수는 얼마인가 | Z63: · 육안점검 시 성능에 문제가 될 정도의 노후 및 부식이 발생했을 경우 | AE63: · 상태에 따라 부분 보수, 전 체 보수, 교체
C64: - 방진상태, 부식 등이 확인되는가
C65: - 주위배관 및 부속류의 손상, 변형, 부식은 없는가
C66: - MCC 및 현장패널의 설정값과 계측값은 일치하는가
A68: 현황 사진 | I68: 적합 | Q68: 미흡사항
A69: 사진 | I69: 사진 | Q69: 사진
I77: 사유 : | K77: 사용연수가 00년으로 손상, 변형, 부식이 없으며 패널의 설정값과 계측값이 일치하므로 적합함 | Q77: 사유 :
A85: ③ 지열시스템 및 히트펌프 정상 작동 상태
A87: 구 분 | C87: 점검내용
A88: 점검 방법 | C88: - 지열시스템 제어 판넬 또는 중앙감시반을 통해 확인 | Z88: · 냉방 시 전년도에 비하여 지열 공급 온도가 현저하게 높은 경우 | AE88: · 제조사 보수 및 원인 파악
C89: * 지열순환펌프 유량 및 지열 공급/환수 온도는 제어 판넬 또는 중앙감시반을 통해서 확인
C90: 가능할 경우만 확인
C91: * 유량, 공급 온도를 판넬 또는 중앙감시반에서 확인할 수 없다 하더라도 미흡사항은 아님 | Z91: · 난방 시 전년도에 비하여 지열 공급 온도가 현저하게 낮은 경우 | AE91: · 제조사 보수 및 원인 파악
...

Sheet 신재생에너지(태양열)
A2: 신재생에너지(태양열) 시스템 성능점검표 | R2: 설비번호
R3: 용 도
A4: 점검자 | C4: ='정보입력-Rev.2'!$C$9 -> 홍길동 | I4: 점검일자 | L4: ='정보입력-Rev.2'!$C$5&"."&'정보입력-Rev.2'!$E$5&"."&'정보입력-Rev.2'!$G$5&" ~ "&'정보입력-Rev.2'!$J$5&"."&'정보입력-Rev.2'!$L$5&"."&'정보입력-Rev.2'!$N$5 -> 2026.9.2 ~ 2026.9.2 | R4: 설치위치(No.)
A6: 구 분 | C6: 점검내용 | V6: 점검결과
A7: 점검 항목 | C7: ① 유지관리 점검표 확인 | V7: ○
C8: ② 노후, 부식 상태 | V8: ○
C9: ③ 태양열 집열기, 축열조 온도 상태 | V9: ○
A10: 조치 사항 | C10: < 미흡사항 >
C13: < 조치필요사항 >
A16: 현장 사진
A30: 비 고
A33: 작 성 방 법
A34: 1. 유지관리지침서 및 기계설비 유지관리 및 성능점검 대상 현황표와의 적합여부를 참고하여 점검결과를 작성한다.
A35: 2. 점검결과에는 [적합 ○, 조치필요 ×, 해당없음 /]을 표기한다.
A36: 3. 현황사진에는 영 별표 7 제3호의 장비를 사용한 측정사진 및 측정데이터를 포함하여 첨부한다.
A39: ① 유지관리 점검표 확인
A41: 구 분 | C41: 점검내용
A42: 점검 기준 | C42: - 해당 기계설비의 유지관리 점검표가 있는가 | Z42: · 구비서류 미비(준공도서, 운용 매뉴얼 등) | AE42: · 미비 서류 보완
C43: - 기계설비 유지관리기준 별지 제2호서식에 따라 작성되었는가
C44: - 반기별 1회 이상 작성되었는가
A46: 현황 사진 | I46: 적합 | Q46: 미흡사항
A47: 유지관리 점검표 사진 | I47: 사진 | Q47: 사진
Z53: · 기계설비 유지관리기준 별지 제2호서식에 따라 유지관리 점검표를 반기별 1회이상 작성, 보유하고 있으므로 적합함
I55: 사유 : | K55: 기계설비유지관리 기준에 따라 반기별 1회 적정하게 작성되어 적합함 | Q55: 사유 :
A59: ② 노후, 부식 상태
A61: 구 분 | C61: 점검내용
A62: 점검 방법 | C62: - 장비 사용 연수, 외관 및 설치 상태에 대한 육안점검
A63: 점검 기준 | C63: - 장비의 사용 연수는 얼마인가 | Z63: · 육안점검 시 성능에 문제가 될 정도의 노후 및 부식이 발생했을 경우 | AE63: · 상태에 따라 부분 보수, 전 체 보수, 교체
C64: - 방진상태, 부식 등이 확인되는가
C65: - 주위배관 및 부속류의 손상, 변형, 부식은 없는가
C66: - MCC 및 현장패널의 설정값과 계측값은 일치하는가
A68: 현황 사진 | I68: 적합 | Q68: 미흡사항
A69: 사진 | I69: 사진 | Q69: 사진
I77: 사유 : | K77: 사용연수가 00년으로 손상, 변형, 부식이 없으며 패널의 설정값과 계측값이 일치하므로 적합함 | Q77: 사유 :
A85: ③ 태양열 집열기, 축열조 온도 상태
A87: 구 분 | C87: 점검내용
A88: 점검 방법 | C88: - 태양열 급탕시스템의 차온제어기 확인
A89: 점검 기준 | C89: - 축열조의 급탕 온도가 설계값의 ±10% 이내
Z90: · 축열조의 온도가 설계값의 ±10% 범위를 벗어났을 경 우 | AE90: · 제조사 보수
A91: 현황 사진 | I91: 적합 | Q91: 미흡사항
...

Sheet 신재생에너지(연료전지)
A2: 신재생에너지(연료전지) 성능점검표 | R2: 설비번호
R3: 용 도
A4: 점검자 | C4: ='정보입력-Rev.2'!$C$9 -> 홍길동 | I4: 점검일자 | L4: ='정보입력-Rev.2'!$C$5&"."&'정보입력-Rev.2'!$E$5&"."&'정보입력-Rev.2'!$G$5&" ~ "&'정보입력-Rev.2'!$J$5&"."&'정보입력-Rev.2'!$L$5&"."&'정보입력-Rev.2'!$N$5 -> 2026.9.2 ~ 2026.9.2 | R4: 설치위치(No.)
A6: 구 분 | C6: 점검내용 | V6: 점검결과
A7: 점검 항목 | C7: ① 유지관리 점검표 확인 | V7: ○
C8: ② 노후, 부식 상태 | V8: ○
C9: ③ 연료전지 발전부 온도 상태 | V9: ○
A10: 조치 사항 | C10: < 미흡사항 >
C13: < 조치필요사항 >
A16: 현장 사진
A30: 비 고
A33: 작 성 방 법
A34: 1. 유지관리지침서 및 기계설비 유지관리 및 성능점검 대상 현황표와의 적합여부를 참고하여 점검결과를 작성한다.
A35: 2. 점검결과에는 [적합 ○, 조치필요 ×, 해당없음 /]을 표기한다.
A36: 3. 현황사진에는 영 별표 7 제3호의 장비를 사용한 측정사진 및 측정데이터를 포함하여 첨부한다.
A39: ① 유지관리 점검표 확인
A41: 구 분 | C41: 점검내용
A42: 점검 기준 | C42: - 해당 기계설비의 유지관리 점검표가 있는가 | Z42: · 구비서류 미비(준공도서, 운용 매뉴얼 등) | AE42: · 미비 서류 보완
C43: - 기계설비 유지관리기준 별지 제2호서식에 따라 작성되었는가
C44: - 반기별 1회 이상 작성되었는가
A46: 현황 사진 | I46: 적합 | Q46: 미흡사항
A47: 유지관리 점검표 사진 | I47: 사진 | Q47: 사진
Z54: · 기계설비 유지관리기준 별지 제2호서식에 따라 유지관리 점검표를 반기별 1회이상 작성, 보유하고 있으므로 적합함
I55: 사유 : | K55: 기계설비유지관리 기준에 따라 반기별 1회 적정하게 작성 되어 적합함 | Q55: 사유 :
A59: ② 노후, 부식 상태
A61: 구 분 | C61: 점검내용
A62: 점검 방법 | C62: - 장비 사용 연수, 외관 및 설치 상태에 대한 육안점검
A63: 점검 기준 | C63: - 장비의 사용 연수는 얼마인가 | Z63: · 육안점검 시 성능에 문제가 될 정도의 노후 및 부식이 발생했을 경우 | AE63: · 상태에 따라 부분 보수, 전 체 보수, 교체
C64: - 방진상태, 부식 등이 확인되는가
C65: - 주위배관 및 부속류의 손상, 변형, 부식은 없는가
A67: 현황 사진 | I67: 적합 | Q67: 미흡사항
A68: 사진 | I68: 사진 | Q68: 사진
I76: 사유 : | K76: 사용연수가 00년으로 손상, 변형, 부식이 없으므로 적합함 | Q76: 사유 :
A86: ③ 연료전지 발전부 온도 상태
A88: 구 분 | C88: 점검내용
A89: 점검 방법 | C89: - 제어 판넬을 통해 확인
A90: 점검 기준 | C90: - 발전부의 온도값이 설계값의 ±10% 이내인가
Z91: · 설계값의 ±10% 범위를 벗어났을 경우 | AE91: · 제조사 보수
A92: 현황 사진 | I92: 적합 | Q92: 미흡사항
A93: 사진 | I93: 사진 | Q93: 사진
...

Sheet 패키지에어컨
A2: 패키지 에어컨 성능점검표 | R2: 설비번호
R3: 용 도
A4: 점검자 | C4: ='정보입력-Rev.2'!$C$9 -> 홍길동 | I4: 점검일자 | L4: ='정보입력-Rev.2'!$C$5&"."&'정보입력-Rev.2'!$E$5&"."&'정보입력-Rev.2'!$G$5&" ~ "&'정보입력-Rev.2'!$J$5&"."&'정보입력-Rev.2'!$L$5&"."&'정보입력-Rev.2'!$N$5 -> 2026.9.2 ~ 2026.9.2 | R4: 설치위치(No.)
A6: 구 분 | C6: 점검내용 | V6: 점검결과
A7: 점검 항목 | C7: ① 유지관리 점검표 확인 | V7: ○
C8: ② 실내기 및 실외기 소음 상태 | V8: ○
C9: ③ 실외기 고정 상태 | V9: ○
C10: ④ 과열차단기 작동 상태 | V10: ○
C11: ⑤ 필터 오염 상태 | V11: ○
A12: 조치 사항 | C12: < 미흡사항 >
C15: < 조치필요사항 >
A18: 현장 사진
A34: 비 고
A37: 작 성 방 법
A38: 1. 유지관리지침서 및 기계설비 유지관리 및 성능점검 대상 현황표와의 적합여부를 참고하여 점검결과를 작성한다.
A39: 2. 점검결과에는 [적합 ○, 조치필요 ×, 해당없음 /]을 표기한다.
A40: 3. 현황사진에는 영 별표 7 제3호의 장비를 사용한 측정사진 및 측정데이터를 포함하여 첨부한다.
A41: 4. 전체 수량의 20% 이상 범위 내에서 점검을 실시한다.
A42: 5. 에어컨, 시스템에어컨, EHP, GHP, CDU 등을 포함하여 작성한다.
A45: ① 유지관리 점검표 확인
A47: 구 분 | C47: 점검내용
A48: 점검 기준 | C48: - 해당 기계설비의 유지관리 점검표가 있는가 | Y48: · 구비서류 미비(준공도서, 운용 매뉴얼 등) | AC48: · 미비 서류 보완
C49: - 기계설비 유지관리기준 별지 제2호서식에 따라 적정하게 작성되었는가
C50: - 반기별 1회 이상 작성되었는가
A52: 현황 사진 | I52: 적합 | Q52: 미흡사항
A53: 유지관리 점검표 사진 | I53: 사진 | Q53: 사진
Y59: · 기계설비 유지관리기준 별지 제2호서식에 따라 유지관리 점검표를 반기별 1회이상 작성, 보유하고 있으므로 적합함
I61: 사유 : | K61: 기계설비유지관리 기준에 따라 반기별 1회 적정하게 작성되어 적합함 | Q61: 사유 :
A65: ② 실내기 및 실외기 소음상태
A67: 구 분 | C67: 점검내용
A68: 점검 방법 | C68: - 실내기, 실외기 소음 상태 확인
A70: 점검 기준 | C70: - 실내기 및 실외기 이상 소음 발생 여부
Y72: · 실내기 및 실외기에서 이상 소음이 발생하는 경우 | AC72: · 제조사 보수
A73: 현황 사진 | I73: 적합 | Q73: 미흡사항
A74: 사진 | I74: 사진 | Q74: 사진
I82: 사유 : | K82: 운전중 이상소음이 발생하지 않으므로 적합함 | Q82: 사유 :
A92: ③ 실외기 고정 상태
A94: 구 분 | C94: 점검내용
A95: 점검 방법 | C95: - 실외기 고정상태 육안 확인
Y96: · 서포트의 기능을 하지 못할 정도의 부식이나 녹이 발생 한 경우 | AC96: · 제조사 보수
...

Sheet 항온항습기
A2: 항온항습기 성능점검표 | R2: 설비번호
R3: 용 도
A4: 점검자 | C4: ='정보입력-Rev.2'!$C$9 -> 홍길동 | I4: 점검일자 | L4: ='정보입력-Rev.2'!$C$5&"."&'정보입력-Rev.2'!$E$5&"."&'정보입력-Rev.2'!$G$5&" ~ "&'정보입력-Rev.2'!$J$5&"."&'정보입력-Rev.2'!$L$5&"."&'정보입력-Rev.2'!$N$5 -> 2026.9.2 ~ 2026.9.2 | R4: 설치위치(No.)
A6: 구 분 | C6: 점검내용 | V6: 점검결과
A7: 점검 항목 | C7: ① 유지관리 점검표 확인 | V7: ○
C8: ② 실외기 부식 상태 | V8: ○
C9: ③ 실내기 및 실외기 송풍기 이상 소음 ‧ 진동 상태 | V9: ○
C10: ④ 과열차단기 작동 상태 | V10: ○
C11: ⑤ 필터 오염 상태 | V11: ○
A12: 조치 사항 | C12: < 미흡사항 >
C15: < 조치필요사항 >
A18: 현장 사진
A34: 비 고
A37: 작 성 방 법
A38: 1. 유지관리지침서 및 기계설비 유지관리 및 성능점검 대상 현황표와의 적합여부를 참고하여 점검결과를 작성한다.
A39: 2. 점검결과에는 [적합 ○, 조치필요 ×, 해당없음 /]을 표기한다.
A40: 3. 현황사진에는 영 별표 7 제3호의 장비를 사용한 측정사진 및 측정데이터를 포함하여 첨부한다.
A41: 4. 전체 수량의 20% 이상 범위 내에서 점검을 실시한다.
A44: ① 유지관리 점검표 확인
A46: 구 분 | C46: 점검내용
A47: 점검 기준 | C47: - 해당 기계설비의 유지관리 점검표가 있는가 | Z47: · 구비서류 미비(준공도서, 운용 매뉴얼 등) | AE47: · 미비 서류 보완
C48: - 기계설비 유지관리기준 별지 제2호서식에 따라 적정하게 작성되었는가
C49: - 반기별 1회 이상 작성되었는가
A51: 현황 사진 | I51: 적합 | Q51: 미흡사항
A52: 유지관리 점검표 사진 | I52: 사진 | Q52: 사진
I60: 사유 : | K60: 기계설비유지관리 기준에 따라 반기별 1회 적정하게 작성되어 적합함 | Q60: 사유 : | Z60: · 기계설비 유지관리기준 별지 제2호서식에 따라 유지관리 점검표를 반기별 1회이상 작성, 보유하고 있으므로 적합함
A64: ② 실외기 부식상태
A66: 구 분 | C66: 점검내용
A67: 점검 방법 | C67: - 외관 및 설치 상태에 대한 육안점검 | Z67: · 서포트의 기능을 하지 못할 정도의 부식이나 녹이 발생 한 경우 | AE67: · 제조사 보수
A69: 점검 기준 | C69: - 부식 흔적이 있는가(성능에 문제가 될 정도의 부식이 상당히 진행된 경우 미흡사항)
A72: 현황 사진 | I72: 적합 | Q72: 미흡사항
A73: 사진 | I73: 사진 | Q73: 사진
I81: 사유 : | K81: 성능에 문제가 될정도의 부식이 없으므로 적합함 | Q81: 사유 :
A91: ③ 실내기 및 실외기 송풍기 이상 소음·진동 상태
A93: 구 분 | C93: 점검내용
A94: 점검 방법 | C94: - 소음 및 진동상태 확인 | Z94: · 실내기 및 실외기 이상 소 음·진동이 발생하는 경우 | AE94: · 제조사 보수
A96: 점검 기준 | C96: - 평시 운전과 다른 소음이나 진동이 있는가
A99: 현황 사진 | I99: 적합 | Q99: 미흡사항
A100: 사진 | I100: 사진 | Q100: 사진
I108: 사유 : | K108: 운전시 이상 진동, 소음이 없으므로 적합함 | Q108: 사유 :
...

Sheet 공기조화기
A2: 공기조화기 성능점검표 | R2: 설비번호
R3: 용 도
A4: 점검자 | C4: ='정보입력-Rev.2'!$C$9 -> 홍길동 | I4: 점검일자 | L4: ='정보입력-Rev.2'!$C$5&"."&'정보입력-Rev.2'!$E$5&"."&'정보입력-Rev.2'!$G$5&" ~ "&'정보입력-Rev.2'!$J$5&"."&'정보입력-Rev.2'!$L$5&"."&'정보입력-Rev.2'!$N$5 -> 2026.9.2 ~ 2026.9.2 | R4: 설치위치(No.)
A6: 구 분 | C6: 점검내용 | V6: 점검결과
A7: 점검 항목 | C7: ① 유지관리 점검표 확인 | V7: ○
C8: ② 외부 케이싱 부식, 손상, 변형 상태 | V8: ○
C9: ③ 전동댐퍼(OA, EA, RA) 작동 상태 | V9: ○
C10: ④ 동파방지 장치 작동 상태 | V10: ○
C11: ⑤ 공기조화기(송풍기) 풍량 상태 | V11: ○
C12: ⑥ 폐열회수장치 작동 상태 | V12: ○
C13: ⑦ 소음, 진동 상태 | V13: ○
C14: ⑧ 필터 오염 상태 | V14: ○
A15: 조치 사항 | C15: < 미흡사항 >
C18: < 조치필요사항 >
A21: 현장 사진
A35: 비 고
A37: 작 성 방 법
A38: 1. 유지관리지침서 및 기계설비 유지관리 및 성능점검 대상 현황표와의 적합여부를 참고하여 점검결과를 작성한다.
A39: 2. 점검결과에는 [적합 ○, 조치필요 ×, 해당없음 /]을 표기한다.
A40: 3. 현황사진에는 영 별표 7 제3호의 장비를 사용한 측정사진 및 측정데이터를 포함하여 첨부한다.
A41: 4. 전체 수량의 20% 이상 범위 내에서 점검을 실시한다.
A44: ① 유지관리 점검표 확인
A46: 구 분 | C46: 점검내용
A47: 점검 기준 | C47: - 해당 기계설비의 유지관리 점검표가 있는가 | Z47: · 구비서류 미비(준공도서, 운용 매뉴얼 등) | AE47: · 미비 서류 보완
C48: - 기계설비 유지관리기준 별지 제2호서식에 따라 적정하게 작성되었는가
C49: - 반기별 1회 이상 작성되었는가
A51: 현황 사진 | I51: 적합 | Q51: 미흡사항
A52: 유지관리 점검표 사진 | I52: 사진 | Q52: 사진
Z58: · 기계설비 유지관리기준 별지 제2호서식에 따라 유지관리 점검표를 반기별 1회이상 작성, 보유하고 있으므로 적합함
I60: 사유 : | K60: 기계설비유지관리 기준에 따라 반기별 1회 적정하게 작성되어 적합함 | Q60: 사유 :
A64: ② 외부 케이싱 부식, 손상, 변형 상태
A66: 구 분 | C66: 점검내용
A67: 점검 방법 | C67: - 장비 외관 및 설치 상태에 대한 육안점검 | Z67: · 성능에 문제가 될 정도의 부식, 손상, 변형 이 발생 했을 경우 | AE67: · 부분 보수 및 교체
A69: 점검 기준 | C69: - 케이싱에 손상이나 변형된 부분이 있는가
C70: - 부식 흔적이 있는가
A72: 현황 사진 | I72: 적합 | Q72: 미흡사항
A73: 사진 | I73: 사진 | Q73: 사진
I81: 사유 : | K81: 부식이 없고 변형된 부분이 없으므로 적합함 | Q81: 사유 :
A91: ③ 전동댐퍼(OA, EA, RA) 작동 상태
A93: 구 분 | C93: 점검내용
...

Sheet 팬코일유닛
A2: 팬코일 유닛 성능점검표 | R2: 설비번호
R3: 용 도
A4: 점검자 | C4: ='정보입력-Rev.2'!$C$9 -> 홍길동 | I4: 점검일자 | L4: ='정보입력-Rev.2'!$C$5&"."&'정보입력-Rev.2'!$E$5&"."&'정보입력-Rev.2'!$G$5&" ~ "&'정보입력-Rev.2'!$J$5&"."&'정보입력-Rev.2'!$L$5&"."&'정보입력-Rev.2'!$N$5 -> 2026.9.2 ~ 2026.9.2 | R4: 설치위치(No.)
A6: 구 분 | C6: 점검내용 | V6: 점검결과
A7: 점검 항목 | C7: ① 유지관리 점검표 확인 | V7: ○
C8: ② 노후 및 부식 상태 | V8: ○
C9: ③ 전동밸브 정상 작동 상태 | V9: ○
C10: ④ 조닝 적정 상태 | V10: ○
C11: ⑤ 팬코일 풍량 조절 상태 | V11: ○
C12: ⑥ 필터 오염 상태 | V12: ○
A13: 조치 사항 | C13: < 미흡사항 >
C16: < 조치필요사항 >
A19: 현장 사진
A33: 비 고
A36: 작 성 방 법
A37: 1. 유지관리지침서 및 기계설비 유지관리 및 성능점검 대상 현황표와의 적합여부를 참고하여 점검결과를 작성한다.
A38: 2. 점검결과에는 [적합 ○, 조치필요 ×, 해당없음 /]을 표기한다.
A39: 3. 현황사진에는 영 별표 7 제3호의 장비를 사용한 측정사진 및 측정데이터를 포함하여 첨부한다.
A40: 4. 전체 수량의 20% 이상 범위 내에서 점검을 실시한다.
A41: 5. 팬파워 유닛, 터미널 유닛, 팬컨벡터 등을 포함하여 작성한다.
A44: ① 유지관리 점검표 확인
A46: 구 분 | C46: 점검내용
A47: 점검 기준 | C47: - 해당 기계설비의 유지관리 점검표가 있는가 | Z47: · 구비서류 미비(준공도서, 운용 매뉴얼 등) | AE47: · 미비 서류 보완
C48: - 기계설비 유지관리기준 별지 제2호서식에 따라 적정하게 작성되었는가
C49: - 반기별 1회 이상 작성되었는가
A51: 현황 사진 | I51: 적합 | Q51: 미흡사항
A52: 유지관리 점검표 사진 | I52: 사진 | Q52: 사진
Z59: · 기계설비 유지관리기준 별지 제2호서식에 따라 유지관리 점검표를 반기별 1회이상 작성, 보유하고 있으므로 적합함
I60: 사유 : | K60: 기계설비유지관리 기준에 따라 반기별 1회 적정하게 작성되어 적합함 | Q60: 사유 :
A64: ② 노후 및 부식 상태
A66: 구 분 | C66: 점검내용
A67: 점검 방법 | C67: - 장비 사용 연수, 외관 및 설치 상태에 대한 육안점검
A69: 점검 기준 | C69: - 장비의 사용 연수는 얼마인가 | Z69: · 성능에 문제가 될 정도의 부식, 손상, 변형이 발생했 을 경우 | AE69: · 보수 또는 교체
C70: - 케이싱, 외부 상태는 양호한가
C71: - 연결배관, 덕트의 상태는 양호한가
C72: - 점검구의 위치는 적절한가
A74: 현황 사진 | I74: 적합 | Q74: 미흡사항
A75: 사진 | I75: 사진 | Q75: 사진
I83: 사유 : | K83: 점검구 위치가 적절하고 연결배관 및 케이싱 외부 상태가 양호하므로 적합함 | Q83: 사유 :
A91: ③ 전동밸브 정상 작동 상태
...

Sheet 환기
A2: 환기설비 성능점검표 | R2: 설비번호
R3: 용 도
A4: 점검자 | C4: ='정보입력-Rev.2'!$C$9 -> 홍길동 | I4: 점검일자 | L4: ='정보입력-Rev.2'!$C$5&"."&'정보입력-Rev.2'!$E$5&"."&'정보입력-Rev.2'!$G$5&" ~ "&'정보입력-Rev.2'!$J$5&"."&'정보입력-Rev.2'!$L$5&"."&'정보입력-Rev.2'!$N$5 -> 2026.9.2 ~ 2026.9.2 | R4: 설치위치(No.)
A6: 구 분 | C6: 점검내용 | V6: 점검결과
A7: 점검 항목 | C7: ① 유지관리 점검표 확인 | V7: ○
C8: ② 노후 및 부식 상태 | V8: ○
C9: ③ 모터 및 송풍기 베어링 이상 소음 상태 | V9: ○
C10: ④ 볼륨댐퍼 개ㆍ폐쇄 상태 | V10: ○
C11: ⑤ 이산화탄소 농도 확인 (10개소 내외) | V11: ○
C12: ⑥ 급ㆍ배기 풍량 상태 | V12: ○
C13: ⑦ 필터 오염 상태 | V13: ○
A14: 조치 사항 | C14: < 미흡사항 >
C16: < 조치필요사항 >
A18: 현장 사진
A34: 비 고
A36: 작 성 방 법
A37: 1. 유지관리지침서 및 기계설비 유지관리 및 성능점검 대상 현황표와의 적합여부를 참고하여 점검결과를 작성한다.
A38: 2. 점검결과에는 [적합 ○, 조치필요 ×, 해당없음 /]을 표기한다.
A39: 3. 현황사진에는 영 별표 7 제3호의 장비를 사용한 측정사진 및 측정데이터를 포함하여 첨부한다.
A40: 4. 전체 수량의 20% 이상 범위 내에서 점검을 실시한다.
A41: 5. 송풍기, 열회수형 환기장치 등을 포함하여 작성한다.
A44: ① 유지관리 점검표 확인
A46: 구 분 | C46: 점검내용
A47: 점검 기준 | C47: - 해당 기계설비의 유지관리 점검표가 있는가 | Y47: · 구비서류 미비(준공도서, 운용 매뉴얼 등) | AC47: · 미비 서류 보완
C48: - 기계설비 유지관리기준 별지 제2호서식에 따라 적정하게 작성되었는가
C49: - 반기별 1회 이상 작성되었는가
A51: 현황 사진 | I51: 적합 | Q51: 미흡사항
A52: 유지관리 점검표 사진 | I52: 사진 | Q52: 사진
Y59: · 기계설비 유지관리기준 별지 제2호서식에 따라 유지관리 점검표를 반기별 1회이상 작성, 보유하고 있으므로 적합함
I60: 사유 : | K60: 기계설비유지관리 기준에 따라 반기별 1회 적정하게 작성되어 적합함 | Q60: 사유 :
A64: ② 노후 및 부식상태
A66: 구 분 | C66: 점검내용
A67: 점검 방법 | C67: - 장비 사용 연수, 외관 및 설치 상태에 대한 육안점검
A69: 점검 기준 | C69: - 장비의 사용 연수는 얼마인가 | Y69: · 성능에 문제가 될 정도의 부식, 손상, 변형이 발생했 을 경우 | AC69: · 보수 또는 교체
C70: - 케이싱, 방진 상태는 양호한가
C71: - 송풍기, 덕트 연결상태는 양호한가
C72: - 팬 벨트 상태는 양호한가
C73: - 덕트 오염 상태는 양호한가
A75: 현황 사진 | I75: 적합 | Q75: 미흡사항
A76: 사진 | I76: 사진 | Q76: 사진
...

Sheet 공기조화기-열교환 효율 계산법
A1: 공기조화기 성능점검표
R2: 설비번호
A3: 점검자 | C3: 한국기계설비관리㈜ | I3: 점검일자 | L3: 2022.09.15 ~ 09.30 | R3: 설치위치(No.)
A5: 구 분 | C5: 점검내용 | V5: 점검결과
A6: 점검 항목 | C6: ① 유지관리 점검표 확인 | V6: ○
C7: ② 외부 케이싱 부식, 손상, 변형 상태 | V7: ○
C8: ③ 전동댐퍼(OA, EA, RA) 작동 상태 | V8: ○
C9: ④ 동파방지 장치 작동 상태 | V9: ○
C10: ⑤ 공기조화기(송풍기) 풍량 상태 | V10: ○
C11: ⑥ 폐열회수장치 작동 상태 | V11: ○
C12: ⑦ 소음, 진동 상태 | V12: ○
A13: 부적합 | C13: < 부적합사항 >
C16: < 조치필요사항 >
A19: 현장 사진
A35: 비 고
A37: 작 성 방 법
A38: 1. 유지관리지침서 및 점검대상 기계설비 현황표와의 적합여부를 참고하여 점검결과를 작성한다.
A39: 2. 점검결과에는 [적합 ○, 부적합 ×, 해당없음 /]을 표기한다.
A40: 3. 전체 수량의 20% 이상 범위 내에서 점검을 실시한다.
A41: ① 유지관리 점검표 확인
A43: 구 분 | C43: 점검내용
A44: 점검 기준 | C44: - 해당 기계설비의 유지관리 점검표가 있는가
C45: - 기계설비 유지관리기준 별지 제2호서식에 따라 적정하게 작성되었는가
C46: - 반기별 1회 이상 작성되었는가
A48: 현황 사진 | I48: 적합 | Q48: 부적합
A49: 사진 | I49: 사진 | Q49: 사진
I57: 사유 : | Q57: 사유 :
A61: ② 외부 케이싱 부식, 손상, 변형 상태
A63: 구 분 | C63: 점검내용
A64: 점검 방법 | C64: - 장비 외관 및 설치 상태에 대한 육안점검
A66: 점검 기준 | C66: - 케이싱에 손상이나 변형된 부분이 있는가
C67: - 부식 흔적이 있는가
A69: 현황 사진 | I69: 적합 | Q69: 부적합
A70: 사진 | I70: 사진 | Q70: 사진
I78: 사유 : | Q78: 사유 :
A86: ③ 전동댐퍼(OA, EA, RA) 작동 상태
A88: 구 분 | C88: 점검내용
A89: 점검 방법 | C89: - 해당 공기조화기 댐퍼의 자동제어 지시값과 현장 전동댐퍼 동작 확인
A91: 점검 기준 | C91: - 자동제어 지시에 따라 정상적으로 구동될 것
C92: - 댐퍼 자체 고장은 없는지 확인
...

Sheet 필터
A2: 필터설비 성능점검표 | R2: 설비번호
R3: 용 도
A4: 점검자 | C4: ='정보입력-Rev.2'!$C$9 -> 홍길동 | I4: 점검일자 | L4: ='정보입력-Rev.2'!$C$5&"."&'정보입력-Rev.2'!$E$5&"."&'정보입력-Rev.2'!$G$5&" ~ "&'정보입력-Rev.2'!$J$5&"."&'정보입력-Rev.2'!$L$5&"."&'정보입력-Rev.2'!$N$5 -> 2026.9.2 ~ 2026.9.2 | R4: 설치위치(No.)
A6: 구 분 | C6: 점검내용 | V6: 점검결과
A7: 점검 항목 | C7: ① 유지관리 점검표 확인 | V7: ○ | Z7: · 구비서류 미비(준공도서, 운용 매뉴얼 등) | AE7: · 미비 서류 보완
C8: ② 필터 차압 상태 | V8: ○
C9: ③ 필터 오염 상태 | V9: ○
A10: 조치 사항 | C10: < 미흡사항 >
C13: < 조치필요사항 >
A16: 현장 사진
A28: 비 고
A30: 작 성 방 법
A31: 1. 유지관리지침서 및 기계설비 유지관리 및 성능점검 대상 현황표와의 적합여부를 참고하여 점검결과를 작성한다.
A32: 2. 점검결과에는 [적합 ○, 조치필요 ×, 해당없음 /]을 표기한다.
A33: 3. 현황사진에는 영 별표 7 제3호의 장비를 사용한 측정사진 및 측정데이터를 포함하여 첨부한다.
A34: 4. 필터유닛, 냄새제거필터유닛, 특수목적필터 등을 포함하여 작성한다.
A37: ① 유지관리 점검표 확인
A39: 구 분 | C39: 점검내용
A40: 점검 기준 | C40: - 해당 기계설비의 유지관리 점검표가 있는가 | Z40: · 구비서류 미비(준공도서, 운용 매뉴얼 등) | AE40: · 미비 서류 보완
C41: - 기계설비 유지관리기준 별지 제2호서식에 따라 적정하게 작성되었는가
C42: - 반기별 1회 이상 작성되었는가
A44: 현황 사진 | I44: 적합 | Q44: 미흡사항
A45: 유지관리 점검표 사진 | I45: 사진 | Q45: 사진
Z51: · 기계설비 유지관리기준 별지 제2호서식에 따라 유지관리 점검표를 반기별 1회이상 작성, 보유하고 있으므로 적합함
I53: 사유 : | K53: 기계설비유지관리 기준에 따라 반기별 1회 적정하게 작성되어 적합함 | Q53: 사유 :
A57: ② 필터 차압 상태
A59: 구 분 | C59: 점검내용
A60: 점검 방법 | C60: - 필터에 설치된 차압계 측정값 확인
A62: 점검 기준 | C62: - 필터 말기 차압(설계값 또는 제조사 기준값) 이하일 것 | Z62: · 필터 말기 차압을 초과할 경우 | AF62: · 필터 교체
AB63: (50mmAq 이상)
A65: 현황 사진 | I65: 적합 | Q65: 미흡사항
A66: 사진 | I66: 사진 | Q66: 사진
I74: 사유 : | K74: 필터 말기 차압이 기준값(50mmAq) 이하로 적합함 | Q74: 사유 :
A84: ③ 필터 오염 상태
A86: 구 분 | C86: 점검내용
A87: 점검 방법 | C87: - 필터 상태 육안 점검
A89: 점검 기준 | C89: - 필터 오염 상태가 양호한가 | Z89: · 필터 말기 차압을 초과할 경우 | AF89: · 필터 교체
AB90: (50mmAq 이상)
A92: 현황 사진 | I92: 적합 | Q92: 미흡사항
A93: 사진 | I93: 사진 | Q93: 사진
...

Sheet 위생기구
A2: 위생기구설비 성능점검표 | R2: 설비번호 | U2: 위생기구설비
R3: 용 도 | U3: 화장실
A4: 점검자 | C4: ='정보입력-Rev.2'!$C$9 -> 홍길동 | I4: 점검일자 | L4: ='정보입력-Rev.2'!$C$5&"."&'정보입력-Rev.2'!$E$5&"."&'정보입력-Rev.2'!$G$5&" ~ "&'정보입력-Rev.2'!$J$5&"."&'정보입력-Rev.2'!$L$5&"."&'정보입력-Rev.2'!$N$5 -> 2026.9.2 ~ 2026.9.2 | R4: 설치위치(No.) | U4: 각층 화장실
A6: 구 분 | C6: 점검내용 | V6: 점검결과
A7: 점검 항목 | C7: ① 유지관리 점검표 확인 | V7: ○
C8: ② 자동 ‧ 수동 급수전 동작 상태 및 급수상태(10개소 내외) | V8: ○
C9: ③ 동파 방지 조치 상태 | V9: ○
C10: ④ 최상층 수전 사용에 따른 수격작용 상태 | V10: ○
A11: 조치 사항 | C11: < 미흡사항 >
C14: < 조치필요사항 >
A17: 현장 사진
A36: 비 고
A38: 작 성 방 법
A39: 1. 유지관리지침서 및 기계설비 유지관리 및 성능점검 대상 현황표와의 적합여부를 참고하여 점검결과를 작성한다.
A40: 2. 점검결과에는 [적합 ○, 조치필요 ×, 해당없음 /]을 표기한다.
A41: 3. 현황사진에는 영 별표 7 제3호의 장비를 사용한 측정사진 및 측정데이터를 포함하여 첨부한다.
A44: ① 유지관리 점검표 확인
A46: 구 분 | C46: 점검내용
A47: 점검 기준 | C47: - 해당 기계설비의 유지관리 점검표가 있는가 | Z47: · 구비서류 미비(준공도서, 운용 매뉴얼 등) | AE47: · 미비 서류 보완
C48: - 기계설비 유지관리기준 별지 제2호서식에 따라 적정하게 작성되었는가
C49: - 반기별 1회 이상 작성되었는가
A51: 현황 사진 | I51: 적합 | Q51: 미흡사항
A52: 유지관리 점검표 사진 | I52: 사진 | Q52: 사진
Z58: · 기계설비 유지관리기준 별지 제2호서식에 따라 유지관리 점검표를 반기별 1회이상 작성, 보유하고 있으므로 적합함
I60: 사유 : | K60: 기계설비유지관리 기준에 따라 반기별 1회 적정하게 작성되어 적합함 | Q60: 사유 :
A64: ② 자동·수동 급수전 동작 상태 및 급수상태(10개소 내외)
A66: 구 분 | C66: 점검내용
A67: 점검 방법 | C67: - 수전, 위생기구 급수 동작 확인
C68: - 최상층 수전, 최하층 수전 수압 측정
C69: - 점검개소는 총 10개소 내외(수전, 위생기구, 수압)
A70: 점검 기준 | C70: - 수전이 원활하게 작동 되는가(자동, 수동)
C71: - 최상층 수전, 최하층 수전의 수압은 적정한가 | Z71: · 급수전 미동작 | AE71: · 수전 보수 또는 교체
C72: * 기계설비 기술기준 [별표 5] 급수·급탕설비의 설계 및 시공 기준 표 2. 위생기구의 필요 급수압력과 유량에서 제시하는 최저필요수압 이상인가 * 층별 감압밸브가 설치되어 있는 경우 최고급수압력이 245kPa 이내인가 ※ 비고 참조 | Z72: · 수압이 기준치에서 벗어나 는 경우 | AE72: · 급수배관계통 압력 조정
A77: 현황 사진 | I77: 적합 | Q77: 미흡사항
A78: 사진 | I78: 사진 | Q78: 사진
I86: 사유 : | K86: 급수전이 정상 작동하고 수압 측정 값이 기준치에 적정하므로 적합함 | Q86: 사유 :
A91: ③ 동파 방지 조치 상태
A93: 구 분 | C93: 점검내용
A94: 점검 방법 | C94: - 화장실에 설치된 동파방지 장치(전열기, 라디에에이터, 열선 등) 가동 여부 점검
A96: 점검 기준 | C96: - 동파방지 장치가 정상적으로 동작하는가? | Z96: · 동파방지장치 미동작 | AE96: · 동파방지장치 보수 또는 교체
...

Sheet 급수급탕
A2: 급수 ‧ 급탕설비 성능점검표 | R2: 설비번호 | U2: 급수·급탕설비
R3: 용 도 | U3: 급수·급탕
A4: 점검자 | C4: ='정보입력-Rev.2'!$C$9 -> 홍길동 | I4: 점검일자 | L4: ='정보입력-Rev.2'!$C$5&"."&'정보입력-Rev.2'!$E$5&"."&'정보입력-Rev.2'!$G$5&" ~ "&'정보입력-Rev.2'!$J$5&"."&'정보입력-Rev.2'!$L$5&"."&'정보입력-Rev.2'!$N$5 -> 2026.9.2 ~ 2026.9.2 | R4: 설치위치(No.) | U4: 기계실 등
A6: 구 분 | C6: 점검내용 | V6: 점검결과
A7: 점검 항목 | C7: ① 유지관리 점검표 확인 | V7: ○
C8: ② 펌프 운전(급수, 순환, 대류) 상태 | V8: ○
C9: ③ 급탕 안전밸브 설정 상태 | V9: ○
C10: ④ 급탕탱크 열교환기 증기트랩 동작 상태 | V10: ○
A11: 조치 사항 | C11: < 미흡사항 >
C14: < 조치필요사항 >
A17: 현장 사진
A30: 비 고
A32: 작 성 방 법
A33: 1. 유지관리지침서 및 기계설비 유지관리 및 성능점검 대상 현황표와의 적합여부를 참고하여 점검결과를 작성한다.
A34: 2. 점검결과에는 [적합 ○, 조치필요 ×, 해당없음 /]을 표기한다.
A35: 3. 현황사진에는 영 별표 7 제3호의 장비를 사용한 측정사진 및 측정데이터를 포함하여 첨부한다.
A38: ① 유지관리 점검표 확인
A40: 구 분 | C40: 점검내용
A41: 점검 기준 | C41: - 해당 기계설비의 유지관리 점검표가 있는가 | Z41: · 구비서류 미비(준공도서, 운용 매뉴얼 등) | AE41: · 미비 서류 보완
C42: - 기계설비 유지관리기준 별지 제2호서식에 따라 적정하게 작성되었는가
C43: - 반기별 1회 이상 작성되었는가
A45: 현황 사진 | I45: 적합 | Q45: 미흡사항
A46: 유지관리 점검표 사진 | I46: 사진 | Q46: 사진
Z53: · 기계설비 유지관리기준 별지 제2호서식에 따라 유지관리 점검표를 반기별 1회이상 작성, 보유하고 있으므로 적합함
I54: 사유 : | K54: 기계설비유지관리 기준에 따라 반기별 1회 적정하게 작성되어 적합함 | Q54: 사유 :
A58: ② 펌프 운전(급수, 순환, 대류) 상태
A60: 구 분 | C60: 점검내용
A61: 점검 방법 | C61: - 펌프 운전 상태 육안 점검
A63: 점검 기준 | C63: - 펌프가 원활하게 작동되는가 | Z63: · 이상 소음이나 진동이 발생 하는 경우 | AF63: · 제조사 보수
C64: - 1차측 및 2차측 압력이 설계압력의 ±10% 이내인가
C65: - 2차측 급탕온도는 60℃ 이내인가 | Z65: · 1차측, 2차측 압력이 설 계압력의 ±10%를 초과하 는 경우 | AF65: · 제조사 보수
A67: 현황 사진 | I67: 적합 | Q67: 미흡사항
A68: 사진 | I68: 사진 | Q68: 사진 | Z68: · 급탕온도가 60℃를 초과하 는 경우 | AF68: · 제조사 보수
I76: 사유 : | K76: 펌프가 원활하게 작동하고 압력이 설계압력의 10% 내외로 적합함 | Q76: 사유 :
A85: ③ 급탕 안전밸브 설정 상태
A87: 구 분 | C87: 점검내용
A88: 점검 방법 | C88: - 관리주체의 시험성적서 보유 여부 확인 (연 1회 추가) | Z88: · 설정압력이 최대 사용압력 을 초과하는 경우 | AE88: · 설정압력 조정 또는 안전밸브 교체
A89: 점검 기준 | C89: - 설정압력이 최대 사용압력 이하인지 확인
A91: 현황 사진 | I91: 적합 | Q91: 미흡사항
A92: 사진 | I92: 사진 | Q92: 사진
...

Sheet 고저수조
A2: 고 ‧ 저수조 성능점검표 | R2: 설비번호 | U2: T-1
R3: 용 도 | U3: 급수저장 및 공급
A4: 점검자 | C4: ='정보입력-Rev.2'!$C$9 -> 홍길동 | I4: 점검일자 | L4: ='정보입력-Rev.2'!$C$5&"."&'정보입력-Rev.2'!$E$5&"."&'정보입력-Rev.2'!$G$5&" ~ "&'정보입력-Rev.2'!$J$5&"."&'정보입력-Rev.2'!$L$5&"."&'정보입력-Rev.2'!$N$5 -> 2026.9.2 ~ 2026.9.2 | R4: 설치위치(No.) | U4: 고·저수조실
A6: 구 분 | C6: 점검내용 | V6: 점검결과
A7: 점검 항목 | C7: ① 유지관리 점검표 확인 | V7: ○
C8: ② 파손, 변형, 누수, 결로 상태 | V8: ○
C9: ③ 자동센서 동작 상태 | V9: ○
C10: ④ 수질검사(관계법령에 따른 청소확인증 등을 통해 청소상태 확인) | V10: ○
A11: 조치 사항 | C11: < 미흡사항 >
C14: < 조치필요사항 >
A17: 현장 사진
A31: 비 고
A33: 작 성 방 법
A34: 1. 유지관리지침서 및 기계설비 유지관리 및 성능점검 대상 현황표와의 적합여부를 참고하여 점검결과를 작성한다.
A35: 2. 점검결과에는 [적합 ○, 조치필요 ×, 해당없음 /]을 표기한다.
A36: 3. 현황사진에는 영 별표 7 제3호의 장비를 사용한 측정사진 및 측정데이터를 포함하여 첨부한다.
A39: ① 유지관리 점검표 확인
A41: 구 분 | C41: 점검내용
A42: 점검 기준 | C42: - 해당 기계설비의 유지관리 점검표가 있는가 | Z42: · 구비서류 미비(준공도서, 운용 매뉴얼 등) | AE42: · 미비 서류 보완
C43: - 기계설비 유지관리기준 별지 제2호서식에 따라 적정하게 작성되었는가
C44: - 반기별 1회 이상 작성되었는가
A46: 현황 사진 | I46: 적합 | Q46: 미흡사항
A47: 유지관리 점검표 사진 | I47: 사진 | Q47: 사진
Z52: · 기계설비 유지관리기준 별지 제2호서식에 따라 유지관리 점검표를 반기별 1회이상 작성, 보유하고 있으므로 적합함
I55: 사유 : | K55: 기계설비유지관리 기준에 따라 반기별 1회 적정하게 작성되어 적합함 | Q55: 사유 :
A59: ② 파손, 변형, 누수, 결로 상태
A61: 구 분 | C61: 점검내용
A62: 점검 방법 | C62: - 저수조 내부, 외부, 오버플로우, 드레인, 통기관, 정경구의 파손, 변형, 누수 결로 상태 확인
A63: 점검 기준 | C63: - 내외부에 파손, 변형 흔적이 없을 것 | Z63: · 성능에 문제가 될 정도의 파손, 변형, 누수, 결로가 발 생한 경우 | AE63: · 제조사 보수
C64: - 누수, 결로의 흔적이 없을 것
A66: 현황 사진 | I66: 적합 | Q66: 미흡사항
A67: 사진 | I67: 사진 | Q67: 사진
I75: 사유 : | K75: 성능에 문제가 될정도의 파손, 변형, 누수, 결로가 없으므로 적합함 | Q75: 사유 :
A85: ③ 자동센서 동작 상태
A87: 구 분 | C87: 점검내용
A88: 점검 방법 | C88: - 자동제어 또는 현장제어판넬의 계기류 점검
A89: 점검 기준 | C89: - 정상적으로 수위를 측정할 것 | Z89: · 자동센서 동작이 불능인 경우 | AE89: · 보수 또는 교체
C90: - 자동센서에 의한 펌프 기동/정지(고수조) 또는 수위조절밸브 개방/폐쇄(저수조) 확인
A92: 현황 사진 | I92: 적합 | Q92: 미흡사항
A93: 사진 | I93: 사진 | Q93: 사진
...

Sheet 오배수우수
A2: 오·배수 통기 및 우수배수설비 성능점검표 | R2: 설비번호 | U2: 오·배수 통기 및 우수배수설비
R3: 용 도 | U3: 오·배수 통기 및 우수배수
A4: 점검자 | C4: ='정보입력-Rev.2'!$C$9 -> 홍길동 | I4: 점검일자 | L4: ='정보입력-Rev.2'!$C$5&"."&'정보입력-Rev.2'!$E$5&"."&'정보입력-Rev.2'!$G$5&" ~ "&'정보입력-Rev.2'!$J$5&"."&'정보입력-Rev.2'!$L$5&"."&'정보입력-Rev.2'!$N$5 -> 2026.9.2 ~ 2026.9.2 | R4: 설치위치(No.) | U4: 기계실 등
A6: 구 분 | C6: 점검내용 | V6: 점검결과
A7: 점검 항목 | C7: ① 유지관리 점검표 확인 | V7: ○
C8: ② 파손, 변형, 악취 여부 | V8: ○
C9: ③ 오 ‧ 배수 및 우수 펌프 동작 상태 | V9: ○
C10: ④ 경보장치 상태 | V10: ○
C11: ⑤ 오 ‧ 배수 및 우수 탱크 수위센서 정상 동작 상태 | V11: ○
A12: 조치 사항 | C12: < 미흡사항 >
C15: < 조치필요사항 >
A18: 현장 사진
A35: 비 고
A37: 작 성 방 법
A38: 1. 유지관리지침서 및 기계설비 유지관리 및 성능점검 대상 현황표와의 적합여부를 참고하여 점검결과를 작성한다.
A39: 2. 점검결과에는 [적합 ○, 조치필요 ×, 해당없음 /]을 표기한다.
A40: 3. 현황사진에는 영 별표 7 제3호의 장비를 사용한 측정사진 및 측정데이터를 포함하여 첨부한다.
A43: ① 유지관리 점검표 확인
A45: 구 분 | C45: 점검내용
A46: 점검 기준 | C46: - 해당 기계설비의 유지관리 점검표가 있는가 | Z46: · 구비서류 미비(준공도서, 운용 매뉴얼 등) | AE46: · 미비 서류 보완
C47: - 기계설비 유지관리기준 별지 제2호서식에 따라 적정하게 작성되었는가
C48: - 반기별 1회 이상 작성되었는가
A50: 현황 사진 | I50: 적합 | Q50: 미흡사항
A51: 유지관리 점검표 사진 | I51: 사진 | Q51: 사진
Z58: · 기계설비 유지관리기준 별지 제2호서식에 따라 유지관리 점검표를 반기별 1회이상 작성, 보유하고 있으므로 적합함
I59: 사유 : | K59: 기계설비유지관리 기준에 따라 반기별 1회 적정하게 작성되어 적합함 | Q59: 사유 :
A63: ② 파손, 변형, 악취 여부
A65: 구 분 | C65: 점검내용
A66: 점검 방법 | C66: - 배수트랩 이물질 및 봉수가 유지되는지를 확인 | Z66: · 파손, 변형, 악취, 막힘이 발생한 경우 | AE66: · 보수 또는 교체
C67: - 오·배수, 통기관, 우수배관 연결부분이 틈새, 파손, 변위 등 확인
C68: - 육안점검이 어려운 부위가 막힌 경우 내시경카메라를 사용하여 조사함
A69: 점검 기준 | C69: - 파손, 변형, 막힌 부분이 없을 것
C70: - 누수나 악취가 발생한 부분이 없을 것
A72: 현황 사진 | I72: 적합 | Q72: 미흡사항
A73: 사진 | I73: 사진 | Q73: 사진
I81: 사유 : | K81: 파손, 변형, 막힘이 없고 누수나 악취가 없으므로 적합함 | Q81: 사유 :
A90: ③ 오·배수 및 우수 펌프 동작 상태
A92: 구 분 | C92: 점검내용
A93: 점검 방법 | C93: - 자동제어 또는 현장제어 판넬 육안 점검
A95: 점검 기준 | C95: - 자동센서 및 수위조절기에 의하여 자동으로 기동/정지되는가 | Z95: · 자동 모드로 기동/정지 되 지 않는 경우 | AE95: · 펌프 또는 제어시스템 보수
...

Sheet 오수정화
A2: 오수정화설비 성능점검표 | R2: 설비번호 | U2: 오수정화설비
R3: 용 도 | U3: 오수정화조
A4: 점검자 | C4: ='정보입력-Rev.2'!$C$9 -> 홍길동 | I4: 점검일자 | L4: ='정보입력-Rev.2'!$C$5&"."&'정보입력-Rev.2'!$E$5&"."&'정보입력-Rev.2'!$G$5&" ~ "&'정보입력-Rev.2'!$J$5&"."&'정보입력-Rev.2'!$L$5&"."&'정보입력-Rev.2'!$N$5 -> 2026.9.2 ~ 2026.9.2 | R4: 설치위치(No.) | U4: 오수정화조실
A6: 구 분 | C6: 점검내용 | V6: 점검결과
A7: 점검 항목 | C7: ① 유지관리 점검표 확인 | V7: ○
C8: ② 컨트롤 판넬, 수위제어, 계기류 상태 | V8: ○
C9: ③ 처리시스템의 정상운전 상태 | V9: ○
C10: ④ 경보장치 상태 | V10: ○
A11: 조치 사항 | C11: < 미흡사항 >
C14: < 조치필요사항 >
A17: 현장 사진
A35: 비 고
A37: 작 성 방 법
A38: 1. 유지관리지침서 및 기계설비 유지관리 및 성능점검 대상 현황표와의 적합여부를 참고하여 점검결과를 작성한다.
A39: 2. 점검결과에는 [적합 ○, 조치필요 ×, 해당없음 /]을 표기한다.
A40: 3. 현황사진에는 영 별표 7 제3호의 장비를 사용한 측정사진 및 측정데이터를 포함하여 첨부한다.
A43: ① 유지관리 점검표 확인
A45: 구 분 | C45: 점검내용
A46: 점검 기준 | C46: - 해당 기계설비의 유지관리 점검표가 있는가 | Z46: · 유지관리 점검표 미작성, 내용 미비 | AE46: · 향후 유지관리 점검 표 작성 권고
C47: - 기계설비 유지관리기준 별지 제2호서식에 따라 적정하게 작성되었는가
C48: - 반기별 1회 이상 작성되었는가
Z49: · 구비서류 미비(준공도서, 운용 매뉴얼 등) | AE49: · 작성 내용 보완
A50: 현황 사진 | I50: 적합 | Q50: 미흡사항 | AE50: · 미비 서류 보완
A51: 사진 | I51: 사진 | Q51: 사진
I59: 사유 : | K59: 기계설비유지관리 기준에 따라 반기별 1회 적정하게 작성되어 적합함 | Q59: 사유 : | Z59: · 기계설비 유지관리기준 별지 제2호서식에 따라 유지관리 점검표를 반기별 1회이상 작성, 보유하고 있으므로 적합함
A63: ② 컨트롤 판넬, 수위제어, 계기류 상태
A65: 구 분 | C65: 점검내용
A66: 점검 방법 | C66: - 컨트롤 판넬 육안점검 | Z66: · 수위센서가 고장, 파손된 경우 | AE66: · 수위센서 보수 또는 교체
C67: - 수위제어가 정상적으로 제어 되는지 확인
A68: 점검 기준 | C68: - 작동 불가능한 제어 장치, 계기류가 없을 것 | Z68: · 지시값이 정상범위가 아닌 경우 | AE68: · 제조사 보수
C69: - 정상적으로 수위가 제어되는가
A71: 현황 사진 | I71: 적합 | Q71: 미흡사항
A72: 사진 | I72: 사진 | Q72: 사진
I80: 사유 : | K80: 판넬, 계기류가 이상 없고 수위가 정상으로 제어되므로 적합함 | Q80: 사유 :
A88: ③ 처리시스템의 정상운전 상태
A90: 구 분 | C90: 점검내용
A91: 점검 방법 | C91: - 컨트롤 판넬 또는 자동제어(중앙감시반) 육안 점검
A93: 점검 기준 | C93: - 장비, 시스템이 꺼져있거나 오작동 되는 부분이 없을 것 | Z93: · 오작동하는 경우 | AE93: · 제조사 보수
A96: 현황 사진 | I96: 적합 | Q96: 미흡사항
A97: 사진 | I97: 사진 | Q97: 사진
...

Sheet 물재이용
A2: 물 재이용설비 성능점검표 | R2: 설비번호 | U2: 물재이용설비
R3: 용 도 | U3: 우수재이용
A4: 점검자 | C4: ='정보입력-Rev.2'!$C$9 -> 홍길동 | I4: 점검일자 | L4: ='정보입력-Rev.2'!$C$5&"."&'정보입력-Rev.2'!$E$5&"."&'정보입력-Rev.2'!$G$5&" ~ "&'정보입력-Rev.2'!$J$5&"."&'정보입력-Rev.2'!$L$5&"."&'정보입력-Rev.2'!$N$5 -> 2026.9.2 ~ 2026.9.2 | R4: 설치위치(No.) | U4: 물 재이용 설비실
A6: 구 분 | C6: 점검내용 | V6: 점검결과
A7: 점검 항목 | C7: ① 유지관리 점검표 확인 | V7: ○
C8: ② 노후 및 부식 상태 | V8: ○
C9: ③ 자동센서 동작 상태 | V9: ○
C10: ④ 경보장치(수위조절, 수위경보 등) 상태 | V10: ○
C11: ⑤ 처리량 및 필터 상태 | V11: ○
C12: ⑥ 중수도 수질검사(시험성적서 확인) | V12: ○
A13: 조치 사항 | C13: < 미흡사항 >
C16: < 조치필요사항 >
A19: 현장 사진
A35: 비 고
A37: 작 성 방 법
A38: 1. 유지관리지침서 및 기계설비 유지관리 및 성능점검 대상 현황표와의 적합여부를 참고하여 점검결과를 작성한다.
A39: 2. 점검결과에는 [적합 ○, 조치필요 ×, 해당없음 /]을 표기한다.
A40: 3. 현황사진에는 영 별표 7 제3호의 장비를 사용한 측정사진 및 측정데이터를 포함하여 첨부한다.
A44: ① 유지관리 점검표 확인
A46: 구 분 | C46: 점검내용
A47: 점검 기준 | C47: - 해당 기계설비의 유지관리 점검표가 있는가
C48: - 기계설비 유지관리기준 별지 제2호서식에 따라 적정하게 작성되었는가
C49: - 반기별 1회 이상 작성되었는가
A51: 현황 사진 | I51: 적합 | Q51: 미흡사항
A52: 유지관리 점검표 사진 | I52: 사진 | Q52: 사진 | Z52: · 유지관리 점검표 미작성, 내용 미비 | AE52: · 향후 유지관리 점검표 작성 권고
AE53: · 작성 내용 보완
Z55: · 구비서류 미비(준공도서, 운용 매뉴얼 등) | AE55: · 미비 서류 보완
I60: 사유 : | K60: 기계설비유지관리 기준에 따라 반기별 1회 적정하게 작성되어 적합함 | Q60: 사유 : | Z60: · 기계설비 유지관리기준 별지 제2호서식에 따라 유지관리 점검표를 반기별 1회이상 작성, 보유하고 있으므로 적합함
A64: ② 노후 및 부식상태
A66: 구 분 | C66: 점검내용
A67: 점검 방법 | C67: - 침수설비, 저장조 , 부속장치 등 육안점검
A69: 점검 기준 | C69: - 외부 균열이나 부식 흔적이 없을 것 | Z69: · 육안점검 시 성능에 문제가 될 정도의 노후 및 부식이 발생한 경우 | AE69: · 상태에 따라 부분 보수, 전 체 보수, 교체
A72: 현황 사진 | I72: 적합 | Q72: 미흡사항
A73: 사진 | I73: 사진 | Q73: 사진
I81: 사유 : | K81: 외부균열이나 부식 흔적이 없으므로 적합함 | Q81: 사유 :
A92: ③ 자동센서 동작 상태
A94: 구 분 | C94: 점검내용
A95: 점검 방법 | C95: - 자동제어(중앙감시반) 또는 현장제어판넬에서 계기류 점검
A97: 점검 기준 | C97: - 제어기기, 계기류가 정상적으로 작동하는가 | Z97: · 제어기기, 계기류가 정상 작동하지 않는 경우 | AE97: · 제조사 보수
A100: 현황 사진 | I100: 적합 | Q100: 미흡사항
...

Sheet 물재이용-중수도 수질기준
A1: ⑥ 중수도 수질기준
A3: 구 분 | C3: 점검 기준 근거
A4: 관련 법규 | C4: - 물의 재이용 촉진 및 지원에 관한 법률 제9조(중수도의 설치·관리) ① 다음 각 호의 어느 하나에 해당하는 시설물을 신축(대통령령으로 정하는 규모 이상으로 증축·개축 또는 재촉하는 경우를 포함한다. 이하 이 조에서 같다)하거나 개발사업을 시행하려는 자는 환경부령으로 정하는 바에 따라 단독 또는 공동으로 물 사용량의 10% 이상을 재이용할 수 있도록 중수도를 설치·운영하여야 하며, 중수도의 설치 결과를 특별자치시장·특별자치도지사·시장·군수·구청장에게 신고하여야 한다. 다만, 물사용량의 10% 이상을 하·폐수처리수 재처리수로 공급받거나 빗물을 이용하는 자의 경우에는 그러하지 아니한다. <개정 2013,816, 2015,3,27> 1. 『공중위생관리법』 제2조제1항제2호에 따른 숙박업 또는 같은 항 제3호에 따른 목욕장업에 사용되는 시설로서 건축 연면적이 6만제곱미터 이상인 시설물 2. 『산업집적활성화 및 공장설립에 관한 법률』 제2조제1호에 따른 공장으로서 1일 폐수배출량이 1천500㎥ 이상인 시설물 2의2. 『건축법』 제2조제2항제25호에 따른 발전시설로서 1일 폐수배출량이 1천500㎥ 이상인 시설물 3. 『관광진흥법』 제2조제7호에 따른 관광단지의 개발사업 4. 『도시개발법』 제2조제1항제2호에 따른 도시개발사업 5. 『산업입지 및 개발에 관한 법류』 제2조제6호에 따른 산업단지개발사업 6. 『택지개발촉진법』에 따른 택지개발사업 7. 그 밖에 대통령령으로 정하는 종류 및 규모 이상의 시설물 또는 개발사업 ② 제1항에도 불구하고 같은 항 제3호부터 제7호까지의 개발사업은 다음 각 호의 어느 하나에 해당하는 자가 시행하는 경우에만 적용한다. 1. 국가 또는 지방자치단체 2. 『공공기관의 운영에 관한 법률』 제5조에 따른 공기업 3. 『지방공기업법』 제3조에 따른 지방공기업 ⑥ 중소도의 소유자 또는 관리자는 환경부령으로 정하는 바에 따라 중수도의 안정성 및 수질 등을 분기별로 검사하고, 그 결과를 특별자치시장·특별자치도지사·시장·군수·구청장에게 통보하여야 한다.
C34: · 물의 재이용 촉진 및 지원에 관한 법률 시행규칙 제9조(중수도의 안정성 및 수질검사 등) ① 중수도의 소유자 또는 관리자는 법 제9조제6항에 다라 중소도의 수질검사를 하는 경우에는 다음 각 호의 자에게 수질검사를 하게 하여야 한다. 1. 『환경분야 시험·검사 등에 관한 법률』 제16조에 따른 측정대행업자 2. 특별시·광역시·도 및 특별자치도의 보건환경연구원장 3. 유역환경청장 또는 지방환경청장 ② 중수도의 소유자 및 관리자는 법 제9조제6항에 따라 중수도의 수질검사 결과를 통보하는 때에는 별지 제5호서식에 따른 수질검사 결과통보서에 제1항에 따른 수질검사서를 첨부하여야 한다.
A49: 구 분 | C49: 점검 기준 근거
A50: 중수도 용도별 수질 기준 | C50: - [별표1] 중수도의 용도별 수질기준(물재이용법 시행규칙 제8조제2항 관련)
C51: 구 분 | G51: 도시 재이용수 | J51: 조경용수 | M51: 친수용수 | P51: 하천 유지용수 | S51: 조경용수 | V51: 조경용수
C52: 총 대장균 군수 (개/100mℓ) | G52: 불검출 | J52: 200 이하 | M52: 불검출 | P52: 1000 이하 | S52: 200 이하 | V52: 200 이하
C55: 결합 잔류 염소 (mg/L) | G55: 0.2 이상 | J55: - | M55: 0.1 이상 | P55: - | S55: - | V55: -
C57: 탁도 (NTU) | G57: 2 이하 | J57: 2 이하 | M57: 2 이하 | P57: - | S57: - | V57: 10 이하
C58: 부유 물질(SS) (mg/L) | G58: - | J58: - | M58: - | P58: 6 이하 | S58: 6 이하 | V58: -
C60: 생물화학적 산소요구량 (BOD)(mg/L) | G60: 5 | J60: 5 | M60: 3 | P60: 5 | S60: 5 | V60: 6
C63: 냄새 | G63: 불쾌하지 않을 것 | J63: 불쾌하지 않을 것 | M63: 불쾌하지 않을 것 | P63: 불쾌하지 않을 것 | S63: 불쾌하지 않을 것 | V63: 불쾌하지 않을 것
C64: 색도(소) | G64: 20 이하 | J64: - | M64: 10 이하 | P64: 20 이하 | S64: - | V64: -
C65: 총질소 (T-N) (mg/L) | G65: - | J65: - | M65: 10 이하 | P65: 10 이하 | S65: 10 이하 | V65: -
C67: 총인 (T-P) (mg/L) | G67: - | J67: - | M67: 0.5 이하 | P67: 0.5 이하 | S67: 0.5 이하 | V67: -
C69: 수소 이온 농도 (pH) | G69: 5.8 ~ 8.5 | J69: 5.8 ~ 8.5 | M69: 5.8 ~ 8.5 | P69: 5.8 ~ 8.5 | S69: 5.8 ~ 8.5 | V69: 5.8 ~ 8.5
C71: 염화물 (mgCI/L) | G71: - | J71: 250 이하 | M71: - | P71: - | S71: 250 이하 | V71: -
C73: 비고 1. 항목별 수질검사 방법은 다음과 같다. 가. 총대장균군수, 부유물질(SS), 생물화학적산소요구량(BOD), 색도, 총질소(T-N) 수도이온농도(pH), 염화물은 『환경분야 시험·검사 등에 관한 법률』 제6조제1항 제5호에 따른 수질오염물질 공정시험기준에 따라 검사해야 한다. 다만, 총대장균 군수는 최적확수(最適確數) 시험법 또는 막여과 시험법으로 하고, 부유물질(SS) 은 유리섬유 거름종이법으로 해야한다. 나. 결합잔류염소, 탁도, 냄새는 『환경분야 시험·검사 등에 관한 법률』 제6조제1항 제6호에 따른 먹는물 공정시험 기준에 따라 검사해야 한다 2. 공업용수의 수질기준은 산업용수로 사용하는 경웨 적용하며, 다회순환냉각수, 공정수(工程水), 보일러용수 등은 수요처와 협의하여 수질을 정할 수 있다.

Sheet 배관
A2: 배관설비 성능점검표 | R2: 설비번호 | U2: 배관설비
R3: 용 도 | U3: 각종 배관
A4: 점검자 | C4: ='정보입력-Rev.2'!$C$9 -> 홍길동 | I4: 점검일자 | L4: ='정보입력-Rev.2'!$C$5&"."&'정보입력-Rev.2'!$E$5&"."&'정보입력-Rev.2'!$G$5&" ~ "&'정보입력-Rev.2'!$J$5&"."&'정보입력-Rev.2'!$L$5&"."&'정보입력-Rev.2'!$N$5 -> 2026.9.2 ~ 2026.9.2 | R4: 설치위치(No.) | U4: 기계실 등
A6: 구 분 | C6: 점검내용 | V6: 점검결과
A7: 점검 항목 | C7: ① 유지관리 점검표 확인 | V7: ○
C8: ② 신축이음 상태(10개소 내외) | V8: ○
C9: ③ 경과연수에 따른 노후 및 부식 상태(5개소 내외) | V9: ○
C10: ④ 배관의 고정, 지지 상태(10개소 내외) | V10: ○
A11: 조치 사항 | C11: < 미흡사항 >
C14: < 조치필요사항 >
A17: 현장 사진
A35: 비 고
A37: 작 성 방 법
A38: 1. 유지관리지침서 및 기계설비 유지관리 및 성능점검 대상 현황표와의 적합여부를 참고하여 점검결과를 작성한다.
A39: 2. 점검결과에는 [적합 ○, 조치필요 ×, 해당없음 /]을 표기한다.
A40: 3. 현황사진에는 영 별표 7 제3호의 장비를 사용한 측정사진 및 측정데이터를 포함하여 첨부한다.
A44: ① 유지관리 점검표 확인
A46: 구 분 | C46: 점검내용
A47: 점검 기준 | C47: - 해당 기계설비의 유지관리 점검표가 있는가 | Z47: · 유지관리 점검표 미작성, 내용 미비 | AE47: · 향후 유지관리 점검표 작성권고 · 작성 내용 보완
C48: - 기계설비 유지관리기준 별지 제2호서식에 따라 적정하게 작성되었는가
C49: - 반기별 1회 이상 작성되었는가
Z50: · 구비서류 미비(준공도서, 운용 매뉴얼 등) | AE50: · 미비 서류 보완
A51: 현황 사진 | I51: 적합 | Q51: 미흡사항
A52: 유지관리 점검표 사진 | I52: 사진 | Q52: 사진
I60: 사유 : | K60: 기계설비유지관리 기준에 따라 반기별 1회 적정하게 작성되어 적합함 | Q60: 사유 : | Z60: · 기계설비 유지관리기준 별지 제2호서식에 따라 유지관리 점검표를 반기별 1회이상 작성, 보유하고 있으므로 적합함
A64: ② 신축이음 상태(10개소 내외)
A66: 구 분 | C66: 점검내용
A67: 점검 방법 | C67: - 배관 신축이음 부분 육안 점검 및 신축변위량 측정(10개소 내외) | Z67: · 이음 부위에 누수, 또는 녹 이 발생한 경우 · 신축변위의 여유량이 없음 | AE67: · 보수 또는 교체
A69: 점검 기준 | C69: - 이음 부위에 누수, 녹, 파손이 없을 것 | AE69: · 보수 또는 교체
C70: - 신축변위량을 측정하여 신축변위의 여유량 유무 확인
A72: 현황 사진 | I72: 적합 | Q72: 미흡사항
A73: 사진 | I73: 사진 | Q73: 사진
I81: 사유 : | K81: 이음 부위에 누수, 파손이 없고 신축 변위량에 여유가 있으므로 적합함 | Q81: 사유 :
B93: 측정 기록표
B95: 측정내용 | E95: 측정위치 | I95: 제품형식 (단식/복식) | L95: 측정값(mm) | O95: 변위여유량 여부 | R95: 제품변위량 | U95: 결과 | AC95: 신방향 | AD95: 축방향
B96: 신축이음 변위량 측정 | E96: 지하 PIT | I96: 복식 | L96: 16 | O96: 적합 | R96: 80mm | U96: 적합함 | Z96: 단식 변위여유량 | AC96: 10mm | AD96: 40mm
E97: 지하 PIT | I97: 복식 | L97: 35 | O97: 적합 | R97: 80mm | U97: 적합함 | Z97: 복식 변위여유량 | AC97: 20mm | AD97: 80mm
B106: 최종결과 및 분석의견 | E106: 신축이음 변위량 측정한 결과 제품변위량 내에 있으므로 적합함.
A135: ③ 경과연수에 따른 노후 및 부식 상태(5개소 내외)
A137: 구 분 | C137: 점검내용
...

Sheet 덕트
A2: 덕트설비 성능점검표 | R2: 설비번호 | U2: 덕트설비
R3: 용 도 | U3: 환기 덕트
A4: 점검자 | C4: ='정보입력-Rev.2'!$C$9 -> 홍길동 | I4: 점검일자 | L4: ='정보입력-Rev.2'!$C$5&"."&'정보입력-Rev.2'!$E$5&"."&'정보입력-Rev.2'!$G$5&" ~ "&'정보입력-Rev.2'!$J$5&"."&'정보입력-Rev.2'!$L$5&"."&'정보입력-Rev.2'!$N$5 -> 2026.9.2 ~ 2026.9.2 | R4: 설치위치(No.) | U4: 기계실 등
A6: 구 분 | C6: 점검내용 | V6: 점검결과
A7: 점검 항목 | C7: ① 유지관리 점검표 확인 | V7: ○
C8: ② 장비 운전 시 댐퍼(VD, VAV) 작동 상태(10개소 내외) | V8: ○
C9: ③ 취출구 등의 소음 및 진동 및 풍량 상태(10개소 내외) | V9: ○
A10: 조치 사항 | C10: < 미흡사항 >
C13: < 조치필요사항 >
A16: 현장 사진
A35: 비 고
A37: 작 성 방 법
A38: 1. 유지관리지침서 및 기계설비 유지관리 및 성능점검 대상 현황표와의 적합여부를 참고하여 점검결과를 작성한다.
A39: 2. 점검결과에는 [적합 ○, 조치필요 ×, 해당없음 /]을 표기한다.
A40: 3. 현황사진에는 영 별표 7 제3호의 장비를 사용한 측정사진 및 측정데이터를 포함하여 첨부한다.
A43: ① 유지관리 점검표 확인
A45: 구 분 | C45: 점검내용
A46: 점검 기준 | C46: - 해당 기계설비의 유지관리 점검표가 있는가 | Z46: · 유지관리 점검표 미작성, 내용 미비 | AE46: · 향후 유지관리 점검표 작성 권고 · 작성 내용 보완
C47: - 기계설비 유지관리기준 별지 제2호서식에 따라 적정하게 작성되었는가
C48: - 반기별 1회 이상 작성되었는가
Z49: · 구비서류 미비(준공도서, 운용 매뉴얼 등) | AE49: · 미비 서류 보완
A50: 현황 사진 | I50: 적합 | Q50: 미흡사항
A51: 유지관리 점검표 사진 | I51: 사진 | Q51: 사진
I59: 사유 : | K59: 기계설비유지관리 기준에 따라 반기별 1회 적정하게 작성되어 적합함 | Q59: 사유 : | Z59: · 기계설비 유지관리기준 별지 제2호서식에 따라 유지관리 점검표를 반기별 1회이상 작성, 보유하고 있으므로 적합함
A63: ② 장비 운전 시 댐퍼(VD, MVD) 작동상태(10개소 내외)
A65: 구 분 | C65: 점검내용
A66: 점검 방법 | C66: VD | E66: - VD 개폐 상태 확인 | Z66: · 고장으로 인한 미작동 | AE66: · 댐퍼 보수
C67: MVD | E67: - 장비 주변의 댐퍼 동작 확인 | Z67: · 시나리오대로 MVD 동작하 지 않는 경우 | AE67: · 자동제어 보수
C68: - 점검개소는 총 10개소 내외(VD, MVD)
A69: 점검 기준 | C69: VD | E69: - 댐퍼는 정상적으로 개방, 폐쇄되어 있는가 (상시개방, 상시폐쇄)
C70: MVD | E70: - 정상 동작하는가
A72: 현황 사진 | I72: 적합 | Q72: 미흡사항
A73: 사진 | I73: 사진 | Q73: 사진
I81: 사유 : | K81: 댐퍼가 개방, 폐쇄되어 있고 정상 작동하므로 적합함 | Q81: 사유 :
A90: ③ 취출구 등의 소음 및 진동 및 풍량 상태(10개소 내외)
A92: 구 분 | C92: 점검내용
A93: 점검 방법 | C93: - 유닛, 터미널에서 이상 소음 및 진동발생 여부 확인
C94: - 유닛, 터미널에서 풍량 측정
C95: - 점검개소는 총 10개소 내외(이상소음·진동·풍량 상태)
A96: 점검 기준 | C96: - 송풍시 이상 소음 및 이상 진동이 있는가 | Z96: · 이상 소음, 이상 진동이 발 생하는 경우 | AE96: · 유닛, 터미널 고정부위 보수
...

Sheet 보온
A2: 보온설비 성능점검표 | R2: 설비번호 | U2: 보온설비
R3: 용 도 | U3: 배관 보온
A4: 점검자 | C4: ='정보입력-Rev.2'!$C$9 -> 홍길동 | I4: 점검일자 | L4: ='정보입력-Rev.2'!$C$5&"."&'정보입력-Rev.2'!$E$5&"."&'정보입력-Rev.2'!$G$5&" ~ "&'정보입력-Rev.2'!$J$5&"."&'정보입력-Rev.2'!$L$5&"."&'정보입력-Rev.2'!$N$5 -> 2026.9.2 ~ 2026.9.2 | R4: 설치위치(No.) | U4: 기계실 등
A6: 구 분 | C6: 점검내용 | V6: 점검결과
A7: 점검 항목 | C7: ① 유지관리 점검표 확인 | V7: ○
C8: ② 열선 운전 시 온도에 의한 제어 상태(10개소 내외) | V8: ○
C9: ③ 전열선 파손 및 절연 상태(10개소 내외) | V9: ○
C10: ④ 장비, 배관, 덕트 단열 상태(10개소 내외) | V10: ○
C11: ⑤ 냉난방 보온재 표면온도(열누출) 상태(10개소 내외) | V11: ○
A12: 조치 사항 | C12: < 미흡사항 >
C15: < 조치필요사항 >
A18: 현장 사진
A37: 비 고
A39: 작 성 방 법
A40: 1. 유지관리지침서 및 기계설비 유지관리 및 성능점검 대상 현황표와의 적합여부를 참고하여 점검결과를 작성한다.
A41: 2. 점검결과에는 [적합 ○, 조치필요 ×, 해당없음 /]을 표기한다.
A42: 3. 현황사진에는 영 별표 7 제3호의 장비를 사용한 측정사진 및 측정데이터를 포함하여 첨부한다.
A45: ① 유지관리 점검표 확인
A47: 구 분 | C47: 점검내용
A48: 점검 기준 | C48: - 해당 기계설비의 유지관리 점검표가 있는가 | Z48: · 유지관리 점검표 미작성, 내용 미비 | AE48: · 향후 유지관리 점검표 작성 권고 · 작성 내용 보완
C49: - 기계설비 유지관리기준 별지 제2호서식에 따라 적정하게 작성되었는가
C50: - 반기별 1회 이상 작성되었는가
Z51: · 구비서류 미비(준공도서, 운용 매뉴얼 등) | AE51: · 미비 서류 보완
A52: 현황 사진 | I52: 적합 | Q52: 미흡사항
A53: 유지관리 점검표 사진 | I53: 사진 | Q53: 사진
I61: 사유 : | K61: 기계설비유지관리 기준에 따라 반기별 1회 적정하게 작성되어 적합함 | Q61: 사유 : | Z61: · 기계설비 유지관리기준 별지 제2호서식에 따라 유지관리 점검표를 반기별 1회이상 작성, 보유하고 있으므로 적합함
A65: ② 열선 운전 시 온도에 의한 제어 상태(10개소 내외)
A67: 구 분 | C67: 점검내용
A68: 점검 방법 | C68: - 열선용 분전반에서 유지하고자 하는 목표온도(SV표시값)를 현재주위온도(PV표시값)보 다 낮게 설정값을 변경하여 히터의 동작표시램프가 ON상태로 전환되는지 확인 (온도조절기가 없거나 하절기로 인해 동작 확인이 불가능한 경우 유지관리점검표에서 작동 상태 기록 확인)(10개소 내외)
A72: 점검 기준 | C72: - 히터 동작표시램프의 ON/OFF가 SV표시값과 PV표시값에 의하여 정상 작동할 경우 | Z72: · 설정 온도 도달시 열선 동 작하지 않는 경우 · 온도조절기 고장으로 열선 이 과열되는 경우 | AE72: · 제어 판넬 보수
AE74: · 제어 판넬 보수
A75: 현황 사진 | I75: 적합 | Q75: 미흡사항
A76: 사진 | I76: 사진 | Q76: 사진
I84: 사유 : | K84: 열선 운전시 온도에 의해 히터 동작 램프가 ON/OFF 되며 정상 작동하므로 적합함 | Q84: 사유 :
A94: ③ 전열선 파손 및 전열 상태(10개소 내외)
A96: 구 분 | C96: 점검내용
A97: 점검 방법 | C97: - 전원을 차단한 상태에서 전열선의 절연저항 측정(10개소 내외)
A99: 점검 기준 | C99: - DC 500V 인가하였을 때 20MΩ 이상일 것 | Z99: · DC 500V 인가하였을 때, 20MΩ 미만인 경우 | AE99: · 절연선 교체
A102: 현황 사진 | I102: 적합 | Q102: 미흡사항
A103: 사진 | I103: 사진 | Q103: 사진
...

Sheet 자동제어
A2: 자동제어설비 성능점검표 | R2: 설비번호 | U2: 자동제어설비
R3: 용 도 | U3: 기계설비
A4: 점검자 | C4: ='정보입력-Rev.2'!$C$9 -> 홍길동 | I4: 점검일자 | L4: ='정보입력-Rev.2'!$C$5&"."&'정보입력-Rev.2'!$E$5&"."&'정보입력-Rev.2'!$G$5&" ~ "&'정보입력-Rev.2'!$J$5&"."&'정보입력-Rev.2'!$L$5&"."&'정보입력-Rev.2'!$N$5 -> 2026.9.2 ~ 2026.9.2 | R4: 설치위치(No.) | U4: 방재실
A6: 구 분 | C6: 점검내용 | V6: 점검결과
A7: 점검 항목 | C7: ① 유지관리 점검표 확인 | V7: ○
C8: ② 기록장치 등 상태 | V8: ○
C9: ③ 장비 및 시스템별 운전 적정 여부 | V9: ○
C10: ④ 방화벽(최신 백신 업데이트 상태) 동작 상태 | V10: ○
C11: ⑤ 경보관리, 데이터 조회, 수집 및 분석 | V11: ○
C12: ⑥ BEMS 운영상태 확인 | V12: ○
C13: ⑦ 원격검침시스템 운영상태 확인 | V13: ○
A14: 조치 사항 | C14: < 미흡사항 >
C17: < 조치필요사항 >
A20: 현장 사진
A35: 비 고
A37: 작 성 방 법
A38: 1. 유지관리지침서 및 기계설비 유지관리 및 성능점검 대상 현황표와의 적합여부를 참고하여 점검결과를 작성한다.
A39: 2. 점검결과에는 [적합 ○, 조치필요 ×, 해당없음 /]을 표기한다.
A40: 3. 현황사진에는 영 별표 7 제3호의 장비를 사용한 측정사진 및 측정데이터를 포함하여 첨부한다.
A41: 4. 자동제어 중앙감시반 등을 포함하여 작성한다.
A44: ① 유지관리 점검표 확인
A46: 구 분 | C46: 점검내용
A47: 점검 기준 | C47: - 해당 기계설비의 유지관리 점검표가 있는가 | Z47: · 유지관리 점검표 미작성, 내용 미비 | AF47: · 향후 유지관리 점검표 작성 권고 · 작성 내용 보완
C48: - 기계설비 유지관리기준 별지 제2호서식에 따라 적정하게 작성되었는가
C49: - 반기별 1회 이상 작성되었는가
Z50: · 구비서류 미비(준공도서, 운용 매뉴얼 등) | AF50: · 미비 서류 보완
A51: 현황 사진 | I51: 적합 | Q51: 미흡사항
A52: 유지관리 점검표 사진 | I52: 사진 | Q52: 사진
I60: 사유 : | K60: 기계설비유지관리 기준에 따라 반기별 1회 적정하게 작성되어 적합함 | Q60: 사유 : | Z60: · 기계설비 유지관리기준 별지 제2호서식에 따라 유지관리 점검표를 반기별 1회이상 작성, 보유하고 있으므로 적합함
A64: ② 기록장치 등 상태
A66: 구 분 | C66: 점검내용
A67: 점검 방법 | C67: - 운전자료 등을 기록할 수 있는 장치의 보유 및 정상작동 여부 확인
A69: 점검 기준 | C69: - 운전 이력 또는 경보 이력이 기록되는가 | Z69: · 저장 기록 없는 경우 | AE69: · 데이터 저장이 가능하도록 시스템 구성
A72: 현황 사진 | I72: 적합 | Q72: 미흡사항
A73: 사진 | I73: 사진 | Q73: 사진
I81: 사유 : | K81: 운전이력 또는 경보이력이 기록되므로 적합함 | Q81: 사유 :
A91: ③ 장비 및 시스템별 운전 적정 여부
A93: 구 분 | C93: 점검내용
A94: 점검 방법 | C94: - 자동제어 PC로 동작이 불가능한 장비가 있는가 | Z94: · 초기 자동제어 운전 시나리 오대로 운전되고 있지 않은 경우 | AE94: · 자동제어 시스템 보수
C95: - 반송설비(펌프, 송풍기 등) 가동 중 밸브 또는 댐퍼가 닫혀 있진 않는가
...

Sheet 방음방진내진
A2: 방음‧방진‧내진 설비 성능점검표 | R2: 설비번호 | U2: 방음·방진·내진설비
R3: 용 도 | U3: 각종 장비
A4: 점검자 | C4: ='정보입력-Rev.2'!$C$9 -> 홍길동 | I4: 점검일자 | L4: ='정보입력-Rev.2'!$C$5&"."&'정보입력-Rev.2'!$E$5&"."&'정보입력-Rev.2'!$G$5&" ~ "&'정보입력-Rev.2'!$J$5&"."&'정보입력-Rev.2'!$L$5&"."&'정보입력-Rev.2'!$N$5 -> 2026.9.2 ~ 2026.9.2 | R4: 설치위치(No.) | U4: 기계실 등
A6: 구 분 | C6: 점검내용 | V6: 점검결과
A7: 점검 항목 | C7: ① 유지관리 점검표 확인 | V7: ○
C8: ② 장치 변형 및 변위 상태(10개소 내외) | V8: ○
C9: ③ 장비류, 배관류, 덕트류 등 소음 상태(10개소 내외) | V9: ○
A10: 조치 사항 | C10: < 미흡사항 >
C13: < 조치필요사항 >
A16: 현장 사진
A35: 비 고
A37: 작 성 방 법
A38: 1. 유지관리지침서 및 기계설비 유지관리 및 성능점검 대상 현황표와의 적합여부를 참고하여 점검결과를 작성한다.
A39: 2. 점검결과에는 [적합 ○, 조치필요 ×, 해당없음 /]을 표기한다.
A40: 3. 현황사진에는 영 별표 7 제3호의 장비를 사용한 측정사진 및 측정데이터를 포함하여 첨부한다.
A44: ① 유지관리 점검표 확인
A46: 구 분 | C46: 점검내용 | Z46: · 유지관리 점검표 미작성, 내용 미비 | AE46: · 향후 유지관리 점검표 작성 권고 · 작성 내용 보완
A47: 점검 기준 | C47: - 해당 기계설비의 유지관리 점검표가 있는가
C48: - 기계설비 유지관리기준 별지 제2호서식에 따라 적정하게 작성되었는가
C49: - 반기별 1회 이상 작성되었는가 | Z49: · 구비서류 미비(준공도서, 운용 매뉴얼 등) | AE49: · 미비 서류 보완
A51: 현황 사진 | I51: 적합 | Q51: 미흡사항
A52: 유지관리 점검표 사진 | I52: 사진 | Q52: 사진
I60: 사유 : | K60: 기계설비유지관리 기준에 따라 반기별 1회 적정하게 작성되어 적합함 | Q60: 사유 : | Z60: · 기계설비 유지관리기준 별지 제2호서식에 따라 유지관리 점검표를 반기별 1회이상 작성, 보유하고 있으므로 적합함
